Workbook

Sheet 2019 ALL N OLDER D95
A1: ACARA | B1: FROM DATE | C1: TO DATE | D1: DEPT | E1: WORLD | F1: DIVISION | G1: CLASS | H1: SUPPLIER | I1: BRAND | J1: SKU | K1: ARTICLE | L1: DESCRIPTION | M1: HARGA NORMAL | N1: DISKON | O1: HARGA PROMO | P1: DISCOUNT TYPE
A2: 2019 ALL ITEM & OLDER D95 | B2: 46121 | C2: 46127 | D2: 3260 | E2: 333 | F2: 3 | G2: 1 | H2: GRAHA CIPTA HARDIKA PT- 81455 | I2: AOS | J2: 19890836 | K2: TSH43RAS | L2: T-SHIRT ROCK & SOUL WORD 86:MISTY MEDIUM BROW:S | M2: 79900 | N2: 0.95 | O2: =M2-((95*M2)/100) -> 3995 | P2: PERCENTAGE
A3: =$A$2 -> 2019 ALL ITEM & OLDER D95 | B3: =$B$2 -> 46121 | C3: =$C$2 -> 46127 | D3: 3260 | E3: 333 | F3: 3 | G3: 1 | H3: GRAHA CIPTA HARDIKA PT- 81455 | I3: AOS | J3: 19892843 | K3: TSH43RST | L3: T-SHIRT ROCK STAR WORD 86:FROST GREY:M | M3: 79900 | N3: 0.95 | O3: =M3-((95*M3)/100) -> 3995 | P3: PERCENTAGE
A4: =$A$2 -> 2019 ALL ITEM & OLDER D95 | B4: =$B$2 -> 46121 | C4: =$C$2 -> 46127 | D4: 3260 | E4: 333 | F4: 3 | G4: 1 | H4: GRAHA CIPTA HARDIKA PT- 81455 | I4: AOS | J4: 20117973 | K4: TSH53IMA | L4: T-SHIRT IMAGINE WORD 86:MISTY MEDIUM BROWN:L | M4: 69900 | N4: 0.95 | O4: =M4-((95*M4)/100) -> 3495 | P4: PERCENTAGE
A5: =$A$2 -> 2019 ALL ITEM & OLDER D95 | B5: =$B$2 -> 46121 | C5: =$C$2 -> 46127 | D5: 3260 | E5: 333 | F5: 3 | G5: 1 | H5: GRAHA CIPTA HARDIKA PT- 81455 | I5: AOS | J5: 20124474 | K5: TSH53NOR | L5: T-SHIRT NO REGRET WORD 86:MISTY LIGHT BLUE:L | M5: 69900 | N5: 0.95 | O5: =M5-((95*M5)/100) -> 3495 | P5: PERCENTAGE
A6: =$A$2 -> 2019 ALL ITEM & OLDER D95 | B6: =$B$2 -> 46121 | C6: =$C$2 -> 46127 | D6: 3260 | E6: 333 | F6: 3 | G6: 1 | H6: GRAHA CIPTA HARDIKA PT- 81455 | I6: AOS | J6: 20547437 | K6: TSH83BER | L6: T-SHIRT BERLIN FLAG 86:MAROON:S | M6: 69900 | N6: 0.95 | O6: =M6-((95*M6)/100) -> 3495 | P6: PERCENTAGE
A7: =$A$2 -> 2019 ALL ITEM & OLDER D95 | B7: =$B$2 -> 46121 | C7: =$C$2 -> 46127 | D7: 3260 | E7: 333 | F7: 3 | G7: 1 | H7: GRAHA CIPTA HARDIKA PT- 81455 | I7: AOS | J7: 20547446 | K7: TSH83BER | L7: T-SHIRT BERLIN FLAG 86:MAROON:M | M7: 69900 | N7: 0.95 | O7: =M7-((95*M7)/100) -> 3495 | P7: PERCENTAGE
A8: =$A$2 -> 2019 ALL ITEM & OLDER D95 | B8: =$B$2 -> 46121 | C8: =$C$2 -> 46127 | D8: 3260 | E8: 333 | F8: 3 | G8: 1 | H8: GRAHA CIPTA HARDIKA PT- 81455 | I8: AOS | J8: 20547455 | K8: TSH83BER | L8: T-SHIRT BERLIN FLAG 86:MAROON:L | M8: 69900 | N8: 0.95 | O8: =M8-((95*M8)/100) -> 3495 | P8: PERCENTAGE
A9: =$A$2 -> 2019 ALL ITEM & OLDER D95 | B9: =$B$2 -> 46121 | C9: =$C$2 -> 46127 | D9: 3260 | E9: 333 | F9: 3 | G9: 1 | H9: GRAHA CIPTA HARDIKA PT- 81455 | I9: AOS | J9: 20564981 | K9: TSH83WIL | L9: T-SHIRT WILD LIFE ANIMAL LOGO 86:MISTY LIGHT BROW:M | M9: 69900 | N9: 0.95 | O9: =M9-((95*M9)/100) -> 3495 | P9: PERCENTAGE
A10: =$A$2 -> 2019 ALL ITEM & OLDER D95 | B10: =$B$2 -> 46121 | C10: =$C$2 -> 46127 | D10: 3260 | E10: 333 | F10: 3 | G10: 1 | H10: GRAHA CIPTA HARDIKA PT- 81455 | I10: AOS | J10: 20601001 | K10: CNS93ANO | L10: CUT N SEWN ANOMALI WORD 86:MAROON:M | M10: 79900 | N10: 0.95 | O10: =M10-((95*M10)/100) -> 3995 | P10: PERCENTAGE
A11: =$A$2 -> 2019 ALL ITEM & OLDER D95 | B11: =$B$2 -> 46121 | C11: =$C$2 -> 46127 | D11: 3260 | E11: 333 | F11: 3 | G11: 1 | H11: GRAHA CIPTA HARDIKA PT- 81455 | I11: AOS | J11: 20622060 | K11: TSH03DEN | L11: T-SHIRT DENIM ROCK WORDS 86:TURQUOISE:S | M11: 79900 | N11: 0.95 | O11: =M11-((95*M11)/100) -> 3995 | P11: PERCENTAGE
A12: =$A$2 -> 2019 ALL ITEM & OLDER D95 | B12: =$B$2 -> 46121 | C12: =$C$2 -> 46127 | D12: 3260 | E12: 333 | F12: 3 | G12: 1 | H12: GRAHA CIPTA HARDIKA PT- 81455 | I12: AOS | J12: 20622079 | K12: TSH03DEN | L12: T-SHIRT DENIM ROCK WORDS 86:TURQUOISE:M | M12: 79900 | N12: 0.95 | O12: =M12-((95*M12)/100) -> 3995 | P12: PERCENTAGE
A13: =$A$2 -> 2019 ALL ITEM & OLDER D95 | B13: =$B$2 -> 46121 | C13: =$C$2 -> 46127 | D13: 3260 | E13: 333 | F13: 3 | G13: 1 | H13: GRAHA CIPTA HARDIKA PT- 81455 | I13: AOS | J13: 20622382 | K13: TSH03COR | L13: T-SHIRT CORE DNM BIG FONT WORD 86:WINE:L | M13: 79900 | N13: 0.95 | O13: =M13-((95*M13)/100) -> 3995 | P13: PERCENTAGE
A14: =$A$2 -> 2019 ALL ITEM & OLDER D95 | B14: =$B$2 -> 46121 | C14: =$C$2 -> 46127 | D14: 3260 | E14: 333 | F14: 3 | G14: 1 | H14: GRAHA CIPTA HARDIKA PT- 81455 | I14: AOS | J14: 20622391 | K14: TSH03COR | L14: T-SHIRT CORE DNM BIG FONT WORD 86:WINE:XL | M14: 79900 | N14: 0.95 | O14: =M14-((95*M14)/100) -> 3995 | P14: PERCENTAGE
... A940: =$A$2 -> 2019 ALL ITEM & OLDER D95 | B940: =$B$2 -> 46121 | C940: =$C$2 -> 46127 | D940: 3260 | E940: 333 | F940: 3 | G940: 3 | H940: JAVA DESIGN SENTOSA CV. | I940: AOS | J940: 24925637 | K940: RSJ9M412 | L940: RAGLAN SHORT - HOME RUN 2 RSJ9 M412/BROWN:MISTY LIGHT BR:XL | M940: 99900 | N940: 0.95 | O940: =M940-((95*M940)/100) -> 4995 | P940: PERCENTAGE

Sheet 2020 ALL D85
A1: ACARA | B1: FROM DATE | C1: TO DATE | D1: DEPT | E1: WORLD | F1: DIVISION | G1: CLASS | H1: SUPPLIER | I1: BRAND | J1: SKU | K1: ARTICLE | L1: DESCRIPTION | M1: HARGA NORMAL | N1: DISKON | O1: HARGA PROMO | P1: DISCOUNT TYPE
A2: 2020 ALL D85 | B2: ='2019 ALL N OLDER D95'!$B$2 -> 46121 | C2: ='2019 ALL N OLDER D95'!$C$2 -> 46127 | D2: 3260 | E2: 333 | F2: 3 | G2: 2 | H2: 81461 | I2: AOS | J2: 26311662 | K2: LEB20-L3WH | L2: MUSLIM LONG SLEEVE 2020 - 3 LEB20-L3 WHITE:WHITE:S | M2: 159900 | N2: 0.85 | O2: =M2*(1-N2) -> 23985 | P2: PERCENTAGE
A3: =$A$2 -> 2020 ALL D85 | B3: ='2019 ALL N OLDER D95'!$B$2 -> 46121 | C3: ='2019 ALL N OLDER D95'!$C$2 -> 46127 | D3: 3260 | E3: 333 | F3: 3 | G3: 2 | H3: 81461 | I3: AOS | J3: 26311671 | K3: LEB20-L3WH | L3: MUSLIM LONG SLEEVE 2020 - 3 LEB20-L3 WHITE:WHITE:M | M3: 159900 | N3: =$N2 -> 0.85 | O3: =$O2 -> 23985 | P3: =$P2 -> PERCENTAGE
A4: =$A$2 -> 2020 ALL D85 | B4: ='2019 ALL N OLDER D95'!$B$2 -> 46121 | C4: ='2019 ALL N OLDER D95'!$C$2 -> 46127 | D4: 3260 | E4: 333 | F4: 3 | G4: 2 | H4: 81461 | I4: AOS | J4: 26311680 | K4: LEB20-L3WH | L4: MUSLIM LONG SLEEVE 2020 - 3 LEB20-L3 WHITE:WHITE:L | M4: 159900 | N4: =$N3 -> 0.85 | O4: =$O3 -> 23985 | P4: =$P3 -> PERCENTAGE
A5: =$A$2 -> 2020 ALL D85 | B5: ='2019 ALL N OLDER D95'!$B$2 -> 46121 | C5: ='2019 ALL N OLDER D95'!$C$2 -> 46127 | D5: 3260 | E5: 333 | F5: 3 | G5: 2 | H5: 81461 | I5: AOS | J5: 26311699 | K5: LEB20-L3WH | L5: MUSLIM LONG SLEEVE 2020 - 3 LEB20-L3 WHITE:WHITE:XL | M5: 159900 | N5: =$N4 -> 0.85 | O5: =$O4 -> 23985 | P5: =$P4 -> PERCENTAGE
A6: =$A$2 -> 2020 ALL D85 | B6: ='2019 ALL N OLDER D95'!$B$2 -> 46121 | C6: ='2019 ALL N OLDER D95'!$C$2 -> 46127 | D6: 3260 | E6: 333 | F6: 3 | G6: 2 | H6: 81461 | I6: AOS | J6: 26318923 | K6: LEB20-L4MDB | L6: MUSLIM LONG SLEEVE 2020 - 4 LEB20-L4 MDB:MISTY DARK BRO:S | M6: 159900 | N6: =$N5 -> 0.85 | O6: =$O5 -> 23985 | P6: =$P5 -> PERCENTAGE
A7: =$A$2 -> 2020 ALL D85 | B7: ='2019 ALL N OLDER D95'!$B$2 -> 46121 | C7: ='2019 ALL N OLDER D95'!$C$2 -> 46127 | D7: 3260 | E7: 333 | F7: 3 | G7: 2 | H7: 81461 | I7: AOS | J7: 26318932 | K7: LEB20-L4MDB | L7: MUSLIM LONG SLEEVE 2020 - 4 LEB20-L4 MDB:MISTY DARK BRO:M | M7: 159900 | N7: =$N6 -> 0.85 | O7: =$O6 -> 23985 | P7: =$P6 -> PERCENTAGE
A8: =$A$2 -> 2020 ALL D85 | B8: ='2019 ALL N OLDER D95'!$B$2 -> 46121 | C8: ='2019 ALL N OLDER D95'!$C$2 -> 46127 | D8: 3260 | E8: 333 | F8: 3 | G8: 2 | H8: 81461 | I8: AOS | J8: 26318941 | K8: LEB20-L4MDB | L8: MUSLIM LONG SLEEVE 2020 - 4 LEB20-L4 MDB:MISTY DARK BRO:L | M8: 159900 | N8: =$N7 -> 0.85 | O8: =$O7 -> 23985 | P8: =$P7 -> PERCENTAGE
A9: =$A$2 -> 2020 ALL D85 | B9: ='2019 ALL N OLDER D95'!$B$2 -> 46121 | C9: ='2019 ALL N OLDER D95'!$C$2 -> 46127 | D9: 3260 | E9: 333 | F9: 3 | G9: 2 | H9: 81461 | I9: AOS | J9: 26318950 | K9: LEB20-L4MDB | L9: MUSLIM LONG SLEEVE 2020 - 4 LEB20-L4 MDB:MISTY DARK BRO:XL | M9: 159900 | N9: =$N8 -> 0.85 | O9: =$O8 -> 23985 | P9: =$P8 -> PERCENTAGE
A10: =$A$2 -> 2020 ALL D85 | B10: ='2019 ALL N OLDER D95'!$B$2 -> 46121 | C10: ='2019 ALL N OLDER D95'!$C$2 -> 46127 | D10: 3260 | E10: 333 | F10: 3 | G10: 1 | H10: 81461 | I10: AOS | J10: 26321473 | K10: LEB20-S2WH | L10: MUSLIM SHORT SLEEVE 2020 - 2 LEB20-S2 WHITE:WHITE:S | M10: 149900 | N10: =$N9 -> 0.85 | O10: =$O9 -> 23985 | P10: =$P9 -> PERCENTAGE
A11: =$A$2 -> 2020 ALL D85 | B11: ='2019 ALL N OLDER D95'!$B$2 -> 46121 | C11: ='2019 ALL N OLDER D95'!$C$2 -> 46127 | D11: 3260 | E11: 333 | F11: 3 | G11: 1 | H11: 81461 | I11: AOS | J11: 26321482 | K11: LEB20-S2WH | L11: MUSLIM SHORT SLEEVE 2020 - 2 LEB20-S2 WHITE:WHITE:M | M11: 149900 | N11: =$N10 -> 0.85 | O11: =$O10 -> 23985 | P11: =$P10 -> PERCENTAGE
A12: =$A$2 -> 2020 ALL D85 | B12: ='2019 ALL N OLDER D95'!$B$2 -> 46121 | C12: ='2019 ALL N OLDER D95'!$C$2 -> 46127 | D12: 3260 | E12: 333 | F12: 3 | G12: 1 | H12: 81461 | I12: AOS | J12: 26321491 | K12: LEB20-S2WH | L12: MUSLIM SHORT SLEEVE 2020 - 2 LEB20-S2 WHITE:WHITE:L | M12: 149900 | N12: =$N11 -> 0.85 | O12: =$O11 -> 23985 | P12: =$P11 -> PERCENTAGE
A13: =$A$2 -> 2020 ALL D85 | B13: ='2019 ALL N OLDER D95'!$B$2 -> 46121 | C13: ='2019 ALL N OLDER D95'!$C$2 -> 46127 | D13: 3260 | E13: 333 | F13: 3 | G13: 1 | H13: 81461 | I13: AOS | J13: 26321508 | K13: LEB20-S2WH | L13: MUSLIM SHORT SLEEVE 2020 - 2 LEB20-S2 WHITE:WHITE:XL | M13: 149900 | N13: =$N12 -> 0.85 | O13: =$O12 -> 23985 | P13: =$P12 -> PERCENTAGE
A14: =$A$2 -> 2020 ALL D85 | B14: ='2019 ALL N OLDER D95'!$B$2 -> 46121 | C14: ='2019 ALL N OLDER D95'!$C$2 -> 46127 | D14: 3260 | E14: 333 | F14: 3 | G14: 1 | H14: 81461 | I14: AOS | J14: 26321759 | K14: LEB20-S4WH | L14: MUSLIM SHORT SLEEVE 2020 - 4 LEB20-S4 WHITE:WHITE:S | M14: 149900 | N14: =$N13 -> 0.85 | O14: =$O13 -> 23985 | P14: =$P13 -> PERCENTAGE
... A141: =$A$2 -> 2020 ALL D85 | B141: ='2019 ALL N OLDER D95'!$B$2 -> 46121 | C141: ='2019 ALL N OLDER D95'!$C$2 -> 46127 | D141: 3260 | E141: 333 | F141: 3 | G141: 4 | H141: 81323 | I141: AOS | J141: 27863403 | K141: CNY20-T2 | L141: SS T-SHIRT CNY 2021 - T-SHIRT CHINESE LETTERS CNY CO:CLASSIC RED:XL:GRAPHIC:SS T-SHIRT | M141: 89900 | N141: =$N140 -> 0.85 | O141: =$O140 -> 23985 | P141: =$P140 -> PERCENTAGE
A142: =$A$2 -> 2020 ALL D85 | B142: ='2019 ALL N OLDER D95'!$B$2 -> 46121 | C142: ='2019 ALL N OLDER D95'!$C$2 -> 46127 | D142: 3260 | E142: 333 | F142: 3 | G142: 1 | H142: PUTRA KREASINDO GARM | I142: AOS | J142: 26153208 | K142: STEP1BK | L142: TSHIRT PHOTOPRINT STE CALIFORNIA STEP1 BLACK | M142: 99900 | N142: =$N141 -> 0.85 | O142: =$O141 -> 23985 | P142: =$P141 -> PERCENTAGE
A143: =$A$2 -> 2020 ALL D85 | B143: ='2019 ALL N OLDER D95'!$B$2 -> 46121 | C143: ='2019 ALL N OLDER D95'!$C$2 -> 46127 | D143: 3260 | E143: 333 | F143: 3 | G143: 1 | H143: PUTRA KREASINDO GARM | I143: AOS | J143: 26153217 | K143: STEP1BK | L143: TSHIRT PHOTOPRINT STE CALIFORNIA STEP1 BLACK | M143: 99900 | N143: =$N142 -> 0.85 | O143: =$O142 -> 23985 | P143: =$P142 -> PERCENTAGE
A144: =$A$2 -> 2020 ALL D85 | B144: ='2019 ALL N OLDER D95'!$B$2 -> 46121 | C144: ='2019 ALL N OLDER D95'!$C$2 -> 46127 | D144: 3260 | E144: 333 | F144: 3 | G144: 1 | H144: PUTRA KREASINDO GARM | I144: AOS | J144: 26153226 | K144: STEP1BK | L144: TSHIRT PHOTOPRINT STE CALIFORNIA STEP1 BLACK | M144: 99900 | N144: =$N143 -> 0.85 | O144: =$O143 -> 23985 | P144: =$P143 -> PERCENTAGE
A145: =$A$2 -> 2020 ALL D85 | B145: ='2019 ALL N OLDER D95'!$B$2 -> 46121 | C145: ='2019 ALL N OLDER D95'!$C$2 -> 46127 | D145: 3260 | E145: 333 | F145: 3 | G145: 1 | H145: PUTRA KREASINDO GARM | I145: AOS | J145: 26153235 | K145: STEP1BK | L145: TSHIRT PHOTOPRINT STE CALIFORNIA STEP1 BLACK | M145: 99900 | N145: =$N144 -> 0.85 | O145: =$O144 -> 23985 | P145: =$P144 -> PERCENTAGE
A146: =$A$2 -> 2020 ALL D85 | B146: ='2019 ALL N OLDER D95'!$B$2 -> 46121 | C146: ='2019 ALL N OLDER D95'!$C$2 -> 46127 | D146: 3260 | E146: 333 | F146: 3 | G146: 1 | H146: PUTRA KREASINDO GARM | I146: AOS | J146: 26153244 | K146: STEP1NA | L146: TSHIRT PHOTOPRINT STE ENDLESS SUMMER STEP2 NAVY | M146: 99900 | N146: =$N145 -> 0.85 | O146: =$O145 -> 23985 | P146: =$P145 -> PERCENTAGE
A147: =$A$2 -> 2020 ALL D85 | B147: ='2019 ALL N OLDER D95'!$B$2 -> 46121 | C147: ='2019 ALL N OLDER D95'!$C$2 -> 46127 | D147: 3260 | E147: 333 | F147: 3 | G147: 1 | H147: PUTRA KREASINDO GARM | I147: AOS | J147: 26153253 | K147: STEP1NA | L147: TSHIRT PHOTOPRINT STE ENDLESS SUMMER STEP2 NAVY | M147: 99900 | N147: =$N146 -> 0.85 | O147: =$O146 -> 23985 | P147: =$P146 -> PERCENTAGE
A148: =$A$2 -> 2020 ALL D85 | B148: ='2019 ALL N OLDER D95'!$B$2 -> 46121 | C148: ='2019 ALL N OLDER D95'!$C$2 -> 46127 | D148: 3260 | E148: 333 | F148: 3 | G148: 1 | H148: PUTRA KREASINDO GARM | I148: AOS | J148: 26153262 | K148: STEP1NA | L148: TSHIRT PHOTOPRINT STE ENDLESS SUMMER STEP2 NAVY | M148: 99900 | N148: =$N147 -> 0.85 | O148: =$O147 -> 23985 | P148: =$P147 -> PERCENTAGE
A149: =$A$2 -> 2020 ALL D85 | B149: ='2019 ALL N OLDER D95'!$B$2 -> 46121 | C149: ='2019 ALL N OLDER D95'!$C$2 -> 46127 | D149: 3260 | E149: 333 | F149: 3 | G149: 1 | H149: PUTRA KREASINDO GARM | I149: AOS | J149: 26153271 | K149: STEP1NA | L149: TSHIRT PHOTOPRINT STE ENDLESS SUMMER STEP2 NAVY | M149: 99900 | N149: =$N148 -> 0.85 | O149: =$O148 -> 23985 | P149: =$P148 -> PERCENTAGE
A150: =$A$2 -> 2020 ALL D85 | B150: ='2019 ALL N OLDER D95'!$B$2 -> 46121 | C150: ='2019 ALL N OLDER D95'!$C$2 -> 46127 | D150: 3260 | E150: 333 | F150: 3 | G150: 1 | H150: PUTRA KREASINDO GARM | I150: AOS | J150: 26153280 | K150: STEP3NA | L150: TSHIRT PHOTOPRINT STE SUMMER STEP3 NAVY | M150: 99900 | N150: =$N149 -> 0.85 | O150: =$O149 -> 23985 | P150: =$P149 -> PERCENTAGE
A151: =$A$2 -> 2020 ALL D85 | B151: ='2019 ALL N OLDER D95'!$B$2 -> 46121 | C151: ='2019 ALL N OLDER D95'!$C$2 -> 46127 | D151: 3260 | E151: 333 | F151: 3 | G151: 1 | H151: PUTRA KREASINDO GARM | I151: AOS | J151: 26153299 | K151: STEP3NA | L151: TSHIRT PHOTOPRINT STE SUMMER STEP3 NAVY | M151: 99900 | N151: =$N150 -> 0.85 | O151: =$O150 -> 23985 | P151: =$P150 -> PERCENTAGE
A152: =$A$2 -> 2020 ALL D85 | B152: ='2019 ALL N OLDER D95'!$B$2 -> 46121 | C152: ='2019 ALL N OLDER D95'!$C$2 -> 46127 | D152: 3260 | E152: 333 | F152: 3 | G152: 1 | H152: PUTRA KREASINDO GARM | I152: AOS | J152: 26153306 | K152: STEP3NA | L152: TSHIRT PHOTOPRINT STE SUMMER STEP3 NAVY | M152: 99900 | N152: =$N151 -> 0.85 | O152: =$O151 -> 23985 | P152: =$P151 -> PERCENTAGE
A153: =$A$2 -> 2020 ALL D85 | B153: ='2019 ALL N OLDER D95'!$B$2 -> 46121 | C153: ='2019 ALL N OLDER D95'!$C$2 -> 46127 | D153: 3260 | E153: 333 | F153: 3 | G153: 1 | H153: PUTRA KREASINDO GARM | I153: AOS | J153: 26153315 | K153: STEP3NA | L153: TSHIRT PHOTOPRINT STE SUMMER STEP3 NAVY | M153: 99900 | N153: =$N152 -> 0.85 | O153: =$O152 -> 23985 | P153: =$P152 -> PERCENTAGE
... A1069: =$A$2 -> 2020 ALL D85 | B1069: ='2019 ALL N OLDER D95'!$B$2 -> 46121 | C1069: ='2019 ALL N OLDER D95'!$C$2 -> 46127 | D1069: 3260 | E1069: 333 | F1069: 3 | G1069: 3 | H1069: JAVA DESIGN SENTOSA | I1069: AOS | J1069: 26367531 | K1069: RSBM47 | L1069: RAGLAN SHORT BASIC RSBM47 M47/DARK BROWN 01-20:MISTY DARK BRO:XL | M1069: 89900 | N1069: =$N1068 -> 0.85 | O1069: =$O1068 -> 23985 | P1069: =$P1068 -> PERCENTAGE
A1070: =$A$2 -> 2020 ALL D85 | B1070: ='2019 ALL N OLDER D95'!$B$2 -> 46121 | C1070: ='2019 ALL N OLDER D95'!$C$2 -> 46127 | D1070: 3260 | E1070: 333 | F1070: 3 | G1070: 1 | J1070: 26133248 | K1070: BA-TDBK | L1070: TSHIRT FULLPRINT TIEDYE 1 BA-TDBK BLACK | M1070: 119900 | N1070: =$N1069 -> 0.85 | O1070: =$O1069 -> 23985 | P1070: =$P1069 -> PERCENTAGE
A1071: =$A$2 -> 2020 ALL D85 | B1071: ='2019 ALL N OLDER D95'!$B$2 -> 46121 | C1071: ='2019 ALL N OLDER D95'!$C$2 -> 46127 | D1071: 3260 | E1071: 333 | F1071: 3 | G1071: 1 | J1071: 26133257 | K1071: BA-TDBK | L1071: TSHIRT FULLPRINT TIEDYE 1 BA-TDBK BLACK | M1071: 119900 | N1071: =$N1070 -> 0.85 | O1071: =$O1070 -> 23985 | P1071: =$P1070 -> PERCENTAGE
A1072: =$A$2 -> 2020 ALL D85 | B1072: ='2019 ALL N OLDER D95'!$B$2 -> 46121 | C1072: ='2019 ALL N OLDER D95'!$C$2 -> 46127 | D1072: 3260 | E1072: 333 | F1072: 3 | G1072: 1 | J1072: 26133266 | K1072: BA-TDBK | L1072: TSHIRT FULLPRINT TIEDYE 1 BA-TDBK BLACK | M1072: 119900 | N1072: =$N1071 -> 0.85 | O1072: =$O1071 -> 23985 | P1072: =$P1071 -> PERCENTAGE
A1073: =$A$2 -> 2020 ALL D85 | B1073: ='2019 ALL N OLDER D95'!$B$2 -> 46121 | C1073: ='2019 ALL N OLDER D95'!$C$2 -> 46127 | D1073: 3260 | E1073: 333 | F1073: 3 | G1073: 1 | J1073: 26133275 | K1073: BA-TDBK | L1073: TSHIRT FULLPRINT TIEDYE 1 BA-TDBK BLACK | M1073: 119900 | N1073: =$N1072 -> 0.85 | O1073: =$O1072 -> 23985 | P1073: =$P1072 -> PERCENTAGE
A1074: =$A$2 -> 2020 ALL D85 | B1074: ='2019 ALL N OLDER D95'!$B$2 -> 46121 | C1074: ='2019 ALL N OLDER D95'!$C$2 -> 46127 | D1074: 3260 | E1074: 333 | F1074: 3 | G1074: 1 | J1074: 26133560 | K1074: BA-TDNA | L1074: TSHIRT FULLPRINT TIEDYE 2 BA-TDNA NAVY | M1074: 119900 | N1074: =$N1073 -> 0.85 | O1074: =$O1073 -> 23985 | P1074: =$P1073 -> PERCENTAGE
A1075: =$A$2 -> 2020 ALL D85 | B1075: ='2019 ALL N OLDER D95'!$B$2 -> 46121 | C1075: ='2019 ALL N OLDER D95'!$C$2 -> 46127 | D1075: 3260 | E1075: 333 | F1075: 3 | G1075: 1 | J1075: 26133579 | K1075: BA-TDNA | L1075: TSHIRT FULLPRINT TIEDYE 2 BA-TDNA NAVY | M1075: 119900 | N1075: =$N1074 -> 0.85 | O1075: =$O1074 -> 23985 | P1075: =$P1074 -> PERCENTAGE
A1076: =$A$2 -> 2020 ALL D85 | B1076: ='2019 ALL N OLDER D95'!$B$2 -> 46121 | C1076: ='2019 ALL N OLDER D95'!$C$2 -> 46127 | D1076: 3260 | E1076: 333 | F1076: 3 | G1076: 1 | J1076: 26133588 | K1076: BA-TDNA | L1076: TSHIRT FULLPRINT TIEDYE 2 BA-TDNA NAVY | M1076: 119900 | N1076: =$N1075 -> 0.85 | O1076: =$O1075 -> 23985 | P1076: =$P1075 -> PERCENTAGE
A1077: =$A$2 -> 2020 ALL D85 | B1077: ='2019 ALL N OLDER D95'!$B$2 -> 46121 | C1077: ='2019 ALL N OLDER D95'!$C$2 -> 46127 | D1077: 3260 | E1077: 333 | F1077: 3 | G1077: 1 | J1077: 26133597 | K1077: BA-TDNA | L1077: TSHIRT FULLPRINT TIEDYE 2 BA-TDNA NAVY | M1077: 119900 | N1077: =$N1076 -> 0.85 | O1077: =$O1076 -> 23985 | P1077: =$P1076 -> PERCENTAGE
A1078: =$A$2 -> 2020 ALL D85 | B1078: ='2019 ALL N OLDER D95'!$B$2 -> 46121 | C1078: ='2019 ALL N OLDER D95'!$C$2 -> 46127 | D1078: 3260 | E1078: 333 | F1078: 3 | G1078: 1 | J1078: 26133524 | K1078: BA-TDOL | L1078: TSHIRT FULLPRINT TIEDYE 2 BA-TDOL OLIVE | M1078: 119900 | N1078: =$N1077 -> 0.85 | O1078: =$O1077 -> 23985 | P1078: =$P1077 -> PERCENTAGE
A1079: =$A$2 -> 2020 ALL D85 | B1079: ='2019 ALL N OLDER D95'!$B$2 -> 46121 | C1079: ='2019 ALL N OLDER D95'!$C$2 -> 46127 | D1079: 3260 | E1079: 333 | F1079: 3 | G1079: 1 | J1079: 26133533 | K1079: BA-TDOL | L1079: TSHIRT FULLPRINT TIEDYE 2 BA-TDOL OLIVE | M1079: 119900 | N1079: =$N1078 -> 0.85 | O1079: =$O1078 -> 23985 | P1079: =$P1078 -> PERCENTAGE
A1080: =$A$2 -> 2020 ALL D85 | B1080: ='2019 ALL N OLDER D95'!$B$2 -> 46121 | C1080: ='2019 ALL N OLDER D95'!$C$2 -> 46127 | D1080: 3260 | E1080: 333 | F1080: 3 | G1080: 1 | J1080: 26133542 | K1080: BA-TDOL | L1080: TSHIRT FULLPRINT TIEDYE 2 BA-TDOL OLIVE | M1080: 119900 | N1080: =$N1079 -> 0.85 | O1080: =$O1079 -> 23985 | P1080: =$P1079 -> PERCENTAGE
A1081: =$A$2 -> 2020 ALL D85 | B1081: ='2019 ALL N OLDER D95'!$B$2 -> 46121 | C1081: ='2019 ALL N OLDER D95'!$C$2 -> 46127 | D1081: 3260 | E1081: 333 | F1081: 3 | G1081: 1 | J1081: 26133551 | K1081: BA-TDOL | L1081: TSHIRT FULLPRINT TIEDYE 2 BA-TDOL OLIVE | M1081: 119900 | N1081: =$N1080 -> 0.85 | O1081: =$O1080 -> 23985 | P1081: =$P1080 -> PERCENTAGE
...

Sheet 2021 ALL D85
A1: ACARA | B1: FROM DATE | C1: TO DATE | D1: DEPT | E1: WORLD | F1: DIVISION | G1: CLASS | H1: SUPPLIER | I1: BRAND | J1: SKU | K1: ARTICLE | L1: DESCRIPTION | M1: HARGA NORMAL | N1: DISKON | O1: HARGA PROMO | P1: DISCOUNT TYPE
A2: 2021 ALL D85 | B2: ='2019 ALL N OLDER D95'!$B$2 -> 46121 | C2: ='2019 ALL N OLDER D95'!$C$2 -> 46127 | D2: 3260 | E2: 333 | F2: 3 | G2: 3 | H2: JAVA DESIGN SENTOSA CV. | I2: AOS | J2: 24398181 | K2: KIRSNA | L2: KI RAGLAN BASIC SHORT NAVY/M41 07-19:NAVY BLUE:S | M2: 89900 | N2: 0.85 | O2: =M2*(1-N2) -> 13485 | P2: PERCENTAGE
A3: =$A$2 -> 2021 ALL D85 | B3: ='2019 ALL N OLDER D95'!$B$2 -> 46121 | C3: ='2019 ALL N OLDER D95'!$C$2 -> 46127 | D3: 3260 | E3: 333 | F3: 3 | G3: 3 | H3: JAVA DESIGN SENTOSA CV. | I3: AOS | J3: 24398190 | K3: KIRSNA | L3: KI RAGLAN BASIC SHORT NAVY/M41 07-19:NAVY BLUE:M | M3: 89900 | N3: =$N2 -> 0.85 | O3: =$O2 -> 13485 | P3: =$P2 -> PERCENTAGE
A4: =$A$2 -> 2021 ALL D85 | B4: ='2019 ALL N OLDER D95'!$B$2 -> 46121 | C4: ='2019 ALL N OLDER D95'!$C$2 -> 46127 | D4: 3260 | E4: 333 | F4: 3 | G4: 3 | H4: JAVA DESIGN SENTOSA CV. | I4: AOS | J4: 24398207 | K4: KIRSNA | L4: KI RAGLAN BASIC SHORT NAVY/M41 07-19:NAVY BLUE:L | M4: 89900 | N4: =$N3 -> 0.85 | O4: =$O3 -> 13485 | P4: =$P3 -> PERCENTAGE
A5: =$A$2 -> 2021 ALL D85 | B5: ='2019 ALL N OLDER D95'!$B$2 -> 46121 | C5: ='2019 ALL N OLDER D95'!$C$2 -> 46127 | D5: 3260 | E5: 333 | F5: 3 | G5: 3 | H5: JAVA DESIGN SENTOSA CV. | I5: AOS | J5: 24398216 | K5: KIRSNA | L5: KI RAGLAN BASIC SHORT NAVY/M41 07-19:NAVY BLUE:XL | M5: 89900 | N5: =$N4 -> 0.85 | O5: =$O4 -> 13485 | P5: =$P4 -> PERCENTAGE
A6: =$A$2 -> 2021 ALL D85 | B6: ='2019 ALL N OLDER D95'!$B$2 -> 46121 | C6: ='2019 ALL N OLDER D95'!$C$2 -> 46127 | D6: 3260 | E6: 333 | F6: 3 | G6: 3 | H6: JAVA DESIGN SENTOSA CV. | I6: AOS | J6: 24398225 | K6: KIRSTO | L6: KI RAGLAN BASIC SHORT TOSCA/3T BLUE 07-19:TURQUOISE:S | M6: 89900 | N6: =$N5 -> 0.85 | O6: =$O5 -> 13485 | P6: =$P5 -> PERCENTAGE
A7: =$A$2 -> 2021 ALL D85 | B7: ='2019 ALL N OLDER D95'!$B$2 -> 46121 | C7: ='2019 ALL N OLDER D95'!$C$2 -> 46127 | D7: 3260 | E7: 333 | F7: 3 | G7: 3 | H7: JAVA DESIGN SENTOSA CV. | I7: AOS | J7: 24398234 | K7: KIRSTO | L7: KI RAGLAN BASIC SHORT TOSCA/3T BLUE 07-19:TURQUOISE:M | M7: 89900 | N7: =$N6 -> 0.85 | O7: =$O6 -> 13485 | P7: =$P6 -> PERCENTAGE
A8: =$A$2 -> 2021 ALL D85 | B8: ='2019 ALL N OLDER D95'!$B$2 -> 46121 | C8: ='2019 ALL N OLDER D95'!$C$2 -> 46127 | D8: 3260 | E8: 333 | F8: 3 | G8: 3 | H8: JAVA DESIGN SENTOSA CV. | I8: AOS | J8: 24398243 | K8: KIRSTO | L8: KI RAGLAN BASIC SHORT TOSCA/3T BLUE 07-19:TURQUOISE:L | M8: 89900 | N8: =$N7 -> 0.85 | O8: =$O7 -> 13485 | P8: =$P7 -> PERCENTAGE
A9: =$A$2 -> 2021 ALL D85 | B9: ='2019 ALL N OLDER D95'!$B$2 -> 46121 | C9: ='2019 ALL N OLDER D95'!$C$2 -> 46127 | D9: 3260 | E9: 333 | F9: 3 | G9: 3 | H9: JAVA DESIGN SENTOSA CV. | I9: AOS | J9: 24398252 | K9: KIRSTO | L9: KI RAGLAN BASIC SHORT TOSCA/3T BLUE 07-19:TURQUOISE:XL | M9: 89900 | N9: =$N8 -> 0.85 | O9: =$O8 -> 13485 | P9: =$P8 -> PERCENTAGE
A10: =$A$2 -> 2021 ALL D85 | B10: ='2019 ALL N OLDER D95'!$B$2 -> 46121 | C10: ='2019 ALL N OLDER D95'!$C$2 -> 46127 | D10: 3260 | E10: 333 | F10: 3 | G10: 3 | H10: JAVA DESIGN SENTOSA CV. | I10: AOS | J10: 24398305 | K10: KIRSYE | L10: KI RAGLAN BASIC SHORTYELLOW/CHARCOAL 07-19 :CLASSIC YELLOW:S | M10: 89900 | N10: =$N9 -> 0.85 | O10: =$O9 -> 13485 | P10: =$P9 -> PERCENTAGE
A11: =$A$2 -> 2021 ALL D85 | B11: ='2019 ALL N OLDER D95'!$B$2 -> 46121 | C11: ='2019 ALL N OLDER D95'!$C$2 -> 46127 | D11: 3260 | E11: 333 | F11: 3 | G11: 3 | H11: JAVA DESIGN SENTOSA CV. | I11: AOS | J11: 24398314 | K11: KIRSYE | L11: KI RAGLAN BASIC SHORTYELLOW/CHARCOAL 07-19:CLASSIC YELLOW:M | M11: 89900 | N11: =$N10 -> 0.85 | O11: =$O10 -> 13485 | P11: =$P10 -> PERCENTAGE
A12: =$A$2 -> 2021 ALL D85 | B12: ='2019 ALL N OLDER D95'!$B$2 -> 46121 | C12: ='2019 ALL N OLDER D95'!$C$2 -> 46127 | D12: 3260 | E12: 333 | F12: 3 | G12: 3 | H12: JAVA DESIGN SENTOSA CV. | I12: AOS | J12: 24398323 | K12: KIRSYE | L12: KI RAGLAN BASIC SHORTYELLOW/CHARCOAL 07-19:CLASSIC YELLOW:L | M12: 89900 | N12: =$N11 -> 0.85 | O12: =$O11 -> 13485 | P12: =$P11 -> PERCENTAGE
A13: =$A$2 -> 2021 ALL D85 | B13: ='2019 ALL N OLDER D95'!$B$2 -> 46121 | C13: ='2019 ALL N OLDER D95'!$C$2 -> 46127 | D13: 3260 | E13: 333 | F13: 3 | G13: 3 | H13: JAVA DESIGN SENTOSA CV. | I13: AOS | J13: 24398332 | K13: KIRSYE | L13: KI RAGLAN BASIC SHORTYELLOW/CHARCOAL 07-19:CLASSIC YELLOW:XL | M13: 89900 | N13: =$N12 -> 0.85 | O13: =$O12 -> 13485 | P13: =$P12 -> PERCENTAGE
A14: =$A$2 -> 2021 ALL D85 | B14: ='2019 ALL N OLDER D95'!$B$2 -> 46121 | C14: ='2019 ALL N OLDER D95'!$C$2 -> 46127 | D14: 3260 | E14: 333 | F14: 3 | G14: 5 | H14: JAVA DESIGN | I14: AOS | J14: 20140563 | K14: KI-R34PA | L14: KI RAGLAN BASIC 3/4 POCKET 05-17 105:WINE:XL | M14: 89900 | N14: =$N13 -> 0.85 | O14: =$O13 -> 13485 | P14: =$P13 -> PERCENTAGE
... A252: =$A$2 -> 2021 ALL D85 | B252: ='2019 ALL N OLDER D95'!$B$2 -> 46121 | C252: ='2019 ALL N OLDER D95'!$C$2 -> 46127 | D252: 3260 | E252: 333 | F252: 3 | G252: 1 | H252: JAVA DESIGN SENTOSA | I252: AOS | J252: 32639842 | K252: ID21TJ1 | L252: SS T-SHIRT INDONESIA COLL 2021 - IND ONESIAN MAP ID21TJ1:CLASSIC RE:S:GRAPHIC:SS T-SHIRT | M252: 99900 | N252: =$N251 -> 0.85 | O252: =$O251 -> 13485 | P252: =$P251 -> PERCENTAGE
A253: =$A$2 -> 2021 ALL D85 | B253: ='2019 ALL N OLDER D95'!$B$2 -> 46121 | C253: ='2019 ALL N OLDER D95'!$C$2 -> 46127 | D253: 3260 | E253: 333 | F253: 3 | G253: 1 | H253: JAVA DESIGN SENTOSA | I253: AOS | J253: 32639851 | K253: ID21TJ1 | L253: SS T-SHIRT INDONESIA COLL 2021 - IND ONESIAN MAP ID21TJ1:CLASSIC RE:M:GRAPHIC:SS T-SHIRT | M253: 99900 | N253: =$N252 -> 0.85 | O253: =$O252 -> 13485 | P253: =$P252 -> PERCENTAGE
A254: =$A$2 -> 2021 ALL D85 | B254: ='2019 ALL N OLDER D95'!$B$2 -> 46121 | C254: ='2019 ALL N OLDER D95'!$C$2 -> 46127 | D254: 3260 | E254: 333 | F254: 3 | G254: 1 | H254: JAVA DESIGN SENTOSA | I254: AOS | J254: 32639860 | K254: ID21TJ1 | L254: SS T-SHIRT INDONESIA COLL 2021 - IND ONESIAN MAP ID21TJ1:CLASSIC RE:L:GRAPHIC:SS T-SHIRT | M254: 99900 | N254: =$N253 -> 0.85 | O254: =$O253 -> 13485 | P254: =$P253 -> PERCENTAGE
A255: =$A$2 -> 2021 ALL D85 | B255: ='2019 ALL N OLDER D95'!$B$2 -> 46121 | C255: ='2019 ALL N OLDER D95'!$C$2 -> 46127 | D255: 3260 | E255: 333 | F255: 3 | G255: 1 | H255: JAVA DESIGN SENTOSA | I255: AOS | J255: 32639879 | K255: ID21TJ1 | L255: SS T-SHIRT INDONESIA COLL 2021 - IND ONESIAN MAP ID21TJ1:CLASSIC RE:XL:GRAPHIC:SS T-SHIRT | M255: 99900 | N255: =$N254 -> 0.85 | O255: =$O254 -> 13485 | P255: =$P254 -> PERCENTAGE
A256: =$A$2 -> 2021 ALL D85 | B256: ='2019 ALL N OLDER D95'!$B$2 -> 46121 | C256: ='2019 ALL N OLDER D95'!$C$2 -> 46127 | D256: 3260 | E256: 333 | F256: 3 | G256: 1 | H256: JAVA DESIGN SENTOSA | I256: AOS | J256: 32639922 | K256: ID21TJ2 | L256: SS T-SHIRT INDONESIA COLL 2021 - GOD BLESS INDONESIA:WHITE:S:TEXT:SS T-SHIRT | M256: 99900 | N256: =$N255 -> 0.85 | O256: =$O255 -> 13485 | P256: =$P255 -> PERCENTAGE
A257: =$A$2 -> 2021 ALL D85 | B257: ='2019 ALL N OLDER D95'!$B$2 -> 46121 | C257: ='2019 ALL N OLDER D95'!$C$2 -> 46127 | D257: 3260 | E257: 333 | F257: 3 | G257: 1 | H257: JAVA DESIGN SENTOSA | I257: AOS | J257: 32639931 | K257: ID21TJ2 | L257: SS T-SHIRT INDONESIA COLL 2021 - GOD BLESS INDONESIA:WHITE:M:TEXT:SS T-SHIRT | M257: 99900 | N257: =$N256 -> 0.85 | O257: =$O256 -> 13485 | P257: =$P256 -> PERCENTAGE
A258: =$A$2 -> 2021 ALL D85 | B258: ='2019 ALL N OLDER D95'!$B$2 -> 46121 | C258: ='2019 ALL N OLDER D95'!$C$2 -> 46127 | D258: 3260 | E258: 333 | F258: 3 | G258: 1 | H258: JAVA DESIGN SENTOSA | I258: AOS | J258: 32639940 | K258: ID21TJ2 | L258: SS T-SHIRT INDONESIA COLL 2021 - GOD BLESS INDONESIA:WHITE:L:TEXT:SS T-SHIRT | M258: 99900 | N258: =$N257 -> 0.85 | O258: =$O257 -> 13485 | P258: =$P257 -> PERCENTAGE
A259: =$A$2 -> 2021 ALL D85 | B259: ='2019 ALL N OLDER D95'!$B$2 -> 46121 | C259: ='2019 ALL N OLDER D95'!$C$2 -> 46127 | D259: 3260 | E259: 333 | F259: 3 | G259: 1 | H259: JAVA DESIGN SENTOSA | I259: AOS | J259: 32639959 | K259: ID21TJ2 | L259: SS T-SHIRT INDONESIA COLL 2021 - GOD BLESS INDONESIA:WHITE:XL:TEXT:SS T-SHIRT | M259: 99900 | N259: =$N258 -> 0.85 | O259: =$O258 -> 13485 | P259: =$P258 -> PERCENTAGE
A260: =$A$2 -> 2021 ALL D85 | B260: ='2019 ALL N OLDER D95'!$B$2 -> 46121 | C260: ='2019 ALL N OLDER D95'!$C$2 -> 46127 | D260: 3260 | E260: 333 | F260: 3 | G260: 1 | H260: JAVA DESIGN SENTOSA | I260: AOS | J260: 32640009 | K260: ID21TJ3 | L260: SS T-SHIRT INDONESIA COLL 2021 - PRINT BATIK 1 ID21TJ3:BLACK:S:GRAPHIC:SS T-SHIRT | M260: 99900 | N260: =$N259 -> 0.85 | O260: =$O259 -> 13485 | P260: =$P259 -> PERCENTAGE
A261: =$A$2 -> 2021 ALL D85 | B261: ='2019 ALL N OLDER D95'!$B$2 -> 46121 | C261: ='2019 ALL N OLDER D95'!$C$2 -> 46127 | D261: 3260 | E261: 333 | F261: 3 | G261: 1 | H261: JAVA DESIGN SENTOSA | I261: AOS | J261: 32640018 | K261: ID21TJ3 | L261: SS T-SHIRT INDONESIA COLL 2021 - PRINT BATIK 1 ID21TJ3:BLACK:M:GRAPHIC:SS T-SHIRT | M261: 99900 | N261: =$N260 -> 0.85 | O261: =$O260 -> 13485 | P261: =$P260 -> PERCENTAGE
A262: =$A$2 -> 2021 ALL D85 | B262: ='2019 ALL N OLDER D95'!$B$2 -> 46121 | C262: ='2019 ALL N OLDER D95'!$C$2 -> 46127 | D262: 3260 | E262: 333 | F262: 3 | G262: 1 | H262: JAVA DESIGN SENTOSA | I262: AOS | J262: 32640027 | K262: ID21TJ3 | L262: SS T-SHIRT INDONESIA COLL 2021 - PRINT BATIK 1 ID21TJ3:BLACK:L:GRAPHIC:SS T-SHIRT | M262: 99900 | N262: =$N261 -> 0.85 | O262: =$O261 -> 13485 | P262: =$P261 -> PERCENTAGE
A263: =$A$2 -> 2021 ALL D85 | B263: ='2019 ALL N OLDER D95'!$B$2 -> 46121 | C263: ='2019 ALL N OLDER D95'!$C$2 -> 46127 | D263: 3260 | E263: 333 | F263: 3 | G263: 1 | H263: JAVA DESIGN SENTOSA | I263: AOS | J263: 32640036 | K263: ID21TJ3 | L263: SS T-SHIRT INDONESIA COLL 2021 - PRINT BATIK 1 ID21TJ3:BLACK:XL:GRAPHIC:SS T-SHIRT | M263: 99900 | N263: =$N262 -> 0.85 | O263: =$O262 -> 13485 | P263: =$P262 -> PERCENTAGE
A264: =$A$2 -> 2021 ALL D85 | B264: ='2019 ALL N OLDER D95'!$B$2 -> 46121 | C264: ='2019 ALL N OLDER D95'!$C$2 -> 46127 | D264: 3260 | E264: 333 | F264: 3 | G264: 1 | H264: JAVA DESIGN SENTOSA | I264: AOS | J264: 32640045 | K264: ID21TJ3 | L264: SS T-SHIRT INDONESIA COLL 2021 - PRINT BATIK 1 ID21TJ3:CLASSIC RE:S:GRAPHIC:SS T-SHIRT | M264: 99900 | N264: =$N263 -> 0.85 | O264: =$O263 -> 13485 | P264: =$P263 -> PERCENTAGE
... A287: =$A$2 -> 2021 ALL D85 | B287: ='2019 ALL N OLDER D95'!$B$2 -> 46121 | C287: ='2019 ALL N OLDER D95'!$C$2 -> 46127 | D287: 3260 | E287: 333 | F287: 3 | G287: 2 | H287: JAVA DESIGN SENTOSA | I287: AOS | J287: 32641151 | K287: ID21LJ1 | L287: LS T-SHIRT INDONESIA COLL 2021 - INDONESIA IS AWESOM:MISTY LIGHT:XL:TEXT:LS T-SHIRT | M287: 109900 | N287: =$N286 -> 0.85 | O287: =$O286 -> 13485 | P287: =$P286 -> PERCENTAGE
A288: =$A$2 -> 2021 ALL D85 | B288: ='2019 ALL N OLDER D95'!B2 -> 46121 | C288: ='2019 ALL N OLDER D95'!C2 -> 46127 | D288: 3260 | E288: 333 | F288: 3 | G288: 1 | H288: 81461 | I288: AOS | J288: 28093485 | K288: LEB21-S3 | L288: SS KOKO MUSLIM SHORT SLEEVE 2021 - MISTY DARK BROWN:KHAKI:S:TEXTURE:SS KOKO | M288: 149900 | N288: =$N287 -> 0.85 | O288: =$O287 -> 13485 | P288: =$P287 -> PERCENTAGE
A289: =$A$2 -> 2021 ALL D85 | B289: ='2019 ALL N OLDER D95'!B3 -> 46121 | C289: ='2019 ALL N OLDER D95'!C3 -> 46127 | D289: 3260 | E289: 333 | F289: 3 | G289: 1 | H289: 81461 | I289: AOS | J289: 28093494 | K289: LEB21-S3 | L289: SS KOKO MUSLIM SHORT SLEEVE 2021 - MISTY DARK BROWN:KHAKI:M:TEXTURE:SS KOKO | M289: 149900 | N289: =$N288 -> 0.85 | O289: =$O288 -> 13485 | P289: =$P288 -> PERCENTAGE
A290: =$A$2 -> 2021 ALL D85 | B290: ='2019 ALL N OLDER D95'!B4 -> 46121 | C290: ='2019 ALL N OLDER D95'!C4 -> 46127 | D290: 3260 | E290: 333 | F290: 3 | G290: 1 | H290: 81461 | I290: AOS | J290: 28093501 | K290: LEB21-S3 | L290: SS KOKO MUSLIM SHORT SLEEVE 2021 - MISTY DARK BROWN:KHAKI:L:TEXTURE:SS KOKO | M290: 149900 | N290: =$N289 -> 0.85 | O290: =$O289 -> 13485 | P290: =$P289 -> PERCENTAGE
A291: =$A$2 -> 2021 ALL D85 | B291: ='2019 ALL N OLDER D95'!B5 -> 46121 | C291: ='2019 ALL N OLDER D95'!C5 -> 46127 | D291: 3260 | E291: 333 | F291: 3 | G291: 1 | H291: 81461 | I291: AOS | J291: 28093510 | K291: LEB21-S3 | L291: SS KOKO MUSLIM SHORT SLEEVE 2021 - MISTY DARK BROWN:KHAKI:XL:TEXTURE:SS KOKO | M291: 149900 | N291: =$N290 -> 0.85 | O291: =$O290 -> 13485 | P291: =$P290 -> PERCENTAGE
A292: =$A$2 -> 2021 ALL D85 | B292: ='2019 ALL N OLDER D95'!B6 -> 46121 | C292: ='2019 ALL N OLDER D95'!C6 -> 46127 | D292: 3260 | E292: 333 | F292: 3 | G292: 1 | H292: 81461 | I292: AOS | J292: 28093403 | K292: LEB21-S7 | L292: SS KOKO MUSLIM SHORT SLEEVE 2021 - WHITE LEB21-S7:WHITE:S:TEXTURE:SS KOKO | M292: 149900 | N292: =$N291 -> 0.85 | O292: =$O291 -> 13485 | P292: =$P291 -> PERCENTAGE
A293: =$A$2 -> 2021 ALL D85 | B293: ='2019 ALL N OLDER D95'!B7 -> 46121 | C293: ='2019 ALL N OLDER D95'!C7 -> 46127 | D293: 3260 | E293: 333 | F293: 3 | G293: 1 | H293: 81461 | I293: AOS | J293: 28093412 | K293: LEB21-S7 | L293: SS KOKO MUSLIM SHORT SLEEVE 2021 - WHITE LEB21-S7:WHITE:M:TEXTURE:SS KOKO | M293: 149900 | N293: =$N292 -> 0.85 | O293: =$O292 -> 13485 | P293: =$P292 -> PERCENTAGE
A294: =$A$2 -> 2021 ALL D85 | B294: ='2019 ALL N OLDER D95'!B8 -> 46121 | C294: ='2019 ALL N OLDER D95'!C8 -> 46127 | D294: 3260 | E294: 333 | F294: 3 | G294: 1 | H294: 81461 | I294: AOS | J294: 28093421 | K294: LEB21-S7 | L294: SS KOKO MUSLIM SHORT SLEEVE 2021 - WHITE LEB21-S7:WHITE:L:TEXTURE:SS KOKO | M294: 149900 | N294: =$N293 -> 0.85 | O294: =$O293 -> 13485 | P294: =$P293 -> PERCENTAGE
A295: =$A$2 -> 2021 ALL D85 | B295: ='2019 ALL N OLDER D95'!B9 -> 46121 | C295: ='2019 ALL N OLDER D95'!C9 -> 46127 | D295: 3260 | E295: 333 | F295: 3 | G295: 1 | H295: 81461 | I295: AOS | J295: 28093430 | K295: LEB21-S7 | L295: SS KOKO MUSLIM SHORT SLEEVE 2021 - WHITE LEB21-S7:WHITE:XL:TEXTURE:SS KOKO | M295: 149900 | N295: =$N294 -> 0.85 | O295: =$O294 -> 13485 | P295: =$P294 -> PERCENTAGE
A296: =$A$2 -> 2021 ALL D85 | B296: ='2019 ALL N OLDER D95'!B10 -> 46121 | C296: ='2019 ALL N OLDER D95'!C10 -> 46127 | D296: 3260 | E296: 333 | F296: 3 | G296: 1 | H296: 81461 | I296: AOS | J296: 28093645 | K296: LEB21-S11 | L296: SS KOKO MUSLIM SHORT SLEEVE 2021 - KHAKI LEB21-S11:KHAKI:S:TEXTURE:SS KOKO | M296: 149900 | N296: =$N295 -> 0.85 | O296: =$O295 -> 13485 | P296: =$P295 -> PERCENTAGE
A297: =$A$2 -> 2021 ALL D85 | B297: ='2019 ALL N OLDER D95'!B11 -> 46121 | C297: ='2019 ALL N OLDER D95'!C11 -> 46127 | D297: 3260 | E297: 333 | F297: 3 | G297: 1 | H297: 81461 | I297: AOS | J297: 28093654 | K297: LEB21-S11 | L297: SS KOKO MUSLIM SHORT SLEEVE 2021 - KHAKI LEB21-S11:KHAKI:M:TEXTURE:SS KOKO | M297: 149900 | N297: =$N296 -> 0.85 | O297: =$O296 -> 13485 | P297: =$P296 -> PERCENTAGE
A298: =$A$2 -> 2021 ALL D85 | B298: ='2019 ALL N OLDER D95'!B12 -> 46121 | C298: ='2019 ALL N OLDER D95'!C12 -> 46127 | D298: 3260 | E298: 333 | F298: 3 | G298: 1 | H298: 81461 | I298: AOS | J298: 28093663 | K298: LEB21-S11 | L298: SS KOKO MUSLIM SHORT SLEEVE 2021 - KHAKI LEB21-S11:KHAKI:L:TEXTURE:SS KOKO | M298: 149900 | N298: =$N297 -> 0.85 | O298: =$O297 -> 13485 | P298: =$P297 -> PERCENTAGE
A299: =$A$2 -> 2021 ALL D85 | B299: ='2019 ALL N OLDER D95'!B13 -> 46121 | C299: ='2019 ALL N OLDER D95'!C13 -> 46127 | D299: 3260 | E299: 333 | F299: 3 | G299: 1 | H299: 81461 | I299: AOS | J299: 28093672 | K299: LEB21-S11 | L299: SS KOKO MUSLIM SHORT SLEEVE 2021 - KHAKI LEB21-S11:KHAKI:XL:TEXTURE:SS KOKO | M299: 149900 | N299: =$N298 -> 0.85 | O299: =$O298 -> 13485 | P299: =$P298 -> PERCENTAGE
...

Sheet 2022 ALL D85
A1: ACARA | B1: FROM DATE | C1: TO DATE | D1: DEPT | E1: WORLD | F1: DIVISION | G1: CLASS | H1: SUPPLIER | I1: BRAND | J1: SKU | K1: ARTICLE | L1: DESCRIPTION | M1: HARGA NORMAL | N1: DISKON | O1: HARGA PROMO | P1: DISCOUNT TYPE
A2: 2022 ALL D85 | B2: ='2019 ALL N OLDER D95'!$B$2 -> 46121 | C2: ='2019 ALL N OLDER D95'!$C$2 -> 46127 | D2: 3260 | E2: 333 | F2: 3 | G2: 1 | H2: FECEKRAN SANDANG JAYA PT.-81235 | I2: AOS | J2: 73433353 | K2: TFUF5-AB | L2: SS T-SHIRT FULLPRINT AOP THEME SUMMERTIME- LEAF TFUF5-AB:DUSTY PIN:XL:PRINT:SS T-SHIR | M2: 119900 | N2: 0.85 | O2: =M2*(1-N2) -> 17985 | P2: PERCENTAGE
A3: =$A$2 -> 2022 ALL D85 | B3: ='2019 ALL N OLDER D95'!$B$2 -> 46121 | C3: ='2019 ALL N OLDER D95'!$C$2 -> 46127 | D3: 3260 | E3: 333 | F3: 3 | G3: 1 | H3: FECEKRAN SANDANG JAYA PT.-81235 | I3: AOS | J3: 73433344 | K3: TFUF5-AB | L3: SS T-SHIRT FULLPRINT AOP THEME SUMMERTIME- LEAF TFUF5-AB:DUSTY PIN:L:PRINT:SS T-SHIR | M3: 119900 | N3: =$N$2 -> 0.85 | O3: =$O2 -> 17985 | P3: =$P$2 -> PERCENTAGE
A4: =$A$2 -> 2022 ALL D85 | B4: ='2019 ALL N OLDER D95'!$B$2 -> 46121 | C4: ='2019 ALL N OLDER D95'!$C$2 -> 46127 | D4: 3260 | E4: 333 | F4: 3 | G4: 1 | H4: FECEKRAN SANDANG JAYA PT.-81235 | I4: AOS | J4: 73433335 | K4: TFUF5-AB | L4: SS T-SHIRT FULLPRINT AOP THEME SUMMERTIME- LEAF TFUF5-AB:DUSTY PIN:M:PRINT:SS T-SHIR | M4: 119900 | N4: =$N$2 -> 0.85 | O4: =$O3 -> 17985 | P4: =$P$2 -> PERCENTAGE
A5: =$A$2 -> 2022 ALL D85 | B5: ='2019 ALL N OLDER D95'!$B$2 -> 46121 | C5: ='2019 ALL N OLDER D95'!$C$2 -> 46127 | D5: 3260 | E5: 333 | F5: 3 | G5: 1 | H5: FECEKRAN SANDANG JAYA PT.-81235 | I5: AOS | J5: 73433326 | K5: TFUF5-AB | L5: SS T-SHIRT FULLPRINT AOP THEME SUMMERTIME- LEAF TFUF5-AB:DUSTY PIN:S:PRINT:SS T-SHIR | M5: 119900 | N5: =$N$2 -> 0.85 | O5: =$O4 -> 17985 | P5: =$P$2 -> PERCENTAGE
A6: =$A$2 -> 2022 ALL D85 | B6: ='2019 ALL N OLDER D95'!$B$2 -> 46121 | C6: ='2019 ALL N OLDER D95'!$C$2 -> 46127 | D6: 3260 | E6: 333 | F6: 3 | G6: 1 | H6: FECEKRAN SANDANG JAYA PT.-81235 | I6: AOS | J6: 73433317 | K6: TFUF5-AB | L6: SS T-SHIRT FULLPRINT AOP THEME SUMMERTIME- LEAF TFUF5-AB:MUSTARD:XL:PRINT:SS T-SHIR | M6: 119900 | N6: =$N$2 -> 0.85 | O6: =$O5 -> 17985 | P6: =$P$2 -> PERCENTAGE
A7: =$A$2 -> 2022 ALL D85 | B7: ='2019 ALL N OLDER D95'!$B$2 -> 46121 | C7: ='2019 ALL N OLDER D95'!$C$2 -> 46127 | D7: 3260 | E7: 333 | F7: 3 | G7: 1 | H7: FECEKRAN SANDANG JAYA PT.-81235 | I7: AOS | J7: 73433308 | K7: TFUF5-AB | L7: SS T-SHIRT FULLPRINT AOP THEME SUMMERTIME- LEAF TFUF5-AB:MUSTARD:L:PRINT:SS T-SHIR | M7: 119900 | N7: =$N$2 -> 0.85 | O7: =$O6 -> 17985 | P7: =$P$2 -> PERCENTAGE
A8: =$A$2 -> 2022 ALL D85 | B8: ='2019 ALL N OLDER D95'!$B$2 -> 46121 | C8: ='2019 ALL N OLDER D95'!$C$2 -> 46127 | D8: 3260 | E8: 333 | F8: 3 | G8: 1 | H8: FECEKRAN SANDANG JAYA PT.-81235 | I8: AOS | J8: 73433291 | K8: TFUF5-AB | L8: SS T-SHIRT FULLPRINT AOP THEME SUMMERTIME- LEAF TFUF5-AB:MUSTARD:M:PRINT:SS T-SHIR | M8: 119900 | N8: =$N$2 -> 0.85 | O8: =$O7 -> 17985 | P8: =$P$2 -> PERCENTAGE
A9: =$A$2 -> 2022 ALL D85 | B9: ='2019 ALL N OLDER D95'!$B$2 -> 46121 | C9: ='2019 ALL N OLDER D95'!$C$2 -> 46127 | D9: 3260 | E9: 333 | F9: 3 | G9: 1 | H9: FECEKRAN SANDANG JAYA PT.-81235 | I9: AOS | J9: 73433282 | K9: TFUF5-AB | L9: SS T-SHIRT FULLPRINT AOP THEME SUMMERTIME- LEAF TFUF5-AB:MUSTARD:S:PRINT:SS T-SHIR | M9: 119900 | N9: =$N$2 -> 0.85 | O9: =$O8 -> 17985 | P9: =$P$2 -> PERCENTAGE
A10: =$A$2 -> 2022 ALL D85 | B10: ='2019 ALL N OLDER D95'!$B$2 -> 46121 | C10: ='2019 ALL N OLDER D95'!$C$2 -> 46127 | D10: 3260 | E10: 333 | F10: 3 | G10: 4 | H10: JAVA DESIGN SENTOSA CV. | I10: AOS | J10: 71529254 | K10: WBTF5-4 | L10: SS T-SHIRT WB FRIENDS - 4 WBTF5-4:WHITE:XL:GRAPHIC:SS T-SHIRT | M10: 129900 | N10: =$N$2 -> 0.85 | O10: =$O9 -> 17985 | P10: =$P$2 -> PERCENTAGE
A11: =$A$2 -> 2022 ALL D85 | B11: ='2019 ALL N OLDER D95'!$B$2 -> 46121 | C11: ='2019 ALL N OLDER D95'!$C$2 -> 46127 | D11: 3260 | E11: 333 | F11: 3 | G11: 4 | H11: JAVA DESIGN SENTOSA CV. | I11: AOS | J11: 71529245 | K11: WBTF5-4 | L11: SS T-SHIRT WB FRIENDS - 4 WBTF5-4:WHITE:L:GRAPHIC:SS T-SHIRT | M11: 129900 | N11: =$N$2 -> 0.85 | O11: =$O10 -> 17985 | P11: =$P$2 -> PERCENTAGE
A12: =$A$2 -> 2022 ALL D85 | B12: ='2019 ALL N OLDER D95'!$B$2 -> 46121 | C12: ='2019 ALL N OLDER D95'!$C$2 -> 46127 | D12: 3260 | E12: 333 | F12: 3 | G12: 4 | H12: JAVA DESIGN SENTOSA CV. | I12: AOS | J12: 71529236 | K12: WBTF5-4 | L12: SS T-SHIRT WB FRIENDS - 4 WBTF5-4:WHITE:M:GRAPHIC:SS T-SHIRT | M12: 129900 | N12: =$N$2 -> 0.85 | O12: =$O11 -> 17985 | P12: =$P$2 -> PERCENTAGE
A13: =$A$2 -> 2022 ALL D85 | B13: ='2019 ALL N OLDER D95'!$B$2 -> 46121 | C13: ='2019 ALL N OLDER D95'!$C$2 -> 46127 | D13: 3260 | E13: 333 | F13: 3 | G13: 4 | H13: JAVA DESIGN SENTOSA CV. | I13: AOS | J13: 71529227 | K13: WBTF5-4 | L13: SS T-SHIRT WB FRIENDS - 4 WBTF5-4:WHITE:S:GRAPHIC:SS T-SHIRT | M13: 129900 | N13: =$N$2 -> 0.85 | O13: =$O12 -> 17985 | P13: =$P$2 -> PERCENTAGE
A14: =$A$2 -> 2022 ALL D85 | B14: ='2019 ALL N OLDER D95'!$B$2 -> 46121 | C14: ='2019 ALL N OLDER D95'!$C$2 -> 46127 | D14: 3260 | E14: 333 | F14: 3 | G14: 4 | H14: JAVA DESIGN SENTOSA CV. | I14: AOS | J14: 71529218 | K14: WBTF5-3 | L14: SS T-SHIRT WB FRIENDS - 3 WBTF5-3:MUSTARD:XL:GRAPHIC:SS T-SHIRT | M14: 129900 | N14: =$N$2 -> 0.85 | O14: =$O13 -> 17985 | P14: =$P$2 -> PERCENTAGE
... A1131: =$A$2 -> 2022 ALL D85 | B1131: ='2019 ALL N OLDER D95'!$B$2 -> 46121 | C1131: ='2019 ALL N OLDER D95'!$C$2 -> 46127 | D1131: 3260 | E1131: 333 | F1131: 3 | G1131: 2 | H1131: JAVA DESIGN SENTOSA CV. | I1131: AOS | J1131: 32977432 | K1131: LSJ9-WIND | L1131: LS T-SHIRT PRINT - THE WIND IS CALLING LSJ9-WIND:CHARCOAL:S:TEXT:LS T-SHIRT | M1131: 109900 | N1131: =$N$2 -> 0.85 | O1131: =$O1130 -> 17985 | P1131: =$P$2 -> PERCENTAGE
A1132: =$A$2 -> 2022 ALL D85 | B1132: ='2019 ALL N OLDER D95'!$B$2 -> 46121 | C1132: ='2019 ALL N OLDER D95'!$C$2 -> 46127 | D1132: 3260 | E1132: 333 | F1132: 3 | G1132: 1 | H1132: SAHABAT GARMINDO PT- 81461 | I1132: AOS | J1132: 67146827 | K1132: OSFS3-C3 | L1132: SS T-SHIRT OVERSIZE PHOTOPRINT CITY - BOSTON OSFS3-C3:NAVY BLUE:L:GRAPHIC:SS T-SHIRT | M1132: 129900 | N1132: =$N$2 -> 0.85 | O1132: =$O1131 -> 17985 | P1132: =$P$2 -> PERCENTAGE
A1133: =$A$2 -> 2022 ALL D85 | B1133: ='2019 ALL N OLDER D95'!$B$2 -> 46121 | C1133: ='2019 ALL N OLDER D95'!$C$2 -> 46127 | D1133: 3260 | E1133: 333 | F1133: 3 | G1133: 1 | H1133: SAHABAT GARMINDO PT- 81461 | I1133: AOS | J1133: 67146783 | K1133: OSFS3-C1 | L1133: SS T-SHIRT OVERSIZE PHOTOPRINT CITY - URBAN CITY OSFS3-C1:BLACK:L:GRAPHIC:SS T-SHIRT | M1133: 129900 | N1133: =$N$2 -> 0.85 | O1133: =$O1132 -> 17985 | P1133: =$P$2 -> PERCENTAGE
A1134: =$A$2 -> 2022 ALL D85 | B1134: ='2019 ALL N OLDER D95'!$B$2 -> 46121 | C1134: ='2019 ALL N OLDER D95'!$C$2 -> 46127 | D1134: 3260 | E1134: 333 | F1134: 3 | G1134: 1 | H1134: SAHABAT GARMINDO PT- 81461 | I1134: AOS | J1134: 67146747 | K1134: OSFS3-C2 | L1134: SS T-SHIRT OVERSIZE PHOTOPRINT CITY - NYC CITY OSFS3-C2:WHITE:L:GRAPHIC:SS T-SHIRT | M1134: 129900 | N1134: =$N$2 -> 0.85 | O1134: =$O1133 -> 17985 | P1134: =$P$2 -> PERCENTAGE
A1135: =$A$2 -> 2022 ALL D85 | B1135: ='2019 ALL N OLDER D95'!$B$2 -> 46121 | C1135: ='2019 ALL N OLDER D95'!$C$2 -> 46127 | D1135: 3260 | E1135: 333 | F1135: 3 | G1135: 1 | H1135: PUTRA JAYA KREASI PT- 81602 | I1135: AOS | J1135: 66073103 | K1135: TK2N-96 | L1135: SS TSHIRT PRINT THEME NUMBER - AUTHENTIC 1996:OLIVE:L:TEXT:SS T-SHIRT | M1135: 119900 | N1135: =$N$2 -> 0.85 | O1135: =$O1134 -> 17985 | P1135: =$P$2 -> PERCENTAGE
A1136: =$A$2 -> 2022 ALL D85 | B1136: ='2019 ALL N OLDER D95'!$B$2 -> 46121 | C1136: ='2019 ALL N OLDER D95'!$C$2 -> 46127 | D1136: 3260 | E1136: 333 | F1136: 3 | G1136: 1 | H1136: PUTRA JAYA KREASI PT- 81602 | I1136: AOS | J1136: 66072864 | K1136: TK2N-86 | L1136: SS TSHIRT PRINT THEME NUMBER - 86 TYRANNOSAURUS:KHAKI:L:TEXT:SS T-SHIRT | M1136: 119900 | N1136: =$N$2 -> 0.85 | O1136: =$O1135 -> 17985 | P1136: =$P$2 -> PERCENTAGE
A1137: =$A$2 -> 2022 ALL D85 | B1137: ='2019 ALL N OLDER D95'!$B$2 -> 46121 | C1137: ='2019 ALL N OLDER D95'!$C$2 -> 46127 | D1137: 3260 | E1137: 333 | F1137: 3 | G1137: 1 | H1137: PUTRA JAYA KREASI PT- 81602 | I1137: AOS | J1137: 66072104 | K1137: TK2N-U8 | L1137: SS TSHIRT PRINT THEME - 8 URBAN TK2N-U8:MISTY LIGHT BL:L:TEXT:SS T-SHIRT | M1137: 119900 | N1137: =$N$2 -> 0.85 | O1137: =$O1136 -> 17985 | P1137: =$P$2 -> PERCENTAGE
A1138: =$A$2 -> 2022 ALL D85 | B1138: ='2019 ALL N OLDER D95'!$B$2 -> 46121 | C1138: ='2019 ALL N OLDER D95'!$C$2 -> 46127 | D1138: 3260 | E1138: 333 | F1138: 3 | G1138: 1 | H1138: PUTRA JAYA KREASI PT- 81602 | I1138: AOS | J1138: 66071249 | K1138: TK2N-99 | L1138: SS TSHIRT PRINT THEME NUMBER - 99 IGNORANCE:WHITE:L:TEXT:SS T-SHIRT | M1138: 119900 | N1138: =$N$2 -> 0.85 | O1138: =$O1137 -> 17985 | P1138: =$P$2 -> PERCENTAGE
A1139: =$A$2 -> 2022 ALL D85 | B1139: ='2019 ALL N OLDER D95'!$B$2 -> 46121 | C1139: ='2019 ALL N OLDER D95'!$C$2 -> 46127 | D1139: 3260 | E1139: 333 | F1139: 3 | G1139: 1 | H1139: PUTRA JAYA KREASI PT- 81602 | I1139: AOS | J1139: 66066997 | K1139: TK2N-L8 | L1139: SS TSHIRT PRINT THEME NUMBER - LUCKY EIGHT (8) TK2N-L8:BLACK:L:TEXT:SS T-SHIRT | M1139: 119900 | N1139: =$N$2 -> 0.85 | O1139: =$O1138 -> 17985 | P1139: =$P$2 -> PERCENTAGE
A1140: =$A$2 -> 2022 ALL D85 | B1140: ='2019 ALL N OLDER D95'!$B$2 -> 46121 | C1140: ='2019 ALL N OLDER D95'!$C$2 -> 46127 | D1140: 3260 | E1140: 333 | F1140: 3 | G1140: 1 | H1140: TRIKENCANA PUTRA GARMINDO CV-813 | I1140: AOS | J1140: 66065309 | K1140: TT2JS-JN | L1140: SS TSHIRT PRINT JAPAN STORY-JAPANESE NINJAKEN TT2JS-JN:BLACK:L:TEXT:SS T-SHIRT | M1140: 119900 | N1140: =$N$2 -> 0.85 | O1140: =$O1139 -> 17985 | P1140: =$P$2 -> PERCENTAGE
A1141: =$A$2 -> 2022 ALL D85 | B1141: ='2019 ALL N OLDER D95'!$B$2 -> 46121 | C1141: ='2019 ALL N OLDER D95'!$C$2 -> 46127 | D1141: 3260 | E1141: 333 | F1141: 3 | G1141: 1 | H1141: TRIKENCANA PUTRA GARMINDO CV-813 | I1141: AOS | J1141: 66040004 | K1141: TT2JS-TE | L1141: SS TSHIRT PRINT JAPAN STORY - TEMPLE 1 TT2JS-TE:KHAKI:L:GRAPHIC:SS T-SHIRT | M1141: 119900 | N1141: =$N$2 -> 0.85 | O1141: =$O1140 -> 17985 | P1141: =$P$2 -> PERCENTAGE
A1142: =$A$2 -> 2022 ALL D85 | B1142: ='2019 ALL N OLDER D95'!$B$2 -> 46121 | C1142: ='2019 ALL N OLDER D95'!$C$2 -> 46127 | D1142: 3260 | E1142: 333 | F1142: 3 | G1142: 1 | H1142: TRIKENCANA PUTRA GARMINDO CV-813 | I1142: AOS | J1142: 66039963 | K1142: TT2JS-TE | L1142: SS TSHIRT PRINT JAPAN STORY - TEMPLE 1 TT2JS-TE:CHARCOAL:L:GRAPHIC:SS T-SHIRT | M1142: 119900 | N1142: =$N$2 -> 0.85 | O1142: =$O1141 -> 17985 | P1142: =$P$2 -> PERCENTAGE
A1143: =$A$2 -> 2022 ALL D85 | B1143: ='2019 ALL N OLDER D95'!$B$2 -> 46121 | C1143: ='2019 ALL N OLDER D95'!$C$2 -> 46127 | D1143: 3260 | E1143: 333 | F1143: 3 | G1143: 1 | H1143: PUTRA JAYA KREASI PT- 81602 | I1143: AOS | J1143: 66038464 | K1143: TK2N-88 | L1143: PRINT THEME NUMBER - 88 TK2N-88:MISTY MEDIUM GRE:L:TEXT:SS T-SHIRT | M1143: 119900 | N1143: =$N$2 -> 0.85 | O1143: =$O1142 -> 17985 | P1143: =$P$2 -> PERCENTAGE
... A1159: =$A$2 -> 2022 ALL D85 | B1159: ='2019 ALL N OLDER D95'!$B$2 -> 46121 | C1159: ='2019 ALL N OLDER D95'!$C$2 -> 46127 | D1159: 3260 | E1159: 333 | F1159: 3 | G1159: 1 | H1159: INTAN DUA PT- 81337 | I1159: AOS | J1159: 65609376 | K1159: TI2IL-CR | L1159: SS T-SHIRT PRINT IMAGINERY LETTER - CIRCLE TI2IL-CR:WHITE:L:GRAPHIC:SS T-SHIRT | M1159: 119900 | N1159: =$N$2 -> 0.85 | O1159: =$O1158 -> 17985 | P1159: =$P$2 -> PERCENTAGE
A1160: =$A$2 -> 2022 ALL D85 | B1160: ='2019 ALL N OLDER D95'!$B$2 -> 46121 | C1160: ='2019 ALL N OLDER D95'!$C$2 -> 46127 | D1160: 3260 | E1160: 333 | F1160: 3 | G1160: 4 | H1160: JAVA DESIGN SENTOSA CV. | I1160: AOS | J1160: 66038606 | K1160: WBTB2-6 | L1160: SS T-SHIRT WB BATMAN MOVIE - 6 WBTB2-6:MISTY MEDIUM Y:XL:GRAPHIC:SS T-SHIRT | M1160: 129900 | N1160: =$N$2 -> 0.85 | O1160: =$O1159 -> 17985 | P1160: =$P$2 -> PERCENTAGE
A1161: =$A$2 -> 2022 ALL D85 | B1161: ='2019 ALL N OLDER D95'!$B$2 -> 46121 | C1161: ='2019 ALL N OLDER D95'!$C$2 -> 46127 | D1161: 3260 | E1161: 333 | F1161: 3 | G1161: 4 | H1161: JAVA DESIGN SENTOSA CV. | I1161: AOS | J1161: 66038599 | K1161: WBTB2-6 | L1161: SS T-SHIRT WB BATMAN MOVIE - 6 WBTB2-6:MISTY MEDIUM Y:L:GRAPHIC:SS T-SHIRT | M1161: 129900 | N1161: =$N$2 -> 0.85 | O1161: =$O1160 -> 17985 | P1161: =$P$2 -> PERCENTAGE
A1162: =$A$2 -> 2022 ALL D85 | B1162: ='2019 ALL N OLDER D95'!$B$2 -> 46121 | C1162: ='2019 ALL N OLDER D95'!$C$2 -> 46127 | D1162: 3260 | E1162: 333 | F1162: 3 | G1162: 4 | H1162: JAVA DESIGN SENTOSA CV. | I1162: AOS | J1162: 66038580 | K1162: WBTB2-6 | L1162: SS T-SHIRT WB BATMAN MOVIE - 6 WBTB2-6:MISTY MEDIUM Y:M:GRAPHIC:SS T-SHIRT | M1162: 129900 | N1162: =$N$2 -> 0.85 | O1162: =$O1161 -> 17985 | P1162: =$P$2 -> PERCENTAGE
A1163: =$A$2 -> 2022 ALL D85 | B1163: ='2019 ALL N OLDER D95'!$B$2 -> 46121 | C1163: ='2019 ALL N OLDER D95'!$C$2 -> 46127 | D1163: 3260 | E1163: 333 | F1163: 3 | G1163: 4 | H1163: JAVA DESIGN SENTOSA CV. | I1163: AOS | J1163: 66038571 | K1163: WBTB2-6 | L1163: SS T-SHIRT WB BATMAN MOVIE - 6 WBTB2-6:MISTY MEDIUM Y:S:GRAPHIC:SS T-SHIRT | M1163: 129900 | N1163: =$N$2 -> 0.85 | O1163: =$O1162 -> 17985 | P1163: =$P$2 -> PERCENTAGE
A1164: =$A$2 -> 2022 ALL D85 | B1164: ='2019 ALL N OLDER D95'!$B$2 -> 46121 | C1164: ='2019 ALL N OLDER D95'!$C$2 -> 46127 | D1164: 3260 | E1164: 333 | F1164: 3 | G1164: 4 | H1164: JAVA DESIGN SENTOSA CV. | I1164: AOS | J1164: 66038562 | K1164: WBTB2-5 | L1164: SS T-SHIRT WB BATMAN MOVIE - 5 WBTB2-5:NAVY BLUE:XL:GRAPHIC:SS T-SHIRT | M1164: 129900 | N1164: =$N$2 -> 0.85 | O1164: =$O1163 -> 17985 | P1164: =$P$2 -> PERCENTAGE
A1165: =$A$2 -> 2022 ALL D85 | B1165: ='2019 ALL N OLDER D95'!$B$2 -> 46121 | C1165: ='2019 ALL N OLDER D95'!$C$2 -> 46127 | D1165: 3260 | E1165: 333 | F1165: 3 | G1165: 4 | H1165: JAVA DESIGN SENTOSA CV. | I1165: AOS | J1165: 66038553 | K1165: WBTB2-5 | L1165: SS T-SHIRT WB BATMAN MOVIE - 5 WBTB2-5:NAVY BLUE:L:GRAPHIC:SS T-SHIRT | M1165: 129900 | N1165: =$N$2 -> 0.85 | O1165: =$O1164 -> 17985 | P1165: =$P$2 -> PERCENTAGE
A1166: =$A$2 -> 2022 ALL D85 | B1166: ='2019 ALL N OLDER D95'!$B$2 -> 46121 | C1166: ='2019 ALL N OLDER D95'!$C$2 -> 46127 | D1166: 3260 | E1166: 333 | F1166: 3 | G1166: 4 | H1166: JAVA DESIGN SENTOSA CV. | I1166: AOS | J1166: 66038544 | K1166: WBTB2-5 | L1166: SS T-SHIRT WB BATMAN MOVIE - 5 WBTB2-5:NAVY BLUE:M:GRAPHIC:SS T-SHIRT | M1166: 129900 | N1166: =$N$2 -> 0.85 | O1166: =$O1165 -> 17985 | P1166: =$P$2 -> PERCENTAGE
A1167: =$A$2 -> 2022 ALL D85 | B1167: ='2019 ALL N OLDER D95'!$B$2 -> 46121 | C1167: ='2019 ALL N OLDER D95'!$C$2 -> 46127 | D1167: 3260 | E1167: 333 | F1167: 3 | G1167: 4 | H1167: JAVA DESIGN SENTOSA CV. | I1167: AOS | J1167: 66038535 | K1167: WBTB2-5 | L1167: SS T-SHIRT WB BATMAN MOVIE - 5 WBTB2-5:NAVY BLUE:S:GRAPHIC:SS T-SHIRT | M1167: 129900 | N1167: =$N$2 -> 0.85 | O1167: =$O1166 -> 17985 | P1167: =$P$2 -> PERCENTAGE
A1168: =$A$2 -> 2022 ALL D85 | B1168: ='2019 ALL N OLDER D95'!$B$2 -> 46121 | C1168: ='2019 ALL N OLDER D95'!$C$2 -> 46127 | D1168: 3260 | E1168: 333 | F1168: 3 | G1168: 4 | H1168: JAVA DESIGN SENTOSA CV. | I1168: AOS | J1168: 66038526 | K1168: WBTB2-4 | L1168: SS T-SHIRT WB BATMAN MOVIE - 4 WBTB2-4:BLACK:XL:GRAPHIC:SS T-SHIRT | M1168: 129900 | N1168: =$N$2 -> 0.85 | O1168: =$O1167 -> 17985 | P1168: =$P$2 -> PERCENTAGE
A1169: =$A$2 -> 2022 ALL D85 | B1169: ='2019 ALL N OLDER D95'!$B$2 -> 46121 | C1169: ='2019 ALL N OLDER D95'!$C$2 -> 46127 | D1169: 3260 | E1169: 333 | F1169: 3 | G1169: 4 | H1169: JAVA DESIGN SENTOSA CV. | I1169: AOS | J1169: 66038517 | K1169: WBTB2-4 | L1169: SS T-SHIRT WB BATMAN MOVIE - 4 WBTB2-4:BLACK:L:GRAPHIC:SS T-SHIRT | M1169: 129900 | N1169: =$N$2 -> 0.85 | O1169: =$O1168 -> 17985 | P1169: =$P$2 -> PERCENTAGE
A1170: =$A$2 -> 2022 ALL D85 | B1170: ='2019 ALL N OLDER D95'!$B$2 -> 46121 | C1170: ='2019 ALL N OLDER D95'!$C$2 -> 46127 | D1170: 3260 | E1170: 333 | F1170: 3 | G1170: 4 | H1170: JAVA DESIGN SENTOSA CV. | I1170: AOS | J1170: 66038508 | K1170: WBTB2-4 | L1170: SS T-SHIRT WB BATMAN MOVIE - 4 WBTB2-4:BLACK:M:GRAPHIC:SS T-SHIRT | M1170: 129900 | N1170: =$N$2 -> 0.85 | O1170: =$O1169 -> 17985 | P1170: =$P$2 -> PERCENTAGE
A1171: =$A$2 -> 2022 ALL D85 | B1171: ='2019 ALL N OLDER D95'!$B$2 -> 46121 | C1171: ='2019 ALL N OLDER D95'!$C$2 -> 46127 | D1171: 3260 | E1171: 333 | F1171: 3 | G1171: 4 | H1171: JAVA DESIGN SENTOSA CV. | I1171: AOS | J1171: 66038491 | K1171: WBTB2-4 | L1171: SS T-SHIRT WB BATMAN MOVIE - 4 WBTB2-4:BLACK:S:GRAPHIC:SS T-SHIRT | M1171: 129900 | N1171: =$N$2 -> 0.85 | O1171: =$O1170 -> 17985 | P1171: =$P$2 -> PERCENTAGE
...

Sheet 2023 ALL D90
A1: ACARA | B1: FROM DATE | C1: TO DATE | D1: DEPT | E1: WORLD | F1: DIVISION | G1: CLASS | H1: SUPPLIER | I1: BRAND | J1: SKU | K1: ARTICLE | L1: DESCRIPTION | M1: HARGA NORMAL | N1: DISKON | O1: HARGA PROMO | P1: DISCOUNT TYPE
A2: 2023 ALL TSHIRT D90 | B2: ='2019 ALL N OLDER D95'!$B$2 -> 46121 | C2: ='2019 ALL N OLDER D95'!$C$2 -> 46127 | D2: 3260 | E2: 333 | F2: 3 | G2: 1 | H2: TRIPUTRA | I2: AOS | J2: 76394202 | K2: TFUU11-PP | L2: SS T-SHIRT FULLPRINT THEME POP PUNK TFUU11-PP:MUSTARD:S:PRINT:SS T-SHIRT | M2: 129900 | N2: 0.9 | O2: =M2*(1-N2) -> 12990 | P2: PERCENTAGE
A3: =$A$2 -> 2023 ALL TSHIRT D90 | B3: ='2019 ALL N OLDER D95'!$B$2 -> 46121 | C3: ='2019 ALL N OLDER D95'!$C$2 -> 46127 | D3: 3260 | E3: 333 | F3: 3 | G3: 1 | H3: TRIPUTRA | I3: AOS | J3: 76394211 | K3: TFUU11-PP | L3: SS T-SHIRT FULLPRINT THEME POP PUNK TFUU11-PP:MUSTARD:M:PRINT:SS T-SHIRT | M3: 129900 | N3: =$N2 -> 0.9 | O3: =M3*(1-N3) -> 12990 | P3: =$P$2 -> PERCENTAGE
A4: =$A$2 -> 2023 ALL TSHIRT D90 | B4: ='2019 ALL N OLDER D95'!$B$2 -> 46121 | C4: ='2019 ALL N OLDER D95'!$C$2 -> 46127 | D4: 3260 | E4: 333 | F4: 3 | G4: 1 | H4: TRIPUTRA | I4: AOS | J4: 76394220 | K4: TFUU11-PP | L4: SS T-SHIRT FULLPRINT THEME POP PUNK TFUU11-PP:MUSTARD:L:PRINT:SS T-SHIRT | M4: 129900 | N4: =$N3 -> 0.9 | O4: =M4*(1-N4) -> 12990 | P4: =$P$2 -> PERCENTAGE
A5: =$A$2 -> 2023 ALL TSHIRT D90 | B5: ='2019 ALL N OLDER D95'!$B$2 -> 46121 | C5: ='2019 ALL N OLDER D95'!$C$2 -> 46127 | D5: 3260 | E5: 333 | F5: 3 | G5: 1 | H5: TRIPUTRA | I5: AOS | J5: 76394239 | K5: TFUU11-PP | L5: SS T-SHIRT FULLPRINT THEME POP PUNK TFUU11-PP:MUSTARD:XL:PRINT:SS T-SHIRT | M5: 129900 | N5: =$N4 -> 0.9 | O5: =M5*(1-N5) -> 12990 | P5: =$P$2 -> PERCENTAGE
A6: =$A$2 -> 2023 ALL TSHIRT D90 | B6: ='2019 ALL N OLDER D95'!$B$2 -> 46121 | C6: ='2019 ALL N OLDER D95'!$C$2 -> 46127 | D6: 3260 | E6: 333 | F6: 3 | G6: 1 | H6: PUTRA JAYA KREASI | I6: AOS | J6: 79077399 | K6: TK9UR-CO | L6: SS T-SHIRT PRINT THEME UNEVEN RELIEF - CONSISTENCY TK9UR-CO:BROWN SUGAR:S:GRAPHIC:SS T-SHIRT | M6: 119900 | N6: =$N5 -> 0.9 | O6: =M6*(1-N6) -> 11990 | P6: =$P$2 -> PERCENTAGE
A7: =$A$2 -> 2023 ALL TSHIRT D90 | B7: ='2019 ALL N OLDER D95'!$B$2 -> 46121 | C7: ='2019 ALL N OLDER D95'!$C$2 -> 46127 | D7: 3260 | E7: 333 | F7: 3 | G7: 1 | H7: PUTRA JAYA KREASI | I7: AOS | J7: 79077406 | K7: TK9UR-CO | L7: SS T-SHIRT PRINT THEME UNEVEN RELIEF - CONSISTENCY TK9UR-CO:BROWN SUGAR:M:GRAPHIC:SS T-SHIRT | M7: 119900 | N7: =$N6 -> 0.9 | O7: =M7*(1-N7) -> 11990 | P7: =$P$2 -> PERCENTAGE
A8: =$A$2 -> 2023 ALL TSHIRT D90 | B8: ='2019 ALL N OLDER D95'!$B$2 -> 46121 | C8: ='2019 ALL N OLDER D95'!$C$2 -> 46127 | D8: 3260 | E8: 333 | F8: 3 | G8: 1 | H8: PUTRA JAYA KREASI | I8: AOS | J8: 79077415 | K8: TK9UR-CO | L8: SS T-SHIRT PRINT THEME UNEVEN RELIEF - CONSISTENCY TK9UR-CO:BROWN SUGAR:L:GRAPHIC:SS T-SHIRT | M8: 119900 | N8: =$N7 -> 0.9 | O8: =M8*(1-N8) -> 11990 | P8: =$P$2 -> PERCENTAGE
A9: =$A$2 -> 2023 ALL TSHIRT D90 | B9: ='2019 ALL N OLDER D95'!$B$2 -> 46121 | C9: ='2019 ALL N OLDER D95'!$C$2 -> 46127 | D9: 3260 | E9: 333 | F9: 3 | G9: 1 | H9: PUTRA JAYA KREASI | I9: AOS | J9: 79077424 | K9: TK9UR-CO | L9: SS T-SHIRT PRINT THEME UNEVEN RELIEF - CONSISTENCY TK9UR-CO:BROWN SUGAR:XL:GRAPHIC:SS T-SHIRT | M9: 119900 | N9: =$N8 -> 0.9 | O9: =M9*(1-N9) -> 11990 | P9: =$P$2 -> PERCENTAGE
A10: =$A$2 -> 2023 ALL TSHIRT D90 | B10: ='2019 ALL N OLDER D95'!$B$2 -> 46121 | C10: ='2019 ALL N OLDER D95'!$C$2 -> 46127 | D10: 3260 | E10: 333 | F10: 3 | G10: 1 | H10: PUTRA JAYA KREASI | I10: AOS | J10: 79077433 | K10: TK9UR-NH | L10: SS T-SHIRT PRINT THEME UNEVEN RELIEF - NEW HABITS TK9UR-NH:MUSTARD:S:GRAPHIC:SS T-SHIRT | M10: 119900 | N10: =$N9 -> 0.9 | O10: =M10*(1-N10) -> 11990 | P10: =$P$2 -> PERCENTAGE
A11: =$A$2 -> 2023 ALL TSHIRT D90 | B11: ='2019 ALL N OLDER D95'!$B$2 -> 46121 | C11: ='2019 ALL N OLDER D95'!$C$2 -> 46127 | D11: 3260 | E11: 333 | F11: 3 | G11: 1 | H11: PUTRA JAYA KREASI | I11: AOS | J11: 79077442 | K11: TK9UR-NH | L11: SS T-SHIRT PRINT THEME UNEVEN RELIEF - NEW HABITS TK9UR-NH:MUSTARD:M:GRAPHIC:SS T-SHIRT | M11: 119900 | N11: =$N10 -> 0.9 | O11: =M11*(1-N11) -> 11990 | P11: =$P$2 -> PERCENTAGE
A12: =$A$2 -> 2023 ALL TSHIRT D90 | B12: ='2019 ALL N OLDER D95'!$B$2 -> 46121 | C12: ='2019 ALL N OLDER D95'!$C$2 -> 46127 | D12: 3260 | E12: 333 | F12: 3 | G12: 1 | H12: PUTRA JAYA KREASI | I12: AOS | J12: 79077451 | K12: TK9UR-NH | L12: SS T-SHIRT PRINT THEME UNEVEN RELIEF - NEW HABITS TK9UR-NH:MUSTARD:L:GRAPHIC:SS T-SHIRT | M12: 119900 | N12: =$N11 -> 0.9 | O12: =M12*(1-N12) -> 11990 | P12: =$P$2 -> PERCENTAGE
A13: =$A$2 -> 2023 ALL TSHIRT D90 | B13: ='2019 ALL N OLDER D95'!$B$2 -> 46121 | C13: ='2019 ALL N OLDER D95'!$C$2 -> 46127 | D13: 3260 | E13: 333 | F13: 3 | G13: 1 | H13: PUTRA JAYA KREASI | I13: AOS | J13: 79077460 | K13: TK9UR-NH | L13: SS T-SHIRT PRINT THEME UNEVEN RELIEF - NEW HABITS TK9UR-NH:MUSTARD:XL:GRAPHIC:SS T-SHIRT | M13: 119900 | N13: =$N12 -> 0.9 | O13: =M13*(1-N13) -> 11990 | P13: =$P$2 -> PERCENTAGE
A14: =$A$2 -> 2023 ALL TSHIRT D90 | B14: ='2019 ALL N OLDER D95'!$B$2 -> 46121 | C14: ='2019 ALL N OLDER D95'!$C$2 -> 46127 | D14: 3260 | E14: 333 | F14: 3 | G14: 1 | H14: PUTRA JAYA KREASI | I14: AOS | J14: 79077479 | K14: TK9UR-IT | L14: SS T-SHIRT PRINT THEME UNEVEN RELIEF - INTERSECTION TK9UR-IT:WINE:S:GRAPHIC:SS T-SHIRT | M14: 119900 | N14: =$N13 -> 0.9 | O14: =M14*(1-N14) -> 11990 | P14: =$P$2 -> PERCENTAGE
... A1835: =$A$2 -> 2023 ALL TSHIRT D90 | B1835: ='2019 ALL N OLDER D95'!$B$2 -> 46121 | C1835: ='2019 ALL N OLDER D95'!$C$2 -> 46127 | D1835: 3260 | E1835: 333 | F1835: 3 | G1835: 4 | H1835: JAVA DESIGN | I1835: AOS | J1835: 85495587 | K1835: WBXMAS23-MA | L1835: SS T-SHIRT WB XMAS COLL 2023 - THE MARTIAN WBXMAS23-MA:MAROON:XL:GRAPHIC:SS T-SHIRT | M1835: 129900 | N1835: =$N1834 -> 0.9 | O1835: =M1835*(1-N1835) -> 12990 | P1835: =$P$2 -> PERCENTAGE
A1836: =$A$2 -> 2023 ALL TSHIRT D90 | B1836: ='2019 ALL N OLDER D95'!$B$2 -> 46121 | C1836: ='2019 ALL N OLDER D95'!$C$2 -> 46127 | D1836: 3260 | E1836: 333 | F1836: 3 | G1836: 3 | H1836: JAVA DESIGN SENTOSA CV. | I1836: AOS | J1836: 14590937 | K1836: R3J8-FO | L1836: 3/4 RAGLAN T-SHIRT THEME VARSITY ICON - FOOTBALL R3J8-FO:MISTY DARK GREY:S:GRAPHIC:3/4 RAGLAN T-SHIR | M1836: 129900 | N1836: =$N1835 -> 0.9 | O1836: =M1836*(1-N1836) -> 12990 | P1836: =$P$2 -> PERCENTAGE
A1837: =$A$2 -> 2023 ALL TSHIRT D90 | B1837: ='2019 ALL N OLDER D95'!$B$2 -> 46121 | C1837: ='2019 ALL N OLDER D95'!$C$2 -> 46127 | D1837: 3260 | E1837: 333 | F1837: 3 | G1837: 3 | H1837: JAVA DESIGN SENTOSA CV. | I1837: AOS | J1837: 14590946 | K1837: R3J8-FO | L1837: 3/4 RAGLAN T-SHIRT THEME VARSITY ICON - FOOTBALL R3J8-FO:MISTY DARK GREY:M:GRAPHIC:3/4 RAGLAN T-SHIR | M1837: 129900 | N1837: =$N1836 -> 0.9 | O1837: =M1837*(1-N1837) -> 12990 | P1837: =$P$2 -> PERCENTAGE
A1838: =$A$2 -> 2023 ALL TSHIRT D90 | B1838: ='2019 ALL N OLDER D95'!$B$2 -> 46121 | C1838: ='2019 ALL N OLDER D95'!$C$2 -> 46127 | D1838: 3260 | E1838: 333 | F1838: 3 | G1838: 3 | H1838: JAVA DESIGN SENTOSA CV. | I1838: AOS | J1838: 14590955 | K1838: R3J8-FO | L1838: 3/4 RAGLAN T-SHIRT THEME VARSITY ICON - FOOTBALL R3J8-FO:MISTY DARK GREY:L:GRAPHIC:3/4 RAGLAN T-SHIR | M1838: 129900 | N1838: =$N1837 -> 0.9 | O1838: =M1838*(1-N1838) -> 12990 | P1838: =$P$2 -> PERCENTAGE
A1839: =$A$2 -> 2023 ALL TSHIRT D90 | B1839: ='2019 ALL N OLDER D95'!$B$2 -> 46121 | C1839: ='2019 ALL N OLDER D95'!$C$2 -> 46127 | D1839: 3260 | E1839: 333 | F1839: 3 | G1839: 3 | H1839: JAVA DESIGN SENTOSA CV. | I1839: AOS | J1839: 14590964 | K1839: R3J8-FO | L1839: 3/4 RAGLAN T-SHIRT THEME VARSITY ICON - FOOTBALL R3J8-FO:MISTY DARK GREY:XL:GRAPHIC:3/4 RAGLAN T-SHI | M1839: 129900 | N1839: =$N1838 -> 0.9 | O1839: =M1839*(1-N1839) -> 12990 | P1839: =$P$2 -> PERCENTAGE
A1840: =$A$2 -> 2023 ALL TSHIRT D90 | B1840: ='2019 ALL N OLDER D95'!$B$2 -> 46121 | C1840: ='2019 ALL N OLDER D95'!$C$2 -> 46127 | D1840: 3260 | E1840: 333 | F1840: 3 | G1840: 3 | H1840: JAVA DESIGN SENTOSA CV. | I1840: AOS | J1840: 14590973 | K1840: R3J8-FO | L1840: 3/4 RAGLAN T-SHIRT THEME VARSITY ICON - FOOTBALL R3J8-FO:DARK JADE:S:GRAPHIC:3/4 RAGLAN T-SHIRT | M1840: 129900 | N1840: =$N1839 -> 0.9 | O1840: =M1840*(1-N1840) -> 12990 | P1840: =$P$2 -> PERCENTAGE
