Workbook

Sheet 2026 JAN-APR SHARP PRICE- 3321
A1: ACARA | B1: FROM DATE | C1: TO DATE | D1: DEPT | E1: WORLD | F1: DIVISION | G1: CLASS | H1: SUPPLIER | I1: BRAND | J1: SKU | K1: ARTICLE | L1: DESCRIPTION | M1: HARGA NORMAL | N1: DISKON | O1: HARGA PROMO | P1: DISCOUNT TYPE
A2: 2026 JAN-APR SHARP PRICE | B2: 46121 | C2: 46127 | D2: 3321 | E2: 337 | F2: 4 | G2: 3 | H2: 81588 | I2: CHARACTER | J2: 66252286 | K2: CD425MM | L2: CARDIGAN MY MELODY CD425MM:PASTEL PINK:4:GRAPHIC:CARDIGAN | M2: 199900 | N2: 0 | O2: SHARP PRICE | P2: AMOUNT
A3: =A2 -> 2026 JAN-APR SHARP PRICE | B3: =B2 -> 46121 | C3: =C2 -> 46127 | D3: 3321 | E3: 337 | F3: 4 | G3: 3 | H3: 81588 | I3: CHARACTER | J3: 66252295 | K3: CD425MM | L3: CARDIGAN MY MELODY CD425MM:PASTEL PINK:5:GRAPHIC:CARDIGAN | M3: 199900 | N3: =N2 -> 0 | O3: =O2 -> SHARP PRICE | P3: =P2 -> AMOUNT
A4: =A3 -> 2026 JAN-APR SHARP PRICE | B4: =B3 -> 46121 | C4: =C3 -> 46127 | D4: 3321 | E4: 337 | F4: 4 | G4: 3 | H4: 81588 | I4: CHARACTER | J4: 66252302 | K4: CD425MM | L4: CARDIGAN MY MELODY CD425MM:PASTEL PINK:6:GRAPHIC:CARDIGAN | M4: 199900 | N4: =N3 -> 0 | O4: =O3 -> SHARP PRICE | P4: =P3 -> AMOUNT
A5: =A4 -> 2026 JAN-APR SHARP PRICE | B5: =B4 -> 46121 | C5: =C4 -> 46127 | D5: 3321 | E5: 337 | F5: 4 | G5: 3 | H5: 81588 | I5: CHARACTER | J5: 66252311 | K5: CD425MM | L5: CARDIGAN MY MELODY CD425MM:PASTEL PINK:7-8:GRAPHIC:CARDIGAN | M5: 199900 | N5: =N4 -> 0 | O5: =O4 -> SHARP PRICE | P5: =P4 -> AMOUNT
A6: =A5 -> 2026 JAN-APR SHARP PRICE | B6: =B5 -> 46121 | C6: =C5 -> 46127 | D6: 3321 | E6: 337 | F6: 4 | G6: 1 | H6: 81588 | I6: CHARACTER | J6: 63152032 | K6: TS425KT1 | L6: SS T-SHIRT HELLO KITTY WASHED TS425KT1:MISTY DARK GREY:7-8:GRAPHIC:SS T-SHIRT | M6: 99900 | N6: =N5 -> 0 | O6: =O5 -> SHARP PRICE | P6: =P5 -> AMOUNT
A7: =A6 -> 2026 JAN-APR SHARP PRICE | B7: =B6 -> 46121 | C7: =C6 -> 46127 | D7: 3321 | E7: 337 | F7: 4 | G7: 1 | H7: 81588 | I7: CHARACTER | J7: 63152041 | K7: TS425KT1 | L7: SS T-SHIRT HELLO KITTY WASHED TS425KT1:MISTY DARK GREY:9-10:GRAPHIC:SS T-SHIRT | M7: 99900 | N7: =N6 -> 0 | O7: =O6 -> SHARP PRICE | P7: =P6 -> AMOUNT
A8: =A7 -> 2026 JAN-APR SHARP PRICE | B8: =B7 -> 46121 | C8: =C7 -> 46127 | D8: 3321 | E8: 337 | F8: 4 | G8: 1 | H8: 81588 | I8: CHARACTER | J8: 63152050 | K8: TS425KT1 | L8: SS T-SHIRT HELLO KITTY WASHED TS425KT1:MISTY DARK GREY:11-12:GRAPHIC:SS T-SHIRT | M8: 99900 | N8: =N7 -> 0 | O8: =O7 -> SHARP PRICE | P8: =P7 -> AMOUNT
A9: =A8 -> 2026 JAN-APR SHARP PRICE | B9: =B8 -> 46121 | C9: =C8 -> 46127 | D9: 3321 | E9: 337 | F9: 4 | G9: 1 | H9: 81588 | I9: CHARACTER | J9: 63152069 | K9: TS425KT1 | L9: SS T-SHIRT HELLO KITTY WASHED TS425KT1:MISTY DARK GREY:13-14:GRAPHIC:SS T-SHIRT | M9: 99900 | N9: =N8 -> 0 | O9: =O8 -> SHARP PRICE | P9: =P8 -> AMOUNT
A10: =A9 -> 2026 JAN-APR SHARP PRICE | B10: =B9 -> 46121 | C10: =C9 -> 46127 | D10: 3321 | E10: 337 | F10: 4 | G10: 3 | H10: 81588 | I10: CHARACTER | J10: 63151837 | K10: JKSNCN | L10: JACKET CINNAMOROLL SNACK JKSNCN:LIGHT BLUE:4:GRAPHIC:JACKET | M10: 199900 | N10: =N9 -> 0 | O10: =O9 -> SHARP PRICE | P10: =P9 -> AMOUNT
A11: =A10 -> 2026 JAN-APR SHARP PRICE | B11: =B10 -> 46121 | C11: =C10 -> 46127 | D11: 3321 | E11: 337 | F11: 4 | G11: 3 | H11: 81588 | I11: CHARACTER | J11: 63151846 | K11: JKSNCN | L11: JACKET CINNAMOROLL SNACK JKSNCN:LIGHT BLUE:5:GRAPHIC:JACKET | M11: 199900 | N11: =N10 -> 0 | O11: =O10 -> SHARP PRICE | P11: =P10 -> AMOUNT
A12: =A11 -> 2026 JAN-APR SHARP PRICE | B12: =B11 -> 46121 | C12: =C11 -> 46127 | D12: 3321 | E12: 337 | F12: 4 | G12: 3 | H12: 81588 | I12: CHARACTER | J12: 63151855 | K12: JKSNCN | L12: JACKET CINNAMOROLL SNACK JKSNCN:LIGHT BLUE:6:GRAPHIC:JACKET | M12: 199900 | N12: =N11 -> 0 | O12: =O11 -> SHARP PRICE | P12: =P11 -> AMOUNT
A13: =A12 -> 2026 JAN-APR SHARP PRICE | B13: =B12 -> 46121 | C13: =C12 -> 46127 | D13: 3321 | E13: 337 | F13: 4 | G13: 3 | H13: 81588 | I13: CHARACTER | J13: 63151864 | K13: JKSNCN | L13: JACKET CINNAMOROLL SNACK JKSNCN:LIGHT BLUE:7-8:GRAPHIC:JACKET | M13: 199900 | N13: =N12 -> 0 | O13: =O12 -> SHARP PRICE | P13: =P12 -> AMOUNT
A14: =A13 -> 2026 JAN-APR SHARP PRICE | B14: =B13 -> 46121 | C14: =C13 -> 46127 | D14: 3321 | E14: 337 | F14: 4 | G14: 1 | H14: 81588 | I14: CHARACTER | J14: 68022002 | K14: TS4MLD | L14: SS T-SHIRT MY MELODY LENGAN RUFFLE TS4MLD:PASTEL PINK:4:GRAPHIC:SS T-SHIRT | M14: 99900 | N14: =N13 -> 0 | O14: =O13 -> SHARP PRICE | P14: =P13 -> AMOUNT
... A133: =A132 -> 2026 JAN-APR SHARP PRICE | B133: =B132 -> 46121 | C133: =C132 -> 46127 | D133: 3321 | E133: 337 | F133: 4 | G133: 1 | H133: 81588 | I133: CHARACTER | J133: 68783799 | K133: TSSRDDKT | L133: SS T-SHIRT RIB SERUT DD HELLO KITTY TSSRDDKT:OFF WHITE:15-16:GRAPHIC:SS T-SHIRT | M133: 99900 | N133: =N132 -> 0 | O133: =O132 -> SHARP PRICE | P133: =P132 -> AMOUNT

Sheet 2026 BAMUS D60 - 3321
A1: ACARA | B1: FROM DATE | C1: TO DATE | D1: DEPT | E1: WORLD | F1: DIVISION | G1: CLASS | H1: SUPPLIER | I1: BRAND | J1: SKU | K1: ARTICLE | L1: DESCRIPTION | M1: HARGA NORMAL | N1: DISKON | O1: HARGA PROMO | P1: DISCOUNT TYPE
A2: 2026 BAMUS DISC 60% | B2: 46121 | C2: 46127 | D2: 3321 | E2: 337 | F2: 4 | G2: 2 | H2: 81005 | I2: CHARACTER | J2: 68416337 | K2: 34SRFMM | L2: 3/4 SHIRT WOMEN RUFFLE MY MELODY 34SRFMM:CLASSIC GREEN:4:GRAPHIC:3/4 SHIRT | M2: 199900 | N2: 0.6 | O2: =M2-((60*M2)/100) -> 79960 | P2: PERCENTAGE
A3: =A2 -> 2026 BAMUS DISC 60% | B3: =B2 -> 46121 | C3: =C2 -> 46127 | D3: 3321 | E3: 337 | F3: 4 | G3: 2 | H3: 81005 | I3: CHARACTER | J3: 68416346 | K3: 34SRFMM | L3: 3/4 SHIRT WOMEN RUFFLE MY MELODY 34SRFMM:CLASSIC GREEN:5:GRAPHIC:3/4 SHIRT | M3: 199900 | N3: =N2 -> 0.6 | O3: =M3-((60*M3)/100) -> 79960 | P3: =P2 -> PERCENTAGE
A4: =A3 -> 2026 BAMUS DISC 60% | B4: =B3 -> 46121 | C4: =C3 -> 46127 | D4: 3321 | E4: 337 | F4: 4 | G4: 2 | H4: 81005 | I4: CHARACTER | J4: 68416355 | K4: 34SRFMM | L4: 3/4 SHIRT WOMEN RUFFLE MY MELODY 34SRFMM:CLASSIC GREEN:6:GRAPHIC:3/4 SHIRT | M4: 199900 | N4: =N3 -> 0.6 | O4: =M4-((60*M4)/100) -> 79960 | P4: =P3 -> PERCENTAGE
A5: =A4 -> 2026 BAMUS DISC 60% | B5: =B4 -> 46121 | C5: =C4 -> 46127 | D5: 3321 | E5: 337 | F5: 4 | G5: 2 | H5: 81005 | I5: CHARACTER | J5: 68416364 | K5: 34SRFMM | L5: 3/4 SHIRT WOMEN RUFFLE MY MELODY 34SRFMM:CLASSIC GREEN:7-8:GRAPHIC:3/4 SHIRT | M5: 199900 | N5: =N4 -> 0.6 | O5: =M5-((60*M5)/100) -> 79960 | P5: =P4 -> PERCENTAGE
A6: =A5 -> 2026 BAMUS DISC 60% | B6: =B5 -> 46121 | C6: =C5 -> 46127 | D6: 3321 | E6: 337 | F6: 4 | G6: 2 | H6: 81005 | I6: CHARACTER | J6: 68416373 | K6: 34SRFMM | L6: 3/4 SHIRT WOMEN RUFFLE MY MELODY 34SRFMM:CLASSIC GREEN:9-10:GRAPHIC:3/4 SHIRT | M6: 199900 | N6: =N5 -> 0.6 | O6: =M6-((60*M6)/100) -> 79960 | P6: =P5 -> PERCENTAGE
A7: =A6 -> 2026 BAMUS DISC 60% | B7: =B6 -> 46121 | C7: =C6 -> 46127 | D7: 3321 | E7: 337 | F7: 4 | G7: 2 | H7: 81005 | I7: CHARACTER | J7: 68416382 | K7: 34SRFMM | L7: 3/4 SHIRT WOMEN RUFFLE MY MELODY 34SRFMM:CLASSIC GREEN:11-12:GRAPHIC:3/4 SHIRT | M7: 199900 | N7: =N6 -> 0.6 | O7: =M7-((60*M7)/100) -> 79960 | P7: =P6 -> PERCENTAGE
A8: =A7 -> 2026 BAMUS DISC 60% | B8: =B7 -> 46121 | C8: =C7 -> 46127 | D8: 3321 | E8: 337 | F8: 4 | G8: 5 | H8: 81698 | I8: CHARACTER | J8: 68416542 | K8: DLSEERKU | L8: LS MIDI DRESS WOVEN KIMONO KUROMI DLSEERKU:KHAKI:4:GRAPHIC:LS MIDI DRESS | M8: 249900 | N8: =N7 -> 0.6 | O8: =M8-((60*M8)/100) -> 99960 | P8: =P7 -> PERCENTAGE
A9: =A8 -> 2026 BAMUS DISC 60% | B9: =B8 -> 46121 | C9: =C8 -> 46127 | D9: 3321 | E9: 337 | F9: 4 | G9: 5 | H9: 81698 | I9: CHARACTER | J9: 68416551 | K9: DLSEERKU | L9: LS MIDI DRESS WOVEN KIMONO KUROMI DLSEERKU:KHAKI:5:GRAPHIC:LS MIDI DRESS | M9: 249900 | N9: =N8 -> 0.6 | O9: =M9-((60*M9)/100) -> 99960 | P9: =P8 -> PERCENTAGE
A10: =A9 -> 2026 BAMUS DISC 60% | B10: =B9 -> 46121 | C10: =C9 -> 46127 | D10: 3321 | E10: 337 | F10: 4 | G10: 5 | H10: 81698 | I10: CHARACTER | J10: 68416560 | K10: DLSEERKU | L10: LS MIDI DRESS WOVEN KIMONO KUROMI DLSEERKU:KHAKI:6:GRAPHIC:LS MIDI DRESS | M10: 249900 | N10: =N9 -> 0.6 | O10: =M10-((60*M10)/100) -> 99960 | P10: =P9 -> PERCENTAGE
A11: =A10 -> 2026 BAMUS DISC 60% | B11: =B10 -> 46121 | C11: =C10 -> 46127 | D11: 3321 | E11: 337 | F11: 4 | G11: 5 | H11: 81698 | I11: CHARACTER | J11: 68416579 | K11: DLSEERKU | L11: LS MIDI DRESS WOVEN KIMONO KUROMI DLSEERKU:KHAKI:7-8:GRAPHIC:LS MIDI DRESS | M11: 249900 | N11: =N10 -> 0.6 | O11: =M11-((60*M11)/100) -> 99960 | P11: =P10 -> PERCENTAGE
A12: =A11 -> 2026 BAMUS DISC 60% | B12: =B11 -> 46121 | C12: =C11 -> 46127 | D12: 3321 | E12: 337 | F12: 4 | G12: 5 | H12: 81698 | I12: CHARACTER | J12: 68416588 | K12: DLSEERKU | L12: LS MIDI DRESS WOVEN KIMONO KUROMI DLSEERKU:KHAKI:9-10:GRAPHIC:LS MIDI DRESS | M12: 249900 | N12: =N11 -> 0.6 | O12: =M12-((60*M12)/100) -> 99960 | P12: =P11 -> PERCENTAGE
A13: =A12 -> 2026 BAMUS DISC 60% | B13: =B12 -> 46121 | C13: =C12 -> 46127 | D13: 3321 | E13: 337 | F13: 4 | G13: 5 | H13: 81698 | I13: CHARACTER | J13: 68416597 | K13: DLSEERKU | L13: LS MIDI DRESS WOVEN KIMONO KUROMI DLSEERKU:KHAKI:11-12:GRAPHIC:LS MIDI DRESS | M13: 249900 | N13: =N12 -> 0.6 | O13: =M13-((60*M13)/100) -> 99960 | P13: =P12 -> PERCENTAGE
A14: =A13 -> 2026 BAMUS DISC 60% | B14: =B13 -> 46121 | C14: =C13 -> 46127 | D14: 3321 | E14: 337 | F14: 4 | G14: 5 | H14: 81698 | I14: CHARACTER | J14: 68416604 | K14: DLSEERKU | L14: LS MIDI DRESS WOVEN KIMONO KUROMI DLSEERKU:KHAKI:13-14:GRAPHIC:LS MIDI DRESS | M14: 249900 | N14: =N13 -> 0.6 | O14: =M14-((60*M14)/100) -> 99960 | P14: =P13 -> PERCENTAGE
... A35: =A34 -> 2026 BAMUS DISC 60% | B35: =B34 -> 46121 | C35: =C34 -> 46127 | D35: 3321 | E35: 337 | F35: 4 | G35: 2 | H35: 81005 | I35: CHARACTER | J35: 68416533 | K35: LSROMKU | L35: LS SHIRT WOVEN ROMPI KUROMI LSROMKU:RUSTIC BROWN:13-14:GRAPHIC:LS SHIRT | M35: 199900 | N35: =N34 -> 0.6 | O35: =M35-((60*M35)/100) -> 79960 | P35: =P34 -> PERCENTAGE

Sheet 2026 HILITE D30 -3321
A1: ACARA | B1: FROM DATE | C1: TO DATE | D1: DEPT | E1: WORLD | F1: DIVISION | G1: CLASS | H1: SUPPLIER | I1: BRAND | J1: SKU | K1: ARTICLE | L1: DESCRIPTION | M1: HARGA NORMAL | N1: DISKON | O1: HARGA PROMO | P1: DISCOUNT TYPE
A2: 2026 HILITE DISC 30 | B2: ='2025 JUNSEPT B1G1 - 3321'!B6 -> 46121 | C2: ='2025 JUNSEPT B1G1 - 3321'!C6 -> 46127 | D2: 3321 | E2: 337 | F2: 4 | G2: 5 | H2: 81698 | I2: CHARACTER | J2: 68397475 | K2: DSSAMM | L2: SS MIDI DRESS WOVEN SA MY MELODY DSSAMM:PASTEL GREEN:4:GRAPHIC:SS MIDI DRESS | M2: 179900 | N2: 0.3 | O2: =M2-((30*M2)/100) -> 125930 | P2: PERCENTAGE
A3: =A2 -> 2026 HILITE DISC 30 | B3: =B2 -> 46121 | C3: =C2 -> 46127 | D3: 3321 | E3: 337 | F3: 4 | G3: 5 | H3: 81698 | I3: CHARACTER | J3: 68397484 | K3: DSSAMM | L3: SS MIDI DRESS WOVEN SA MY MELODY DSSAMM:PASTEL GREEN:5:GRAPHIC:SS MIDI DRESS | M3: 179900 | N3: =N2 -> 0.3 | O3: =M3-((30*M3)/100) -> 125930 | P3: =P2 -> PERCENTAGE
A4: =A3 -> 2026 HILITE DISC 30 | B4: =B3 -> 46121 | C4: =C3 -> 46127 | D4: 3321 | E4: 337 | F4: 4 | G4: 5 | H4: 81698 | I4: CHARACTER | J4: 68397493 | K4: DSSAMM | L4: SS MIDI DRESS WOVEN SA MY MELODY DSSAMM:PASTEL GREEN:6:GRAPHIC:SS MIDI DRESS | M4: 179900 | N4: =N3 -> 0.3 | O4: =M4-((30*M4)/100) -> 125930 | P4: =P3 -> PERCENTAGE
A5: =A4 -> 2026 HILITE DISC 30 | B5: =B4 -> 46121 | C5: =C4 -> 46127 | D5: 3321 | E5: 337 | F5: 4 | G5: 5 | H5: 81698 | I5: CHARACTER | J5: 68397500 | K5: DSSAMM | L5: SS MIDI DRESS WOVEN SA MY MELODY DSSAMM:PASTEL GREEN:7-8:GRAPHIC:SS MIDI DRESS | M5: 179900 | N5: =N4 -> 0.3 | O5: =M5-((30*M5)/100) -> 125930 | P5: =P4 -> PERCENTAGE
A6: =A5 -> 2026 HILITE DISC 30 | B6: =B5 -> 46121 | C6: =C5 -> 46127 | D6: 3321 | E6: 337 | F6: 4 | G6: 5 | H6: 81698 | I6: CHARACTER | J6: 68397519 | K6: DSSAMM | L6: SS MIDI DRESS WOVEN SA MY MELODY DSSAMM:PASTEL GREEN:9-10:GRAPHIC:SS MIDI DRESS | M6: 179900 | N6: =N5 -> 0.3 | O6: =M6-((30*M6)/100) -> 125930 | P6: =P5 -> PERCENTAGE
A7: =A6 -> 2026 HILITE DISC 30 | B7: =B6 -> 46121 | C7: =C6 -> 46127 | D7: 3321 | E7: 337 | F7: 4 | G7: 5 | H7: 81698 | I7: CHARACTER | J7: 68397528 | K7: DSSAMM | L7: SS MIDI DRESS WOVEN SA MY MELODY DSSAMM:PASTEL GREEN:11-12:GRAPHIC:SS MIDI DRESS | M7: 179900 | N7: =N6 -> 0.3 | O7: =M7-((30*M7)/100) -> 125930 | P7: =P6 -> PERCENTAGE
A8: =A7 -> 2026 HILITE DISC 30 | B8: =B7 -> 46121 | C8: =C7 -> 46127 | D8: 3321 | E8: 337 | F8: 4 | G8: 5 | H8: 81698 | I8: CHARACTER | J8: 68397537 | K8: DSSAMM | L8: SS MIDI DRESS WOVEN SA MY MELODY DSSAMM:PASTEL GREEN:13-14:GRAPHIC:SS MIDI DRESS | M8: 179900 | N8: =N7 -> 0.3 | O8: =M8-((30*M8)/100) -> 125930 | P8: =P7 -> PERCENTAGE
A9: =A8 -> 2026 HILITE DISC 30 | B9: =B8 -> 46121 | C9: =C8 -> 46127 | D9: 3321 | E9: 337 | F9: 4 | G9: 2 | H9: 81005 | I9: CHARACTER | J9: 68397617 | K9: SSIKATKU | L9: SS SHIRT TOP WOVEN KUROMI KEMEJA IKAT SSIKATKU:KHAKI:4:GRAPHIC:SS SHIRT | M9: 149900 | N9: =N8 -> 0.3 | O9: =M9-((30*M9)/100) -> 104930 | P9: =P8 -> PERCENTAGE
A10: =A9 -> 2026 HILITE DISC 30 | B10: =B9 -> 46121 | C10: =C9 -> 46127 | D10: 3321 | E10: 337 | F10: 4 | G10: 2 | H10: 81005 | I10: CHARACTER | J10: 68397626 | K10: SSIKATKU | L10: SS SHIRT TOP WOVEN KUROMI KEMEJA IKAT SSIKATKU:KHAKI:5:GRAPHIC:SS SHIRT | M10: 149900 | N10: =N9 -> 0.3 | O10: =M10-((30*M10)/100) -> 104930 | P10: =P9 -> PERCENTAGE
A11: =A10 -> 2026 HILITE DISC 30 | B11: =B10 -> 46121 | C11: =C10 -> 46127 | D11: 3321 | E11: 337 | F11: 4 | G11: 2 | H11: 81005 | I11: CHARACTER | J11: 68397635 | K11: SSIKATKU | L11: SS SHIRT TOP WOVEN KUROMI KEMEJA IKAT SSIKATKU:KHAKI:6:GRAPHIC:SS SHIRT | M11: 149900 | N11: =N10 -> 0.3 | O11: =M11-((30*M11)/100) -> 104930 | P11: =P10 -> PERCENTAGE
A12: =A11 -> 2026 HILITE DISC 30 | B12: =B11 -> 46121 | C12: =C11 -> 46127 | D12: 3321 | E12: 337 | F12: 4 | G12: 2 | H12: 81005 | I12: CHARACTER | J12: 68397644 | K12: SSIKATKU | L12: SS SHIRT TOP WOVEN KUROMI KEMEJA IKAT SSIKATKU:KHAKI:7-8:GRAPHIC:SS SHIRT | M12: 149900 | N12: =N11 -> 0.3 | O12: =M12-((30*M12)/100) -> 104930 | P12: =P11 -> PERCENTAGE
A13: =A12 -> 2026 HILITE DISC 30 | B13: =B12 -> 46121 | C13: =C12 -> 46127 | D13: 3321 | E13: 337 | F13: 4 | G13: 2 | H13: 81005 | I13: CHARACTER | J13: 68397653 | K13: SSIKATKU | L13: SS SHIRT TOP WOVEN KUROMI KEMEJA IKAT SSIKATKU:KHAKI:9-10:GRAPHIC:SS SHIRT | M13: 149900 | N13: =N12 -> 0.3 | O13: =M13-((30*M13)/100) -> 104930 | P13: =P12 -> PERCENTAGE
A14: =A13 -> 2026 HILITE DISC 30 | B14: =B13 -> 46121 | C14: =C13 -> 46127 | D14: 3321 | E14: 337 | F14: 4 | G14: 2 | H14: 81005 | I14: CHARACTER | J14: 68397662 | K14: SSIKATKU | L14: SS SHIRT TOP WOVEN KUROMI KEMEJA IKAT SSIKATKU:KHAKI:11-12:GRAPHIC:SS SHIRT | M14: 149900 | N14: =N13 -> 0.3 | O14: =M14-((30*M14)/100) -> 104930 | P14: =P13 -> PERCENTAGE
... A43: =A42 -> 2026 HILITE DISC 30 | B43: =B42 -> 46121 | C43: =C42 -> 46127 | D43: 3321 | E43: 337 | F43: 4 | G43: 5 | H43: 81005 | I43: CHARACTER | J43: 68784412 | K43: DSDNCN | L43: SS MIDI DRESS WOVEN DNM COLLAR CINNAMOROLL DSDNCN:CLASSIC BLUE:13-14:GRAPHIC:SS MIDI DRESS | M43: 99900 | N43: =N42 -> 0.3 | O43: =M43-((30*M43)/100) -> 69930 | P43: =P42 -> PERCENTAGE

Sheet 2025 DEC D30 -3321
A1: ACARA | B1: FROM DATE | C1: TO DATE | D1: DEPT | E1: WORLD | F1: DIVISION | G1: CLASS | H1: SUPPLIER | I1: BRAND | J1: SKU | K1: ARTICLE | L1: DESCRIPTION | M1: HARGA NORMAL | N1: DISKON | O1: HARGA PROMO | P1: DISCOUNT TYPE
A2: 2025 DEC DISC 30 | B2: ='2025 JUNSEPT B1G1 - 3321'!B6 -> 46121 | C2: ='2025 JUNSEPT B1G1 - 3321'!C6 -> 46127 | D2: 3321 | E2: 337 | F2: 4 | G2: 1 | H2: 81588 | I2: CHARACTER | J2: 63151873 | K2: TSSNCN | L2: SS T-SHIRT CINNAMOROLL SNACK TSSNCN:LIGHT BLUE:4:GRAPHIC:SS T-SHIRT | M2: 99900 | N2: 0.3 | O2: =M2-((30*M2)/100) -> 69930 | P2: PERCENTAGE
A3: =A2 -> 2025 DEC DISC 30 | B3: =B2 -> 46121 | C3: =C2 -> 46127 | D3: 3321 | E3: 337 | F3: 4 | G3: 1 | H3: 81588 | I3: CHARACTER | J3: 63151882 | K3: TSSNCN | L3: SS T-SHIRT CINNAMOROLL SNACK TSSNCN:LIGHT BLUE:5:GRAPHIC:SS T-SHIRT | M3: 99900 | N3: 0.3 | O3: =M3-((30*M3)/100) -> 69930 | P3: PERCENTAGE
A4: =A3 -> 2025 DEC DISC 30 | B4: =B3 -> 46121 | C4: =C3 -> 46127 | D4: 3321 | E4: 337 | F4: 4 | G4: 1 | H4: 81588 | I4: CHARACTER | J4: 63151891 | K4: TSSNCN | L4: SS T-SHIRT CINNAMOROLL SNACK TSSNCN:LIGHT BLUE:6:GRAPHIC:SS T-SHIRT | M4: 99900 | N4: 0.3 | O4: =M4-((30*M4)/100) -> 69930 | P4: PERCENTAGE
A5: =A4 -> 2025 DEC DISC 30 | B5: =B4 -> 46121 | C5: =C4 -> 46127 | D5: 3321 | E5: 337 | F5: 4 | G5: 1 | H5: 81588 | I5: CHARACTER | J5: 63151908 | K5: TSSNCN | L5: SS T-SHIRT CINNAMOROLL SNACK TSSNCN:LIGHT BLUE:7-8:GRAPHIC:SS T-SHIRT | M5: 99900 | N5: 0.3 | O5: =M5-((30*M5)/100) -> 69930 | P5: PERCENTAGE
A6: =A5 -> 2025 DEC DISC 30 | B6: =B5 -> 46121 | C6: =C5 -> 46127 | D6: 3321 | E6: 337 | F6: 4 | G6: 1 | H6: 81588 | I6: CHARACTER | J6: 63151917 | K6: TSSNCN | L6: SS T-SHIRT CINNAMOROLL SNACK TSSNCN:LIGHT BLUE:9-10:GRAPHIC:SS T-SHIRT | M6: 99900 | N6: 0.3 | O6: =M6-((30*M6)/100) -> 69930 | P6: PERCENTAGE
A7: =A6 -> 2025 DEC DISC 30 | B7: =B6 -> 46121 | C7: =C6 -> 46127 | D7: 3321 | E7: 337 | F7: 4 | G7: 1 | H7: 81588 | I7: CHARACTER | J7: 63151926 | K7: TSSNCN | L7: SS T-SHIRT CINNAMOROLL SNACK TSSNCN:LIGHT BLUE:11-12:GRAPHIC:SS T-SHIRT | M7: 99900 | N7: 0.3 | O7: =M7-((30*M7)/100) -> 69930 | P7: PERCENTAGE
A8: =A7 -> 2025 DEC DISC 30 | B8: =B7 -> 46121 | C8: =C7 -> 46127 | D8: 3321 | E8: 337 | F8: 4 | G8: 1 | H8: 81588 | I8: CHARACTER | J8: 63152078 | K8: TS425KT2 | L8: SS T-SHIRT HELLO KITTY TS425KT2:OFF WHITE:7-8:GRAPHIC:SS T-SHIRT | M8: 99900 | N8: 0.3 | O8: =M8-((30*M8)/100) -> 69930 | P8: PERCENTAGE
A9: =A8 -> 2025 DEC DISC 30 | B9: =B8 -> 46121 | C9: =C8 -> 46127 | D9: 3321 | E9: 337 | F9: 4 | G9: 1 | H9: 81588 | I9: CHARACTER | J9: 63152087 | K9: TS425KT2 | L9: SS T-SHIRT HELLO KITTY TS425KT2:OFF WHITE:9-10:GRAPHIC:SS T-SHIRT | M9: 99900 | N9: 0.3 | O9: =M9-((30*M9)/100) -> 69930 | P9: PERCENTAGE
A10: =A9 -> 2025 DEC DISC 30 | B10: =B9 -> 46121 | C10: =C9 -> 46127 | D10: 3321 | E10: 337 | F10: 4 | G10: 1 | H10: 81588 | I10: CHARACTER | J10: 63152096 | K10: TS425KT2 | L10: SS T-SHIRT HELLO KITTY TS425KT2:OFF WHITE:11-12:GRAPHIC:SS T-SHIRT | M10: 99900 | N10: 0.3 | O10: =M10-((30*M10)/100) -> 69930 | P10: PERCENTAGE
A11: =A10 -> 2025 DEC DISC 30 | B11: =B10 -> 46121 | C11: =C10 -> 46127 | D11: 3321 | E11: 337 | F11: 4 | G11: 1 | H11: 81588 | I11: CHARACTER | J11: 63152103 | K11: TS425KT2 | L11: SS T-SHIRT HELLO KITTY TS425KT2:OFF WHITE:13-14:GRAPHIC:SS T-SHIRT | M11: 99900 | N11: 0.3 | O11: =M11-((30*M11)/100) -> 69930 | P11: PERCENTAGE
A12: =A11 -> 2025 DEC DISC 30 | B12: =B11 -> 46121 | C12: =C11 -> 46127 | D12: 3321 | E12: 337 | F12: 4 | G12: 1 | H12: 81588 | I12: CHARACTER | J12: 63152158 | K12: TSLVKU | L12: SS T-SHIRT KUROMI LOVE TSLVKU:OFF WHITE:4:GRAPHIC:SS T-SHIRT | M12: 99900 | N12: 0.3 | O12: =M12-((30*M12)/100) -> 69930 | P12: PERCENTAGE
A13: =A12 -> 2025 DEC DISC 30 | B13: =B12 -> 46121 | C13: =C12 -> 46127 | D13: 3321 | E13: 337 | F13: 4 | G13: 1 | H13: 81588 | I13: CHARACTER | J13: 63152167 | K13: TSLVKU | L13: SS T-SHIRT KUROMI LOVE TSLVKU:OFF WHITE:5:GRAPHIC:SS T-SHIRT | M13: 99900 | N13: 0.3 | O13: =M13-((30*M13)/100) -> 69930 | P13: PERCENTAGE
A14: =A13 -> 2025 DEC DISC 30 | B14: =B13 -> 46121 | C14: =C13 -> 46127 | D14: 3321 | E14: 337 | F14: 4 | G14: 1 | H14: 81588 | I14: CHARACTER | J14: 63152176 | K14: TSLVKU | L14: SS T-SHIRT KUROMI LOVE TSLVKU:OFF WHITE:6:GRAPHIC:SS T-SHIRT | M14: 99900 | N14: 0.3 | O14: =M14-((30*M14)/100) -> 69930 | P14: PERCENTAGE
... A41: =A40 -> 2025 DEC DISC 30 | B41: =B40 -> 46121 | C41: =C40 -> 46127 | D41: 3321 | E41: 337 | F41: 4 | G41: 5 | H41: 81588 | I41: CHARACTER | J41: 66253418 | K41: DS425MM | L41: SS MIDI DRESS MY MELODY SAILOR COLLAR DS425MM:PASTEL PINK:7-8:EMBRO:SS MIDI DRESS | M41: 179900 | N41: 0.3 | O41: =M41-((30*M41)/100) -> 125930 | P41: PERCENTAGE

Sheet 2025 OCTNOV D30 -3321
A1: ACARA | B1: FROM DATE | C1: TO DATE | D1: DEPT | E1: WORLD | F1: DIVISION | G1: CLASS | H1: SUPPLIER | I1: BRAND | J1: SKU | K1: ARTICLE | L1: DESCRIPTION | M1: HARGA NORMAL | N1: DISKON | O1: HARGA PROMO | P1: DISCOUNT TYPE
A2: 2025 OCT-NOV DISC 30 | B2: 46121 | C2: 46127 | D2: 3321 | E2: 337 | F2: 4 | G2: 5 | H2: 81005 | I2: CHARACTER | J2: 59168284 | K2: DSOPAW | L2: SS MIDI DRESS OVR PAW PATROL KTG DPN DSOPAW:PASTEL PINK:4:GRAPHIC:SS MIDI DRESS | M2: 179900 | N2: 0.3 | O2: =M2-((30*M2)/100) -> 125930 | P2: PERCENTAGE
A3: =A2 -> 2025 OCT-NOV DISC 30 | B3: =B2 -> 46121 | C3: =C2 -> 46127 | D3: 3321 | E3: 337 | F3: 4 | G3: 5 | H3: 81005 | I3: CHARACTER | J3: 59168293 | K3: DSOPAW | L3: SS MIDI DRESS OVR PAW PATROL KTG DPN DSOPAW:PASTEL PINK:5:GRAPHIC:SS MIDI DRESS | M3: 179900 | N3: =N2 -> 0.3 | O3: =M3-((30*M3)/100) -> 125930 | P3: PERCENTAGE
A4: =A3 -> 2025 OCT-NOV DISC 30 | B4: =B3 -> 46121 | C4: =C3 -> 46127 | D4: 3321 | E4: 337 | F4: 4 | G4: 5 | H4: 81005 | I4: CHARACTER | J4: 59168300 | K4: DSOPAW | L4: SS MIDI DRESS OVR PAW PATROL KTG DPN DSOPAW:PASTEL PINK:6:GRAPHIC:SS MIDI DRESS | M4: 179900 | N4: =N3 -> 0.3 | O4: =M4-((30*M4)/100) -> 125930 | P4: PERCENTAGE
A5: =A4 -> 2025 OCT-NOV DISC 30 | B5: =B4 -> 46121 | C5: =C4 -> 46127 | D5: 3321 | E5: 337 | F5: 4 | G5: 5 | H5: 81005 | I5: CHARACTER | J5: 59168319 | K5: DSOPAW | L5: SS MIDI DRESS OVR PAW PATROL KTG DPN DSOPAW:PASTEL PINK:7-8:GRAPHIC:SS MIDI DRESS | M5: 179900 | N5: =N4 -> 0.3 | O5: =M5-((30*M5)/100) -> 125930 | P5: PERCENTAGE
A6: =A5 -> 2025 OCT-NOV DISC 30 | B6: =B5 -> 46121 | C6: =C5 -> 46127 | D6: 3321 | E6: 337 | F6: 4 | G6: 5 | H6: 190 | I6: CHARACTER | J6: 63152390 | K6: DSPAGKT | L6: SS MIDI DRESS POLO HELLO KITTY DSPAGKT:PASTEL PINK:4:EMBRO:SS MIDI DRESS | M6: 179900 | N6: =N5 -> 0.3 | O6: =M6-((30*M6)/100) -> 125930 | P6: PERCENTAGE
A7: =A6 -> 2025 OCT-NOV DISC 30 | B7: =B6 -> 46121 | C7: =C6 -> 46127 | D7: 3321 | E7: 337 | F7: 4 | G7: 5 | H7: 190 | I7: CHARACTER | J7: 63152407 | K7: DSPAGKT | L7: SS MIDI DRESS POLO HELLO KITTY DSPAGKT:PASTEL PINK:5:EMBRO:SS MIDI DRESS | M7: 179900 | N7: =N6 -> 0.3 | O7: =M7-((30*M7)/100) -> 125930 | P7: PERCENTAGE
A8: =A7 -> 2025 OCT-NOV DISC 30 | B8: =B7 -> 46121 | C8: =C7 -> 46127 | D8: 3321 | E8: 337 | F8: 4 | G8: 5 | H8: 190 | I8: CHARACTER | J8: 63152416 | K8: DSPAGKT | L8: SS MIDI DRESS POLO HELLO KITTY DSPAGKT:PASTEL PINK:6:EMBRO:SS MIDI DRESS | M8: 179900 | N8: =N7 -> 0.3 | O8: =M8-((30*M8)/100) -> 125930 | P8: PERCENTAGE
A9: =A8 -> 2025 OCT-NOV DISC 30 | B9: =B8 -> 46121 | C9: =C8 -> 46127 | D9: 3321 | E9: 337 | F9: 4 | G9: 5 | H9: 190 | I9: CHARACTER | J9: 63152425 | K9: DSPAGKT | L9: SS MIDI DRESS POLO HELLO KITTY DSPAGKT:PASTEL PINK:7-8:EMBRO:SS MIDI DRESS | M9: 179900 | N9: =N8 -> 0.3 | O9: =M9-((30*M9)/100) -> 125930 | P9: PERCENTAGE
A10: =A9 -> 2025 OCT-NOV DISC 30 | B10: =B9 -> 46121 | C10: =C9 -> 46127 | D10: 3321 | E10: 337 | F10: 4 | G10: 5 | H10: 190 | I10: CHARACTER | J10: 63152434 | K10: DSPAGKT | L10: SS MIDI DRESS POLO HELLO KITTY DSPAGKT:PASTEL PINK:9-10:EMBRO:SS MIDI DRESS | M10: 179900 | N10: =N9 -> 0.3 | O10: =M10-((30*M10)/100) -> 125930 | P10: PERCENTAGE
A11: =A10 -> 2025 OCT-NOV DISC 30 | B11: =B10 -> 46121 | C11: =C10 -> 46127 | D11: 3321 | E11: 337 | F11: 4 | G11: 5 | H11: 190 | I11: CHARACTER | J11: 63152443 | K11: DSPAGKT | L11: SS MIDI DRESS POLO HELLO KITTY DSPAGKT:PASTEL PINK:11-12:EMBRO:SS MIDI DRESS | M11: 179900 | N11: =N10 -> 0.3 | O11: =M11-((30*M11)/100) -> 125930 | P11: PERCENTAGE
A12: =A11 -> 2025 OCT-NOV DISC 30 | B12: =B11 -> 46121 | C12: =C11 -> 46127 | D12: 3321 | E12: 337 | F12: 4 | G12: 3 | H12: 81005 | I12: CHARACTER | J12: 63152274 | K12: JKFLCKU | L12: JACKET FLEECE KUROMI JKFLCKU:BLACK:4:GRAPHIC:JACKET | M12: 199900 | N12: =N11 -> 0.3 | O12: =M12-((30*M12)/100) -> 139930 | P12: PERCENTAGE
A13: =A12 -> 2025 OCT-NOV DISC 30 | B13: =B12 -> 46121 | C13: =C12 -> 46127 | D13: 3321 | E13: 337 | F13: 4 | G13: 3 | H13: 81005 | I13: CHARACTER | J13: 63152283 | K13: JKFLCKU | L13: JACKET FLEECE KUROMI JKFLCKU:BLACK:5:GRAPHIC:JACKET | M13: 199900 | N13: =N12 -> 0.3 | O13: =M13-((30*M13)/100) -> 139930 | P13: PERCENTAGE
A14: =A13 -> 2025 OCT-NOV DISC 30 | B14: =B13 -> 46121 | C14: =C13 -> 46127 | D14: 3321 | E14: 337 | F14: 4 | G14: 3 | H14: 81005 | I14: CHARACTER | J14: 63152292 | K14: JKFLCKU | L14: JACKET FLEECE KUROMI JKFLCKU:BLACK:6:GRAPHIC:JACKET | M14: 199900 | N14: =N13 -> 0.3 | O14: =M14-((30*M14)/100) -> 139930 | P14: PERCENTAGE
... A97: =A96 -> 2025 OCT-NOV DISC 30 | B97: =B96 -> 46121 | C97: =C96 -> 46127 | D97: 3321 | E97: 337 | F97: 4 | G97: 1 | H97: 81588 | I97: CHARACTER | J97: 55507441 | K97: TSTNJ4 | L97: SS T-SHIRT TOM N JERRY HIDE N SEEK TSTNJ4:PASTEL ORANGE:11-12:GRAPHIC:SS T-SHIRT | M97: 99900 | N97: =N96 -> 0.3 | O97: =M97-((30*M97)/100) -> 69930 | P97: PERCENTAGE

Sheet 2025 JUNSEPT B1G1 - 3321
A1: ACARA | B1: FROM DATE | C1: TO DATE | D1: DEPT | E1: WORLD | F1: DIVISION | G1: CLASS | H1: SUPPLIER | I1: BRAND | J1: SKU | K1: ARTICLE | L1: DESCRIPTION | M1: HARGA NORMAL | N1: DISKON | O1: HARGA PROMO | P1: DISCOUNT TYPE
A2: 2025 JUNSEPT B1G1 | B2: 46121 | C2: 46127 | D2: 3321 | E2: 337 | F2: 4 | G2: 5 | H2: 190 | I2: CHARACTER | J2: 54955076 | K2: DS3CN | L2: SS MIDI DRESS CINNAMOROLL DS3CN:PASTEL PINK:4:GRAPHIC:SS MIDI DRESS | M2: 149900 | N2: BXGY | O2: B1G1 | P2: BXGY
A3: =A2 -> 2025 JUNSEPT B1G1 | B3: =B2 -> 46121 | C3: =C2 -> 46127 | D3: 3321 | E3: 337 | F3: 4 | G3: 5 | H3: 190 | I3: CHARACTER | J3: 54955085 | K3: DS3CN | L3: SS MIDI DRESS CINNAMOROLL DS3CN:PASTEL PINK:5:GRAPHIC:SS MIDI DRESS | M3: 149900 | N3: BXGY | O3: B1G1 | P3: BXGY
A4: =A3 -> 2025 JUNSEPT B1G1 | B4: =B3 -> 46121 | C4: =C3 -> 46127 | D4: 3321 | E4: 337 | F4: 4 | G4: 5 | H4: 190 | I4: CHARACTER | J4: 54955094 | K4: DS3CN | L4: SS MIDI DRESS CINNAMOROLL DS3CN:PASTEL PINK:6:GRAPHIC:SS MIDI DRESS | M4: 149900 | N4: BXGY | O4: B1G1 | P4: BXGY
A5: =A4 -> 2025 JUNSEPT B1G1 | B5: =B4 -> 46121 | C5: =C4 -> 46127 | D5: 3321 | E5: 337 | F5: 4 | G5: 5 | H5: 190 | I5: CHARACTER | J5: 54955101 | K5: DS3CN | L5: SS MIDI DRESS CINNAMOROLL DS3CN:PASTEL PINK:7-8:GRAPHIC:SS MIDI DRESS | M5: 149900 | N5: BXGY | O5: B1G1 | P5: BXGY
A6: =A5 -> 2025 JUNSEPT B1G1 | B6: =B5 -> 46121 | C6: =C5 -> 46127 | D6: 3321 | E6: 337 | F6: 4 | G6: 5 | H6: 81146 | I6: CHARACTER | J6: 55301627 | K6: DS3HK | L6: SS MIDI DRESS HELLO KITTY DS3HK:PASTEL PINK:4:GRAPHIC:SS MIDI DRESS | M6: 149900 | N6: BXGY | O6: B1G1 | P6: BXGY
A7: =A6 -> 2025 JUNSEPT B1G1 | B7: =B6 -> 46121 | C7: =C6 -> 46127 | D7: 3321 | E7: 337 | F7: 4 | G7: 5 | H7: 81146 | I7: CHARACTER | J7: 55301636 | K7: DS3HK | L7: SS MIDI DRESS HELLO KITTY DS3HK:PASTEL PINK:5:GRAPHIC:SS MIDI DRESS | M7: 149900 | N7: BXGY | O7: B1G1 | P7: BXGY
A8: =A7 -> 2025 JUNSEPT B1G1 | B8: =B7 -> 46121 | C8: =C7 -> 46127 | D8: 3321 | E8: 337 | F8: 4 | G8: 5 | H8: 81146 | I8: CHARACTER | J8: 55301645 | K8: DS3HK | L8: SS MIDI DRESS HELLO KITTY DS3HK:PASTEL PINK:6:GRAPHIC:SS MIDI DRESS | M8: 149900 | N8: BXGY | O8: B1G1 | P8: BXGY
A9: =A8 -> 2025 JUNSEPT B1G1 | B9: =B8 -> 46121 | C9: =C8 -> 46127 | D9: 3321 | E9: 337 | F9: 4 | G9: 5 | H9: 81146 | I9: CHARACTER | J9: 55301654 | K9: DS3HK | L9: SS MIDI DRESS HELLO KITTY DS3HK:PASTEL PINK:7-8:GRAPHIC:SS MIDI DRESS | M9: 149900 | N9: BXGY | O9: B1G1 | P9: BXGY
A10: =A9 -> 2025 JUNSEPT B1G1 | B10: =B9 -> 46121 | C10: =C9 -> 46127 | D10: 3321 | E10: 337 | F10: 4 | G10: 5 | H10: 81588 | I10: CHARACTER | J10: 55301583 | K10: DS3KU1 | L10: SS MIDI DRESS KUROMI DS3KU1:PASTEL PURPLE:4:GRAPHIC:SS MIDI DRESS | M10: 149900 | N10: BXGY | O10: B1G1 | P10: BXGY
A11: =A10 -> 2025 JUNSEPT B1G1 | B11: =B10 -> 46121 | C11: =C10 -> 46127 | D11: 3321 | E11: 337 | F11: 4 | G11: 5 | H11: 81588 | I11: CHARACTER | J11: 55301592 | K11: DS3KU1 | L11: SS MIDI DRESS KUROMI DS3KU1:PASTEL PURPLE:5:GRAPHIC:SS MIDI DRESS | M11: 149900 | N11: BXGY | O11: B1G1 | P11: BXGY
A12: =A11 -> 2025 JUNSEPT B1G1 | B12: =B11 -> 46121 | C12: =C11 -> 46127 | D12: 3321 | E12: 337 | F12: 4 | G12: 5 | H12: 81588 | I12: CHARACTER | J12: 55301609 | K12: DS3KU1 | L12: SS MIDI DRESS KUROMI DS3KU1:PASTEL PURPLE:6:GRAPHIC:SS MIDI DRESS | M12: 149900 | N12: BXGY | O12: B1G1 | P12: BXGY
A13: =A12 -> 2025 JUNSEPT B1G1 | B13: =B12 -> 46121 | C13: =C12 -> 46127 | D13: 3321 | E13: 337 | F13: 4 | G13: 5 | H13: 81588 | I13: CHARACTER | J13: 55301618 | K13: DS3KU1 | L13: SS MIDI DRESS KUROMI DS3KU1:PASTEL PURPLE:7-8:GRAPHIC:SS MIDI DRESS | M13: 149900 | N13: BXGY | O13: B1G1 | P13: BXGY
A14: =A13 -> 2025 JUNSEPT B1G1 | B14: =B13 -> 46121 | C14: =C13 -> 46127 | D14: 3321 | E14: 337 | F14: 4 | G14: 5 | H14: 81588 | I14: CHARACTER | J14: 61094528 | K14: DS3KU2 | L14: SS MIDI DRESS COLLAR KUROMI DS3KU2:BLACK:7-8:GRAPHIC:SS MIDI DRESS | M14: 179900 | N14: BXGY | O14: B1G1 | P14: BXGY
... A237: =A236 -> 2025 JUNSEPT B1G1 | B237: =B236 -> 46121 | C237: =C236 -> 46127 | D237: 3321 | E237: 337 | F237: 4 | G237: 5 | H237: 81005 | I237: CHARACTER | J237: 54391363 | K237: SETMM | L237: TOP - BOTTOM SET SKORT MY MELODY SETMM:PASTEL PINK:7-8:GRAPHIC:TOP - BOTTOM SET | M237: 299900 | N237: BXGY | O237: B1G1 | P237: BXGY

Sheet 2025 JAN-MEI D75 - 3321
A1: ACARA | B1: FROM DATE | C1: TO DATE | D1: DEPT | E1: WORLD | F1: DIVISION | G1: CLASS | H1: SUPPLIER | I1: BRAND | J1: SKU | K1: ARTICLE | L1: DESCRIPTION | M1: HARGA NORMAL | N1: DISKON | O1: HARGA PROMO | P1: DISCOUNT TYPE
A2: 2025 JAN-MEI DISC 75% | B2: 46121 | C2: 46127 | D2: 3321 | E2: 337 | F2: 4 | G2: 4 | H2: 81588 | I2: CHARACTER | J2: 51607135 | K2: SKKU | L2: SKORT PARASUT KUROMI SKKU:BLACK:3-4:GRAPHIC:SKORT | M2: 199900 | N2: 0.75 | O2: =M2-((75*M2)/100) -> 49975 | P2: PERCENTAGE
A3: =A2 -> 2025 JAN-MEI DISC 75% | B3: =B2 -> 46121 | C3: =C2 -> 46127 | D3: 3321 | E3: 337 | F3: 4 | G3: 4 | H3: 81588 | I3: CHARACTER | J3: 51607144 | K3: SKKU | L3: SKORT PARASUT KUROMI SKKU:BLACK:4-5:GRAPHIC:SKORT | M3: 199900 | N3: 0.75 | O3: =M3-((75*M3)/100) -> 49975 | P3: =P2 -> PERCENTAGE
A4: =A3 -> 2025 JAN-MEI DISC 75% | B4: =B3 -> 46121 | C4: =C3 -> 46127 | D4: 3321 | E4: 337 | F4: 4 | G4: 4 | H4: 81588 | I4: CHARACTER | J4: 51607153 | K4: SKKU | L4: SKORT PARASUT KUROMI SKKU:BLACK:5-6:GRAPHIC:SKORT | M4: 199900 | N4: 0.75 | O4: =M4-((75*M4)/100) -> 49975 | P4: =P3 -> PERCENTAGE
A5: =A4 -> 2025 JAN-MEI DISC 75% | B5: =B4 -> 46121 | C5: =C4 -> 46127 | D5: 3321 | E5: 337 | F5: 4 | G5: 4 | H5: 81588 | I5: CHARACTER | J5: 51607162 | K5: SKKU | L5: SKORT PARASUT KUROMI SKKU:BLACK:7-8:GRAPHIC:SKORT | M5: 199900 | N5: 0.75 | O5: =M5-((75*M5)/100) -> 49975 | P5: =P4 -> PERCENTAGE
A6: =A5 -> 2025 JAN-MEI DISC 75% | B6: =B5 -> 46121 | C6: =C5 -> 46127 | D6: 3321 | E6: 337 | F6: 4 | G6: 4 | H6: 81588 | I6: CHARACTER | J6: 51837191 | K6: SKKU | L6: SKORT PARASUT KUROMI SKKU:BLACK:9-10:GRAPHIC:SKORT | M6: 199900 | N6: 0.75 | O6: =M6-((75*M6)/100) -> 49975 | P6: =P5 -> PERCENTAGE
A7: =A6 -> 2025 JAN-MEI DISC 75% | B7: =B6 -> 46121 | C7: =C6 -> 46127 | D7: 3321 | E7: 337 | F7: 4 | G7: 4 | H7: 81588 | I7: CHARACTER | J7: 51837208 | K7: SKKU | L7: SKORT PARASUT KUROMI SKKU:BLACK:11-12:GRAPHIC:SKORT | M7: 199900 | N7: 0.75 | O7: =M7-((75*M7)/100) -> 49975 | P7: =P6 -> PERCENTAGE
A8: =A7 -> 2025 JAN-MEI DISC 75% | B8: =B7 -> 46121 | C8: =C7 -> 46127 | D8: 3321 | E8: 337 | F8: 4 | G8: 5 | H8: 190 | I8: CHARACTER | J8: 51607019 | K8: DSOARMM | L8: SS MIDI DRESS OVERALL MY MELODY DSOARMM:PASTEL GREEN:3-4:GRAPHIC:SS MIDI DRESS | M8: 259900 | N8: 0.75 | O8: =M8-((75*M8)/100) -> 64975 | P8: =P7 -> PERCENTAGE
A9: =A8 -> 2025 JAN-MEI DISC 75% | B9: =B8 -> 46121 | C9: =C8 -> 46127 | D9: 3321 | E9: 337 | F9: 4 | G9: 5 | H9: 190 | I9: CHARACTER | J9: 51607028 | K9: DSOARMM | L9: SS MIDI DRESS OVERALL MY MELODY DSOARMM:PASTEL GREEN:4-5:GRAPHIC:SS MIDI DRESS | M9: 259900 | N9: 0.75 | O9: =M9-((75*M9)/100) -> 64975 | P9: =P8 -> PERCENTAGE
A10: =A9 -> 2025 JAN-MEI DISC 75% | B10: =B9 -> 46121 | C10: =C9 -> 46127 | D10: 3321 | E10: 337 | F10: 4 | G10: 5 | H10: 190 | I10: CHARACTER | J10: 51607037 | K10: DSOARMM | L10: SS MIDI DRESS OVERALL MY MELODY DSOARMM:PASTEL GREEN:5-6:GRAPHIC:SS MIDI DRESS | M10: 259900 | N10: 0.75 | O10: =M10-((75*M10)/100) -> 64975 | P10: =P9 -> PERCENTAGE
A11: =A10 -> 2025 JAN-MEI DISC 75% | B11: =B10 -> 46121 | C11: =C10 -> 46127 | D11: 3321 | E11: 337 | F11: 4 | G11: 5 | H11: 190 | I11: CHARACTER | J11: 51607046 | K11: DSOARMM | L11: SS MIDI DRESS OVERALL MY MELODY DSOARMM:PASTEL GREEN:7-8:GRAPHIC:SS MIDI DRESS | M11: 259900 | N11: 0.75 | O11: =M11-((75*M11)/100) -> 64975 | P11: =P10 -> PERCENTAGE
A12: =A11 -> 2025 JAN-MEI DISC 75% | B12: =B11 -> 46121 | C12: =C11 -> 46127 | D12: 3321 | E12: 337 | F12: 4 | G12: 5 | H12: 190 | I12: CHARACTER | J12: 51607055 | K12: DSPTMM | L12: SS MIDI DRESS MY MELODY DSPTMM:PASTEL PINK:3-4:GRAPHIC:SS MIDI DRESS | M12: 259900 | N12: 0.75 | O12: =M12-((75*M12)/100) -> 64975 | P12: =P11 -> PERCENTAGE
A13: =A12 -> 2025 JAN-MEI DISC 75% | B13: =B12 -> 46121 | C13: =C12 -> 46127 | D13: 3321 | E13: 337 | F13: 4 | G13: 5 | H13: 190 | I13: CHARACTER | J13: 51607064 | K13: DSPTMM | L13: SS MIDI DRESS MY MELODY DSPTMM:PASTEL PINK:4-5:GRAPHIC:SS MIDI DRESS | M13: 259900 | N13: 0.75 | O13: =M13-((75*M13)/100) -> 64975 | P13: =P12 -> PERCENTAGE
A14: =A13 -> 2025 JAN-MEI DISC 75% | B14: =B13 -> 46121 | C14: =C13 -> 46127 | D14: 3321 | E14: 337 | F14: 4 | G14: 5 | H14: 190 | I14: CHARACTER | J14: 51607073 | K14: DSPTMM | L14: SS MIDI DRESS MY MELODY DSPTMM:PASTEL PINK:5-6:GRAPHIC:SS MIDI DRESS | M14: 259900 | N14: 0.75 | O14: =M14-((75*M14)/100) -> 64975 | P14: =P13 -> PERCENTAGE
... A176: =A175 -> 2025 JAN-MEI DISC 75% | B176: =B175 -> 46121 | C176: =C175 -> 46127 | D176: 3321 | E176: 337 | F176: 4 | G176: 4 | H176: 81005 | I176: CHARACTER | J176: 54391247 | K176: SKBMM | L176: MINI SKIRT BALON MY MELODY SKBMM:PASTEL PINK:7-8:PRINT:MINI SKIRT | M176: 199900 | N176: 0.75 | O176: =M176-((75*M176)/100) -> 49975 | P176: =P175 -> PERCENTAGE
A177: =A176 -> 2025 JAN-MEI DISC 75% | B177: =B176 -> 46121 | C177: =C176 -> 46127 | D177: 3321 | E177: 337 | F177: 4 | G177: 1 | H177: 81676 | I177: CHARACTER | J177: 54462474 | K177: TSGGHK2 | L177: SS T-SHIRT TD HELLO KITTY TSGGHK2:OFF WHITE:3-4:GRAPHIC:SS T-SHIRT | M177: 149900 | N177: 0.75 | O177: =M177-((75*M177)/100) -> 37475 | P177: PERCENTAGE
A178: =A177 -> 2025 JAN-MEI DISC 75% | B178: =B177 -> 46121 | C178: =C177 -> 46127 | D178: 3321 | E178: 337 | F178: 4 | G178: 1 | H178: 81676 | I178: CHARACTER | J178: 54462483 | K178: TSGGHK2 | L178: SS T-SHIRT TD HELLO KITTY TSGGHK2:OFF WHITE:4-5:GRAPHIC:SS T-SHIRT | M178: 149900 | N178: 0.75 | O178: =M178-((75*M178)/100) -> 37475 | P178: PERCENTAGE
A179: =A178 -> 2025 JAN-MEI DISC 75% | B179: =B178 -> 46121 | C179: =C178 -> 46127 | D179: 3321 | E179: 337 | F179: 4 | G179: 1 | H179: 81676 | I179: CHARACTER | J179: 54462492 | K179: TSGGHK2 | L179: SS T-SHIRT TD HELLO KITTY TSGGHK2:OFF WHITE:5-6:GRAPHIC:SS T-SHIRT | M179: 149900 | N179: 0.75 | O179: =M179-((75*M179)/100) -> 37475 | P179: PERCENTAGE
A180: =A179 -> 2025 JAN-MEI DISC 75% | B180: =B179 -> 46121 | C180: =C179 -> 46127 | D180: 3321 | E180: 337 | F180: 4 | G180: 1 | H180: 81676 | I180: CHARACTER | J180: 54462509 | K180: TSGGHK2 | L180: SS T-SHIRT TD HELLO KITTY TSGGHK2:OFF WHITE:7-8:GRAPHIC:SS T-SHIRT | M180: 149900 | N180: 0.75 | O180: =M180-((75*M180)/100) -> 37475 | P180: PERCENTAGE
A181: =A180 -> 2025 JAN-MEI DISC 75% | B181: =B180 -> 46121 | C181: =C180 -> 46127 | D181: 3321 | E181: 337 | F181: 4 | G181: 1 | H181: 81676 | I181: CHARACTER | J181: 54462518 | K181: TSGGHK2 | L181: SS T-SHIRT TD HELLO KITTY TSGGHK2:OFF WHITE:9-10:GRAPHIC:SS T-SHIRT | M181: 149900 | N181: 0.75 | O181: =M181-((75*M181)/100) -> 37475 | P181: PERCENTAGE
A182: =A181 -> 2025 JAN-MEI DISC 75% | B182: =B181 -> 46121 | C182: =C181 -> 46127 | D182: 3321 | E182: 337 | F182: 4 | G182: 1 | H182: 81676 | I182: CHARACTER | J182: 54462527 | K182: TSGGHK2 | L182: SS T-SHIRT TD HELLO KITTY TSGGHK2:OFF WHITE:11-12:GRAPHIC:SS T-SHIRT | M182: 149900 | N182: 0.75 | O182: =M182-((75*M182)/100) -> 37475 | P182: PERCENTAGE
A183: =A182 -> 2025 JAN-MEI DISC 75% | B183: =B182 -> 46121 | C183: =C182 -> 46127 | D183: 3321 | E183: 337 | F183: 4 | G183: 1 | H183: 81676 | I183: CHARACTER | J183: 54462410 | K183: TSGGHK1 | L183: SS T-SHIRT KTG HELLO KITTY TSGGHK1:PASTEL PINK:3-4:GRAPHIC:SS T-SHIRT | M183: 149900 | N183: 0.75 | O183: =M183-((75*M183)/100) -> 37475 | P183: PERCENTAGE
A184: =A183 -> 2025 JAN-MEI DISC 75% | B184: =B183 -> 46121 | C184: =C183 -> 46127 | D184: 3321 | E184: 337 | F184: 4 | G184: 1 | H184: 81676 | I184: CHARACTER | J184: 54462429 | K184: TSGGHK1 | L184: SS T-SHIRT KTG HELLO KITTY TSGGHK1:PASTEL PINK:4-5:GRAPHIC:SS T-SHIRT | M184: 149900 | N184: 0.75 | O184: =M184-((75*M184)/100) -> 37475 | P184: PERCENTAGE
A185: =A184 -> 2025 JAN-MEI DISC 75% | B185: =B184 -> 46121 | C185: =C184 -> 46127 | D185: 3321 | E185: 337 | F185: 4 | G185: 1 | H185: 81676 | I185: CHARACTER | J185: 54462438 | K185: TSGGHK1 | L185: SS T-SHIRT KTG HELLO KITTY TSGGHK1:PASTEL PINK:5-6:GRAPHIC:SS T-SHIRT | M185: 149900 | N185: 0.75 | O185: =M185-((75*M185)/100) -> 37475 | P185: PERCENTAGE
A186: =A185 -> 2025 JAN-MEI DISC 75% | B186: =B185 -> 46121 | C186: =C185 -> 46127 | D186: 3321 | E186: 337 | F186: 4 | G186: 1 | H186: 81676 | I186: CHARACTER | J186: 54462447 | K186: TSGGHK1 | L186: SS T-SHIRT KTG HELLO KITTY TSGGHK1:PASTEL PINK:7-8:GRAPHIC:SS T-SHIRT | M186: 149900 | N186: 0.75 | O186: =M186-((75*M186)/100) -> 37475 | P186: PERCENTAGE
A187: =A186 -> 2025 JAN-MEI DISC 75% | B187: =B186 -> 46121 | C187: =C186 -> 46127 | D187: 3321 | E187: 337 | F187: 4 | G187: 1 | H187: 81676 | I187: CHARACTER | J187: 54462456 | K187: TSGGHK1 | L187: SS T-SHIRT KTG HELLO KITTY TSGGHK1:PASTEL PINK:9-10:GRAPHIC:SS T-SHIRT | M187: 149900 | N187: 0.75 | O187: =M187-((75*M187)/100) -> 37475 | P187: PERCENTAGE
A188: =A187 -> 2025 JAN-MEI DISC 75% | B188: =B187 -> 46121 | C188: =C187 -> 46127 | D188: 3321 | E188: 337 | F188: 4 | G188: 1 | H188: 81676 | I188: CHARACTER | J188: 54462465 | K188: TSGGHK1 | L188: SS T-SHIRT KTG HELLO KITTY TSGGHK1:PASTEL PINK:11-12:GRAPHIC:SS T-SHIRT | M188: 149900 | N188: 0.75 | O188: =M188-((75*M188)/100) -> 37475 | P188: PERCENTAGE
... A204: =A203 -> 2025 JAN-MEI DISC 75% | B204: =B203 -> 46121 | C204: =C203 -> 46127 | D204: 3321 | E204: 337 | F204: 4 | G204: 1 | H204: 81462 | I204: CHARACTER | J204: 54462401 | K204: TS254MM | L204: SS T-SHIRT MY MELODY TS254MM:PASTEL PINK:7-8:GRAPHIC:SS T-SHIRT | M204: 119900 | N204: 0.75 | O204: =M204-((75*M204)/100) -> 29975 | P204: PERCENTAGE

Sheet 2025 HILITE D80 - 3321
A1: ACARA | B1: FROM DATE | C1: TO DATE | D1: DEPT | E1: WORLD | F1: DIVISION | G1: CLASS | H1: SUPPLIER | I1: BRAND | J1: SKU | K1: ARTICLE | L1: DESCRIPTION | M1: HARGA NORMAL | N1: DISKON | O1: HARGA PROMO | P1: DISCOUNT TYPE
A2: 2025 HILITE DISC 80 | B2: ='2025 JUNSEPT B1G1 - 3321'!B6 -> 46121 | C2: ='2025 JUNSEPT B1G1 - 3321'!C6 -> 46127 | D2: 3321 | E2: 337 | F2: 4 | G2: 3 | H2: 81005 | I2: CHARACTER | J2: 52133270 | K2: LSSWCN | L2: LS SHIRT KOMBI WOVEN CINNAMOROLL LSSWCN:PASTEL PINK:5-6:STRIPES:LS SHIRT | M2: 229900 | N2: 0.8 | O2: =M2-((80*M2)/100) -> 45980 | P2: PERCENTAGE
A3: 2025 HILITE DISC 80 | B3: =B2 -> 46121 | C3: =C2 -> 46127 | D3: 3321 | E3: 337 | F3: 4 | G3: 3 | H3: 81005 | I3: CHARACTER | J3: 52133289 | K3: LSSWCN | L3: LS SHIRT KOMBI WOVEN CINNAMOROLL LSSWCN:PASTEL PINK:7-8:STRIPES:LS SHIRT | M3: 229900 | N3: 0.8 | O3: =M3-((80*M3)/100) -> 45980 | P3: PERCENTAGE
A4: 2025 HILITE DISC 80 | B4: =B3 -> 46121 | C4: =C3 -> 46127 | D4: 3321 | E4: 337 | F4: 4 | G4: 3 | H4: 81005 | I4: CHARACTER | J4: 52133298 | K4: LSSWCN | L4: LS SHIRT KOMBI WOVEN CINNAMOROLL LSSWCN:PASTEL PINK:9-10:STRIPES:LS SHIRT | M4: 229900 | N4: 0.8 | O4: =M4-((80*M4)/100) -> 45980 | P4: PERCENTAGE
A5: 2025 HILITE DISC 80 | B5: =B4 -> 46121 | C5: =C4 -> 46127 | D5: 3321 | E5: 337 | F5: 4 | G5: 3 | H5: 81005 | I5: CHARACTER | J5: 52133305 | K5: LSSWCN | L5: LS SHIRT KOMBI WOVEN CINNAMOROLL LSSWCN:PASTEL PINK:11-12:STRIPES:LS SHIRT | M5: 229900 | N5: 0.8 | O5: =M5-((80*M5)/100) -> 45980 | P5: PERCENTAGE
A6: 2025 HILITE DISC 80 | B6: =B5 -> 46121 | C6: =C5 -> 46127 | D6: 3321 | E6: 337 | F6: 4 | G6: 3 | H6: 81005 | I6: CHARACTER | J6: 52133314 | K6: LSSWKU | L6: LS SHIRT KOMBI WOVEN KUROMI LSSWKU:PASTEL PURPLE:5-6:STRIPES:LS SHIRT | M6: 229900 | N6: 0.8 | O6: =M6-((80*M6)/100) -> 45980 | P6: PERCENTAGE
A7: 2025 HILITE DISC 80 | B7: =B6 -> 46121 | C7: =C6 -> 46127 | D7: 3321 | E7: 337 | F7: 4 | G7: 3 | H7: 81005 | I7: CHARACTER | J7: 52133323 | K7: LSSWKU | L7: LS SHIRT KOMBI WOVEN KUROMI LSSWKU:PASTEL PURPLE:7-8:STRIPES:LS SHIRT | M7: 229900 | N7: 0.8 | O7: =M7-((80*M7)/100) -> 45980 | P7: PERCENTAGE
A8: 2025 HILITE DISC 80 | B8: =B7 -> 46121 | C8: =C7 -> 46127 | D8: 3321 | E8: 337 | F8: 4 | G8: 3 | H8: 81005 | I8: CHARACTER | J8: 52133332 | K8: LSSWKU | L8: LS SHIRT KOMBI WOVEN KUROMI LSSWKU:PASTEL PURPLE:9-10:STRIPES:LS SHIRT | M8: 229900 | N8: 0.8 | O8: =M8-((80*M8)/100) -> 45980 | P8: PERCENTAGE
A9: 2025 HILITE DISC 80 | B9: =B8 -> 46121 | C9: =C8 -> 46127 | D9: 3321 | E9: 337 | F9: 4 | G9: 3 | H9: 81005 | I9: CHARACTER | J9: 52133341 | K9: LSSWKU | L9: LS SHIRT KOMBI WOVEN KUROMI LSSWKU:PASTEL PURPLE:11-12:STRIPES:LS SHIRT | M9: 229900 | N9: 0.8 | O9: =M9-((80*M9)/100) -> 45980 | P9: PERCENTAGE
A10: 2025 HILITE DISC 80 | B10: =B9 -> 46121 | C10: =C9 -> 46127 | D10: 3321 | E10: 337 | F10: 4 | G10: 3 | H10: 81005 | I10: CHARACTER | J10: 52133529 | K10: DL25CN | L10: LS MIDI DRESS MIDI CINNAMOROLL DL25CN:PASTEL BLUE:3-4:STRIPES:LS MIDI DRESS | M10: 299900 | N10: 0.8 | O10: =M10-((80*M10)/100) -> 59980 | P10: PERCENTAGE
A11: 2025 HILITE DISC 80 | B11: =B10 -> 46121 | C11: =C10 -> 46127 | D11: 3321 | E11: 337 | F11: 4 | G11: 3 | H11: 81005 | I11: CHARACTER | J11: 52133538 | K11: DL25CN | L11: LS MIDI DRESS MIDI CINNAMOROLL DL25CN:PASTEL BLUE:4-5:STRIPES:LS MIDI DRESS | M11: 299900 | N11: 0.8 | O11: =M11-((80*M11)/100) -> 59980 | P11: PERCENTAGE
A12: 2025 HILITE DISC 80 | B12: =B11 -> 46121 | C12: =C11 -> 46127 | D12: 3321 | E12: 337 | F12: 4 | G12: 3 | H12: 81005 | I12: CHARACTER | J12: 52133547 | K12: DL25CN | L12: LS MIDI DRESS MIDI CINNAMOROLL DL25CN:PASTEL BLUE:5-6:STRIPES:LS MIDI DRESS | M12: 299900 | N12: 0.8 | O12: =M12-((80*M12)/100) -> 59980 | P12: PERCENTAGE
A13: 2025 HILITE DISC 80 | B13: =B12 -> 46121 | C13: =C12 -> 46127 | D13: 3321 | E13: 337 | F13: 4 | G13: 3 | H13: 81005 | I13: CHARACTER | J13: 52133556 | K13: DL25CN | L13: LS MIDI DRESS MIDI CINNAMOROLL DL25CN:PASTEL BLUE:7-8:STRIPES:LS MIDI DRESS | M13: 299900 | N13: 0.8 | O13: =M13-((80*M13)/100) -> 59980 | P13: PERCENTAGE
A14: 2025 HILITE DISC 80 | B14: =B13 -> 46121 | C14: =C13 -> 46127 | D14: 3321 | E14: 337 | F14: 4 | G14: 3 | H14: 81005 | I14: CHARACTER | J14: 52133565 | K14: DL25CN | L14: LS MIDI DRESS MIDI CINNAMOROLL DL25CN:PASTEL BLUE:9-10:STRIPES:LS MIDI DRESS | M14: 299900 | N14: 0.8 | O14: =M14-((80*M14)/100) -> 59980 | P14: PERCENTAGE
... A29: 2025 HILITE DISC 80 | B29: =B28 -> 46121 | C29: =C28 -> 46127 | D29: 3321 | E29: 337 | F29: 4 | G29: 3 | H29: 81698 | I29: CHARACTER | J29: 52296863 | K29: DL25AKU | L29: LS MIDI DRESS LEB KUROMI DL25AKU:PASTEL PURPLE:11-12:GRAPHIC:LS MIDI DRESS | M29: 339900 | N29: 0.8 | O29: =M29-((80*M29)/100) -> 67980 | P29: PERCENTAGE

Sheet 2024 JAN-DEC D75 - 3321
A1: ACARA | B1: FROM DATE | C1: TO DATE | D1: DEPT | E1: WORLD | F1: DIVISION | G1: CLASS | H1: SUPPLIER | I1: BRAND | J1: SKU | K1: ARTICLE | L1: DESCRIPTION | M1: HARGA NORMAL | N1: DISKON | O1: HARGA PROMO | P1: DISCOUNT TYPE
A2: 2024 JAN-DEC DISC 75 | B2: ='2025 JUNSEPT B1G1 - 3321'!B6 -> 46121 | C2: ='2025 JUNSEPT B1G1 - 3321'!C6 -> 46127 | D2: 3321 | E2: 337 | F2: 4 | G2: 1 | H2: 81421 | I2: CHARACTER | J2: 15928526 | K2: TSPPG44 | L2: SS T-SHIRT PPG KERAH TSPPG44:PASTEL PINK:5-6:GRAPHIC:SS T-SHIRT | M2: 159900 | N2: 0.75 | O2: =M2-((75*M2))/100 -> 39975 | P2: PERCENTAGE
A3: =A2 -> 2024 JAN-DEC DISC 75 | B3: =B2 -> 46121 | C3: =C2 -> 46127 | D3: 3321 | E3: 337 | F3: 4 | G3: 1 | H3: 81421 | I3: CHARACTER | J3: 15928535 | K3: TSPPG44 | L3: SS T-SHIRT PPG KERAH TSPPG44:PASTEL PINK:7-8:GRAPHIC:SS T-SHIRT | M3: 159900 | N3: =N2 -> 0.75 | O3: =M3-((70*M3))/100 -> 47970 | P3: PERCENTAGE
A4: =A3 -> 2024 JAN-DEC DISC 75 | B4: =B3 -> 46121 | C4: =C3 -> 46127 | D4: 3321 | E4: 337 | F4: 4 | G4: 1 | H4: 81421 | I4: CHARACTER | J4: 15928553 | K4: TSPPG44 | L4: SS T-SHIRT PPG KERAH TSPPG44:PASTEL PINK:11-12:GRAPHIC:SS T-SHIRT | M4: 159900 | N4: =N3 -> 0.75 | O4: =M4-((70*M4))/100 -> 47970 | P4: PERCENTAGE
A5: =A4 -> 2024 JAN-DEC DISC 75 | B5: =B4 -> 46121 | C5: =C4 -> 46127 | D5: 3321 | E5: 337 | F5: 4 | G5: 1 | H5: 81421 | I5: CHARACTER | J5: 15928562 | K5: TSPPG41 | L5: SS T-SHIRT PPG OMBRE LENGAN RUFFLE TSPPG41:PASTEL PINK:5-6:GRAPHIC:SS T-SHIRT | M5: 149900 | N5: =N4 -> 0.75 | O5: =M5-((70*M5))/100 -> 44970 | P5: PERCENTAGE
A6: =A5 -> 2024 JAN-DEC DISC 75 | B6: =B5 -> 46121 | C6: =C5 -> 46127 | D6: 3321 | E6: 337 | F6: 4 | G6: 1 | H6: 81421 | I6: CHARACTER | J6: 15928571 | K6: TSPPG41 | L6: SS T-SHIRT PPG OMBRE LENGAN RUFFLE TSPPG41:PASTEL PINK:7-8:GRAPHIC:SS T-SHIRT | M6: 149900 | N6: =N5 -> 0.75 | O6: =M6-((70*M6))/100 -> 44970 | P6: PERCENTAGE
A7: =A6 -> 2024 JAN-DEC DISC 75 | B7: =B6 -> 46121 | C7: =C6 -> 46127 | D7: 3321 | E7: 337 | F7: 4 | G7: 1 | H7: 81421 | I7: CHARACTER | J7: 15928580 | K7: TSPPG41 | L7: SS T-SHIRT PPG OMBRE LENGAN RUFFLE TSPPG41:PASTEL PINK:9-10:GRAPHIC:SS T-SHIRT | M7: 149900 | N7: =N6 -> 0.75 | O7: =M7-((70*M7))/100 -> 44970 | P7: PERCENTAGE
A8: =A7 -> 2024 JAN-DEC DISC 75 | B8: =B7 -> 46121 | C8: =C7 -> 46127 | D8: 3321 | E8: 337 | F8: 4 | G8: 1 | H8: 81421 | I8: CHARACTER | J8: 15928599 | K8: TSPPG41 | L8: SS T-SHIRT PPG OMBRE LENGAN RUFFLE TSPPG41:PASTEL PINK:11-12:GRAPHIC:SS T-SHIRT | M8: 149900 | N8: =N7 -> 0.75 | O8: =M8-((70*M8))/100 -> 44970 | P8: PERCENTAGE
A9: =A8 -> 2024 JAN-DEC DISC 75 | B9: =B8 -> 46121 | C9: =C8 -> 46127 | D9: 3321 | E9: 337 | F9: 4 | G9: 1 | H9: 81421 | I9: CHARACTER | J9: 15928606 | K9: TSPPG42 | L9: SS T-SHIRT PPG LENGAN SERUT TSPPG42:PASTEL BLUE:5-6:GRAPHIC:SS T-SHIRT | M9: 149900 | N9: =N8 -> 0.75 | O9: =M9-((70*M9))/100 -> 44970 | P9: PERCENTAGE
A10: =A9 -> 2024 JAN-DEC DISC 75 | B10: =B9 -> 46121 | C10: =C9 -> 46127 | D10: 3321 | E10: 337 | F10: 4 | G10: 1 | H10: 81421 | I10: CHARACTER | J10: 15928615 | K10: TSPPG42 | L10: SS T-SHIRT PPG LENGAN SERUT TSPPG42:PASTEL BLUE:7-8:GRAPHIC:SS T-SHIRT | M10: 149900 | N10: =N9 -> 0.75 | O10: =M10-((70*M10))/100 -> 44970 | P10: PERCENTAGE
A11: =A10 -> 2024 JAN-DEC DISC 75 | B11: =B10 -> 46121 | C11: =C10 -> 46127 | D11: 3321 | E11: 337 | F11: 4 | G11: 1 | H11: 81421 | I11: CHARACTER | J11: 15928624 | K11: TSPPG42 | L11: SS T-SHIRT PPG LENGAN SERUT TSPPG42:PASTEL BLUE:9-10:GRAPHIC:SS T-SHIRT | M11: 149900 | N11: =N10 -> 0.75 | O11: =M11-((70*M11))/100 -> 44970 | P11: PERCENTAGE
A12: =A11 -> 2024 JAN-DEC DISC 75 | B12: =B11 -> 46121 | C12: =C11 -> 46127 | D12: 3321 | E12: 337 | F12: 4 | G12: 1 | H12: 81421 | I12: CHARACTER | J12: 15928633 | K12: TSPPG42 | L12: SS T-SHIRT PPG LENGAN SERUT TSPPG42:PASTEL BLUE:11-12:GRAPHIC:SS T-SHIRT | M12: 149900 | N12: =N11 -> 0.75 | O12: =M12-((70*M12))/100 -> 44970 | P12: PERCENTAGE
A13: =A12 -> 2024 JAN-DEC DISC 75 | B13: =B12 -> 46121 | C13: =C12 -> 46127 | D13: 3321 | E13: 337 | F13: 4 | G13: 1 | H13: 81421 | I13: CHARACTER | J13: 16130706 | K13: TSHK1 | L13: SS T-SHIRT FP BBTR HELLO KITTY W BAG TSHK1:CLASSIC RED:3-4:PRINT:SS T-SHIRT | M13: 179900 | N13: =N12 -> 0.75 | O13: =M13-((70*M13))/100 -> 53970 | P13: PERCENTAGE
A14: =A13 -> 2024 JAN-DEC DISC 75 | B14: =B13 -> 46121 | C14: =C13 -> 46127 | D14: 3321 | E14: 337 | F14: 4 | G14: 1 | H14: 81421 | I14: CHARACTER | J14: 16130715 | K14: TSHK1 | L14: SS T-SHIRT FP BBTR HELLO KITTY W BAG TSHK1:CLASSIC RED:4-5:PRINT:SS T-SHIRT | M14: 179900 | N14: =N13 -> 0.75 | O14: =M14-((70*M14))/100 -> 53970 | P14: PERCENTAGE
... A512: =A511 -> 2024 JAN-DEC DISC 75 | B512: =B511 -> 46121 | C512: =C511 -> 46127 | D512: 3321 | E512: 337 | F512: 4 | G512: 5 | H512: 81698 | I512: CHARACTER | J512: 26742198 | K512: DSTLMM | L512: SS MIDI DRESS MELODY W 3D FLOWER DSTLMM:PASTEL PINK:4-5:GRAPHIC:SS MIDI DRESS | M512: 319900 | N512: =N511 -> 0.75 | O512: =M512-((70*M512))/100 -> 95970 | P512: PERCENTAGE

Sheet 2023 JUN-DEC D90 - 3321
A1: ACARA | B1: FROM DATE | C1: TO DATE | D1: DEPT | E1: WORLD | F1: DIVISION | G1: CLASS | H1: SUPPLIER | I1: BRAND | J1: SKU | K1: ARTICLE | L1: DESCRIPTION | M1: HARGA NORMAL | N1: DISKON | O1: HARGA PROMO | P1: DISCOUNT TYPE
A2: 2023 JUN-DEC DISC 90 | B2: ='2025 JUNSEPT B1G1 - 3321'!B6 -> 46121 | C2: ='2025 JUNSEPT B1G1 - 3321'!C6 -> 46127 | D2: 3321 | E2: 337 | F2: 4 | G2: 1 | H2: 81421 | I2: CHARACTER | J2: 14608392 | K2: TSPPG4 | L2: SS T-SHIRT PPG GIRLS LENGAN KERUT TSPPG4:PASTEL PURPLE:5-6:GRAPHIC:SS T-SHIRT | M2: 149900 | N2: 0.9 | O2: =M2-((90*M2)/100) -> 14990 | P2: PERCENTAGE
A3: 2023 JUN-DEC DISC 90 | B3: =B2 -> 46121 | C3: =C2 -> 46127 | D3: 3321 | E3: 337 | F3: 4 | G3: 1 | H3: 81421 | I3: CHARACTER | J3: 14608418 | K3: TSPPG4 | L3: SS T-SHIRT PPG GIRLS LENGAN KERUT TSPPG4:PASTEL PURPLE:9-10:GRAPHIC:SS T-SHIRT | M3: 149900 | N3: 0.9 | O3: =M3-((90*M3)/100) -> 14990 | P3: PERCENTAGE
A4: 2023 JUN-DEC DISC 90 | B4: =B3 -> 46121 | C4: =C3 -> 46127 | D4: 3321 | E4: 337 | F4: 4 | G4: 1 | H4: 81421 | I4: CHARACTER | J4: 14608427 | K4: TSPPG4 | L4: SS T-SHIRT PPG GIRLS LENGAN KERUT TSPPG4:PASTEL PURPLE:11-12:GRAPHIC:SS T-SHIRT | M4: 149900 | N4: 0.9 | O4: =M4-((90*M4)/100) -> 14990 | P4: PERCENTAGE
A5: 2023 JUN-DEC DISC 90 | B5: =B4 -> 46121 | C5: =C4 -> 46127 | D5: 3321 | E5: 337 | F5: 4 | G5: 1 | H5: 81421 | I5: CHARACTER | J5: 14608436 | K5: TSPPG5 | L5: SS T-SHIRT PPG 25 CUT AND SEWN TSPPG5:PASTEL PINK:5-6:GRAPHIC:SS T-SHIRT | M5: 149900 | N5: 0.9 | O5: =M5-((90*M5)/100) -> 14990 | P5: PERCENTAGE
A6: 2023 JUN-DEC DISC 90 | B6: =B5 -> 46121 | C6: =C5 -> 46127 | D6: 3321 | E6: 337 | F6: 4 | G6: 1 | H6: 81421 | I6: CHARACTER | J6: 14608445 | K6: TSPPG5 | L6: SS T-SHIRT PPG 25 CUT AND SEWN TSPPG5:PASTEL PINK:7-8:GRAPHIC:SS T-SHIRT | M6: 149900 | N6: 0.9 | O6: =M6-((90*M6)/100) -> 14990 | P6: PERCENTAGE
A7: 2023 JUN-DEC DISC 90 | B7: =B6 -> 46121 | C7: =C6 -> 46127 | D7: 3321 | E7: 337 | F7: 4 | G7: 1 | H7: 81421 | I7: CHARACTER | J7: 14608454 | K7: TSPPG5 | L7: SS T-SHIRT PPG 25 CUT AND SEWN TSPPG5:PASTEL PINK:9-10:GRAPHIC:SS T-SHIRT | M7: 149900 | N7: 0.9 | O7: =M7-((90*M7)/100) -> 14990 | P7: PERCENTAGE
A8: 2023 JUN-DEC DISC 90 | B8: =B7 -> 46121 | C8: =C7 -> 46127 | D8: 3321 | E8: 337 | F8: 4 | G8: 1 | H8: 81462 | I8: CHARACTER | J8: 14292278 | K8: TSPPG1 | L8: SS T-SHIRT PPG FP SERUT TSPPG1:PASTEL PINK:5-6:PRINT:SS T-SHIRT | M8: 149900 | N8: 0.9 | O8: =M8-((90*M8)/100) -> 14990 | P8: PERCENTAGE
A9: 2023 JUN-DEC DISC 90 | B9: =B8 -> 46121 | C9: =C8 -> 46127 | D9: 3321 | E9: 337 | F9: 4 | G9: 1 | H9: 81462 | I9: CHARACTER | J9: 14292287 | K9: TSPPG1 | L9: SS T-SHIRT PPG FP SERUT TSPPG1:PASTEL PINK:7-8:PRINT:SS T-SHIRT | M9: 149900 | N9: 0.9 | O9: =M9-((90*M9)/100) -> 14990 | P9: PERCENTAGE
A10: 2023 JUN-DEC DISC 90 | B10: =B9 -> 46121 | C10: =C9 -> 46127 | D10: 3321 | E10: 337 | F10: 4 | G10: 1 | H10: 81462 | I10: CHARACTER | J10: 14292303 | K10: TSPPG1 | L10: SS T-SHIRT PPG FP SERUT TSPPG1:PASTEL PINK:11-12:PRINT:SS T-SHIRT | M10: 149900 | N10: 0.9 | O10: =M10-((90*M10)/100) -> 14990 | P10: PERCENTAGE
A11: 2023 JUN-DEC DISC 90 | B11: =B10 -> 46121 | C11: =C10 -> 46127 | D11: 3321 | E11: 337 | F11: 4 | G11: 1 | H11: 81462 | I11: CHARACTER | J11: 14292312 | K11: TSPPG2 | L11: SS T-SHIRT PPG GRL PWR RUFFLE LENGAN TSPPG2:OFF WHITE:5-6:PRINT:SS T-SHIRT | M11: 149900 | N11: 0.9 | O11: =M11-((90*M11)/100) -> 14990 | P11: PERCENTAGE
A12: 2023 JUN-DEC DISC 90 | B12: =B11 -> 46121 | C12: =C11 -> 46127 | D12: 3321 | E12: 337 | F12: 4 | G12: 1 | H12: 81462 | I12: CHARACTER | J12: 14292349 | K12: TSPPG2 | L12: SS T-SHIRT PPG GRL PWR RUFFLE LENGAN TSPPG2:OFF WHITE:11-12:PRINT:SS T-SHIRT | M12: 149900 | N12: 0.9 | O12: =M12-((90*M12)/100) -> 14990 | P12: PERCENTAGE
A13: 2023 JUN-DEC DISC 90 | B13: =B12 -> 46121 | C13: =C12 -> 46127 | D13: 3321 | E13: 337 | F13: 4 | G13: 1 | H13: 81462 | I13: CHARACTER | J13: 14927225 | K13: TSPPG3 | L13: SS T-SHIRT PPG GIRLS POWER RUFFLE BTM TSPPG3:PASTEL ORANGE:5-6:GRAPHIC:SS T-SHIRT | M13: 149900 | N13: 0.9 | O13: =M13-((90*M13)/100) -> 14990 | P13: PERCENTAGE
A14: 2023 JUN-DEC DISC 90 | B14: =B13 -> 46121 | C14: =C13 -> 46127 | D14: 3321 | E14: 337 | F14: 4 | G14: 1 | H14: 81462 | I14: CHARACTER | J14: 14927243 | K14: TSPPG3 | L14: SS T-SHIRT PPG GIRLS POWER RUFFLE BTM TSPPG3:PASTEL ORANGE:9-10:GRAPHIC:SS T-SHIRT | M14: 149900 | N14: 0.9 | O14: =M14-((90*M14)/100) -> 14990 | P14: PERCENTAGE
... A73: 2023 JUN-DEC DISC 90 | B73: =B72 -> 46121 | C73: =C72 -> 46127 | D73: 3321 | E73: 337 | F73: 4 | G73: 5 | H73: 81800 | I73: CHARACTER | J73: 82958850 | K73: DSBARB | L73: SS MIDI DRESS BARBIE DSBARB:PASTEL PINK:9-10:GRAPHIC:SS MIDI DRESS | M73: 219900 | N73: 0.9 | O73: =M73-((90*M73)/100) -> 21990 | P73: PERCENTAGE

Sheet 2026 JAN-APR SHARP PRICE - 3281
A1: ACARA | B1: FROM DATE | C1: TO DATE | D1: DEPT | E1: WORLD | F1: DIVISION | G1: CLASS | H1: SUPPLIER | I1: BRAND | J1: SKU | K1: ARTICLE | L1: DESCRIPTION | M1: HARGA NORMAL | N1: DISKON | O1: HARGA PROMO | P1: DISCOUNT TYPE
A2: 2026 JAN-APR SHARP PRICE | B2: ='2025 JUNSEPT B1G1 - 3321'!B8 -> 46121 | C2: ='2025 JUNSEPT B1G1 - 3321'!C8 -> 46127 | D2: 3281 | E2: 337 | F2: 4 | G2: 4 | H2: 81847 | I2: DISNEY | J2: 68791280 | K2: SSOVPOO | L2: SS SHIRT WOVEN OVERAL POOH SSOVPOO:MUSTARD:4:GRAPHIC:SS SHIRT | M2: 149900 | N2: 0 | O2: SHARP PRICE | P2: AMOUNT
A3: =A2 -> 2026 JAN-APR SHARP PRICE | B3: =B2 -> 46121 | C3: =C2 -> 46127 | D3: 3281 | E3: 337 | F3: 4 | G3: 4 | H3: 81847 | I3: DISNEY | J3: 68791299 | K3: SSOVPOO | L3: SS SHIRT WOVEN OVERAL POOH SSOVPOO:MUSTARD:5:GRAPHIC:SS SHIRT | M3: 149900 | N3: =N2 -> 0 | O3: =O2 -> SHARP PRICE | P3: =P2 -> AMOUNT
A4: =A3 -> 2026 JAN-APR SHARP PRICE | B4: =B3 -> 46121 | C4: =C3 -> 46127 | D4: 3281 | E4: 337 | F4: 4 | G4: 4 | H4: 81847 | I4: DISNEY | J4: 68791306 | K4: SSOVPOO | L4: SS SHIRT WOVEN OVERAL POOH SSOVPOO:MUSTARD:6:GRAPHIC:SS SHIRT | M4: 149900 | N4: =N3 -> 0 | O4: =O3 -> SHARP PRICE | P4: =P3 -> AMOUNT
A5: =A4 -> 2026 JAN-APR SHARP PRICE | B5: =B4 -> 46121 | C5: =C4 -> 46127 | D5: 3281 | E5: 337 | F5: 4 | G5: 4 | H5: 81847 | I5: DISNEY | J5: 68791315 | K5: SSOVPOO | L5: SS SHIRT WOVEN OVERAL POOH SSOVPOO:MUSTARD:7-8:GRAPHIC:SS SHIRT | M5: 149900 | N5: =N4 -> 0 | O5: =O4 -> SHARP PRICE | P5: =P4 -> AMOUNT
A6: =A5 -> 2026 JAN-APR SHARP PRICE | B6: =B5 -> 46121 | C6: =C5 -> 46127 | D6: 3281 | E6: 337 | F6: 4 | G6: 2 | H6: 81588 | I6: DISNEY | J6: 68791324 | K6: SSOVPOO | L6: SS SHIRT WOVEN OVERAL POOH SSOVPOO:MUSTARD:9-10:GRAPHIC:SS SHIRT | M6: 149900 | N6: =N5 -> 0 | O6: =O5 -> SHARP PRICE | P6: =P5 -> AMOUNT
A7: =A6 -> 2026 JAN-APR SHARP PRICE | B7: =B6 -> 46121 | C7: =C6 -> 46127 | D7: 3281 | E7: 337 | F7: 4 | G7: 2 | H7: 81588 | I7: DISNEY | J7: 68791333 | K7: SSOVPOO | L7: SS SHIRT WOVEN OVERAL POOH SSOVPOO:MUSTARD:11-12:GRAPHIC:SS SHIRT | M7: 149900 | N7: =N6 -> 0 | O7: =O6 -> SHARP PRICE | P7: =P6 -> AMOUNT
A8: =A7 -> 2026 JAN-APR SHARP PRICE | B8: =B7 -> 46121 | C8: =C7 -> 46127 | D8: 3281 | E8: 337 | F8: 4 | G8: 2 | H8: 81588 | I8: DISNEY | J8: 68791342 | K8: SSOVPOO | L8: SS SHIRT WOVEN OVERAL POOH SSOVPOO:MUSTARD:13-14:GRAPHIC:SS SHIRT | M8: 149900 | N8: =N7 -> 0 | O8: =O7 -> SHARP PRICE | P8: =P7 -> AMOUNT
A9: =A8 -> 2026 JAN-APR SHARP PRICE | B9: =B8 -> 46121 | C9: =C8 -> 46127 | D9: 3281 | E9: 337 | F9: 4 | G9: 2 | H9: 81588 | I9: DISNEY | J9: 68791351 | K9: SSPITPOO | L9: SS SHIRT WOVEN PITA POOH SSPITPOO:OFF WHITE:4:GRAPHIC:SS SHIRT | M9: 149900 | N9: =N8 -> 0 | O9: =O8 -> SHARP PRICE | P9: =P8 -> AMOUNT
A10: =A9 -> 2026 JAN-APR SHARP PRICE | B10: =B9 -> 46121 | C10: =C9 -> 46127 | D10: 3281 | E10: 337 | F10: 4 | G10: 2 | H10: 81588 | I10: DISNEY | J10: 68791360 | K10: SSPITPOO | L10: SS SHIRT WOVEN PITA POOH SSPITPOO:OFF WHITE:5:GRAPHIC:SS SHIRT | M10: 149900 | N10: =N9 -> 0 | O10: =O9 -> SHARP PRICE | P10: =P9 -> AMOUNT
A11: =A10 -> 2026 JAN-APR SHARP PRICE | B11: =B10 -> 46121 | C11: =C10 -> 46127 | D11: 3281 | E11: 337 | F11: 4 | G11: 2 | H11: 81588 | I11: DISNEY | J11: 68791379 | K11: SSPITPOO | L11: SS SHIRT WOVEN PITA POOH SSPITPOO:OFF WHITE:6:GRAPHIC:SS SHIRT | M11: 149900 | N11: =N10 -> 0 | O11: =O10 -> SHARP PRICE | P11: =P10 -> AMOUNT
A12: =A11 -> 2026 JAN-APR SHARP PRICE | B12: =B11 -> 46121 | C12: =C11 -> 46127 | D12: 3281 | E12: 337 | F12: 4 | G12: 2 | H12: 81588 | I12: DISNEY | J12: 68791388 | K12: SSPITPOO | L12: SS SHIRT WOVEN PITA POOH SSPITPOO:OFF WHITE:7-8:GRAPHIC:SS SHIRT | M12: 149900 | N12: =N11 -> 0 | O12: =O11 -> SHARP PRICE | P12: =P11 -> AMOUNT
A13: =A12 -> 2026 JAN-APR SHARP PRICE | B13: =B12 -> 46121 | C13: =C12 -> 46127 | D13: 3281 | E13: 337 | F13: 4 | G13: 2 | H13: 81588 | I13: DISNEY | J13: 68791397 | K13: SSPITPOO | L13: SS SHIRT WOVEN PITA POOH SSPITPOO:OFF WHITE:9-10:GRAPHIC:SS SHIRT | M13: 149900 | N13: =N12 -> 0 | O13: =O12 -> SHARP PRICE | P13: =P12 -> AMOUNT
A14: =A13 -> 2026 JAN-APR SHARP PRICE | B14: =B13 -> 46121 | C14: =C13 -> 46127 | D14: 3281 | E14: 337 | F14: 4 | G14: 2 | H14: 81588 | I14: DISNEY | J14: 68791404 | K14: SSPITPOO | L14: SS SHIRT WOVEN PITA POOH SSPITPOO:OFF WHITE:11-12:GRAPHIC:SS SHIRT | M14: 149900 | N14: =N13 -> 0 | O14: =O13 -> SHARP PRICE | P14: =P13 -> AMOUNT
... A66: =A65 -> 2026 JAN-APR SHARP PRICE | B66: =B65 -> 46121 | C66: =C65 -> 46127 | D66: 3281 | E66: 337 | F66: 4 | G66: 1 | H66: 81588 | I66: DISNEY | J66: 63154807 | K66: TS4PRN2 | L66: SS T-SHIRT PRINCESS PEPLUM TS4PRN2:PASTEL PINK:7-8:GRAPHIC:SS T-SHIRT | M66: 99900 | N66: =N65 -> 0 | O66: =O65 -> SHARP PRICE | P66: =P65 -> AMOUNT

Sheet 2026 BAMUS D60 - 3281
A1: ACARA | B1: FROM DATE | C1: TO DATE | D1: DEPT | E1: WORLD | F1: DIVISION | G1: CLASS | H1: SUPPLIER | I1: BRAND | J1: SKU | K1: ARTICLE | L1: DESCRIPTION | M1: HARGA NORMAL | N1: DISKON | O1: HARGA PROMO | P1: DISCOUNT TYPE
A2: 2026 BAMUS DISC 60% | B2: ='2025 JUNSEPT B1G1 - 3321'!B6 -> 46121 | C2: ='2025 JUNSEPT B1G1 - 3321'!C6 -> 46127 | D2: 3281 | E2: 337 | F2: 4 | G2: 2 | H2: 81506 | I2: DISNEY | J2: 67948907 | K2: SSL26PR3 | L2: SS SHIRT TOP WOVEN PRINCESS SSL26PR3:DUSTY PINK:4:GRAPHIC:SS SHIRT | M2: 179900 | N2: 0.6 | O2: =M2-((60*M2)/100) -> 71960 | P2: PERCENTAGE
A3: =A2 -> 2026 BAMUS DISC 60% | B3: =B2 -> 46121 | C3: =C2 -> 46127 | D3: 3281 | E3: 337 | F3: 4 | G3: 2 | H3: 81506 | I3: DISNEY | J3: 67948916 | K3: SSL26PR3 | L3: SS SHIRT TOP WOVEN PRINCESS SSL26PR3:DUSTY PINK:5:GRAPHIC:SS SHIRT | M3: 179900 | N3: =N2 -> 0.6 | O3: =O2 -> 71960 | P3: =P2 -> PERCENTAGE
A4: =A3 -> 2026 BAMUS DISC 60% | B4: =B3 -> 46121 | C4: =C3 -> 46127 | D4: 3281 | E4: 337 | F4: 4 | G4: 2 | H4: 81506 | I4: DISNEY | J4: 67948925 | K4: SSL26PR3 | L4: SS SHIRT TOP WOVEN PRINCESS SSL26PR3:DUSTY PINK:6:GRAPHIC:SS SHIRT | M4: 179900 | N4: =N3 -> 0.6 | O4: =O3 -> 71960 | P4: =P3 -> PERCENTAGE
A5: =A4 -> 2026 BAMUS DISC 60% | B5: =B4 -> 46121 | C5: =C4 -> 46127 | D5: 3281 | E5: 337 | F5: 4 | G5: 2 | H5: 81506 | I5: DISNEY | J5: 67948934 | K5: SSL26PR3 | L5: SS SHIRT TOP WOVEN PRINCESS SSL26PR3:DUSTY PINK:7-8:GRAPHIC:SS SHIRT | M5: 179900 | N5: =N4 -> 0.6 | O5: =O4 -> 71960 | P5: =P4 -> PERCENTAGE
A6: =A5 -> 2026 BAMUS DISC 60% | B6: =B5 -> 46121 | C6: =C5 -> 46127 | D6: 3281 | E6: 337 | F6: 4 | G6: 2 | H6: 81506 | I6: DISNEY | J6: 67948943 | K6: SSL26PR3 | L6: SS SHIRT TOP WOVEN PRINCESS SSL26PR3:DUSTY PINK:9-10:GRAPHIC:SS SHIRT | M6: 179900 | N6: =N5 -> 0.6 | O6: =O5 -> 71960 | P6: =P5 -> PERCENTAGE
A7: =A6 -> 2026 BAMUS DISC 60% | B7: =B6 -> 46121 | C7: =C6 -> 46127 | D7: 3281 | E7: 337 | F7: 4 | G7: 2 | H7: 81506 | I7: DISNEY | J7: 67948952 | K7: SSL26PR3 | L7: SS SHIRT TOP WOVEN PRINCESS SSL26PR3:DUSTY PINK:11-12:GRAPHIC:SS SHIRT | M7: 179900 | N7: =N6 -> 0.6 | O7: =M7-((60*M7)/100) -> 71960 | P7: =P6 -> PERCENTAGE
A8: =A7 -> 2026 BAMUS DISC 60% | B8: =B7 -> 46121 | C8: =C7 -> 46127 | D8: 3281 | E8: 337 | F8: 4 | G8: 2 | H8: 81506 | I8: DISNEY | J8: 67948961 | K8: SSL26PR3 | L8: SS SHIRT TOP WOVEN PRINCESS SSL26PR3:DUSTY PINK:13-14:GRAPHIC:SS SHIRT | M8: 179900 | N8: =N7 -> 0.6 | O8: =M8-((60*M8)/100) -> 71960 | P8: =P7 -> PERCENTAGE
